<?xml version="1.0" ?>
<!-- This file was generated by robot assembler -->
<robot name="kxr_uav_fullbody"
       xmlns:xi="http://www.w3.org/2001/XInclude"
       xmlns:gazebo="http://playerstage.sourceforge.net/gazebo/xmlschema/#gz"
       xmlns:model="http://playerstage.sourceforge.net/gazebo/xmlschema/#model"
       xmlns:sensor="http://playerstage.sourceforge.net/gazebo/xmlschema/#sensor"
       xmlns:body="http://playerstage.sourceforge.net/gazebo/xmlschema/#body"
       xmlns:geom="http://playerstage.sourceforge.net/gazebo/xmlschema/#geom"
       xmlns:joint="http://playerstage.sourceforge.net/gazebo/xmlschema/#joint"
       xmlns:interface="http://playerstage.sourceforge.net/gazebo/xmlschema/#interface"
       xmlns:rendering="http://playerstage.sourceforge.net/gazebo/xmlschema/#rendering"
       xmlns:renderable="http://playerstage.sourceforge.net/gazebo/xmlschema/#renderable"
       xmlns:controller="http://playerstage.sourceforge.net/gazebo/xmlschema/#controller"
       xmlns:physics="http://playerstage.sourceforge.net/gazebo/xmlschema/#physics"
       xmlns:xacro="http://www.ros.org/wiki/xacro">
  <xacro:macro name="gazebo_link_reference" params="link_name mu1:=0.9 mu2:=0.9" >
    <gazebo reference="${link_name}">
      <mu1>${mu1}</mu1>
      <mu2>${mu2}</mu2>
    </gazebo>
  </xacro:macro>
  <xacro:macro name="gazebo_transmission" params="joint_name" >
    <transmission name="${joint_name}_trans">
      <type>transmission_interface/SimpleTransmission</type>
      <joint name="${joint_name}">
        <hardwareInterface>hardware_interface/VelocityJointInterface</hardwareInterface>
        <!--hardwareInterface>hardware_interface/EffortJointInterface</hardwareInterface-->
      </joint>
      <actuator name="${joint_name}_motor">
        <hardwareInterface>hardware_interface/VelocityJointInterface</hardwareInterface>
        <!--hardwareInterface>hardware_interface/EffortJointInterface</hardwareInterface-->
        <mechanicalReduction>1</mechanicalReduction>
      </actuator>
    </transmission>
  </xacro:macro>

  <xacro:macro name="no_gazebo_transmission" params="joint_name" >
    <!-- dummy for fixed joint -->
  </xacro:macro>
  <xacro:gazebo_link_reference link_name="BASE" />
  <link name="BASE">
  <inertial>
     <mass value="0.538474"/>
     <origin rpy="0 0 0" xyz="-0.006028 -0.017774 0.032183"/>
     <inertia ixx="0.008163" ixy="-3.540155e-05" ixz="0.000127" iyy="0.008185" iyz="0.000193" izz="0.008113"/>
  </inertial>
  <visual>
     <origin xyz="0.000000 0.000000 0.000000" rpy="0.00000000 -0.00000000 0.00000000"/>
     <geometry>
     <mesh filename="package://robot_assembler/meshes/mesh_BATTERY-LEG-PLATE.dae" scale="1.000000 1.000000 1.000000"/>
     </geometry>
  </visual>
  <collision>
     <origin xyz="0.000000 0.000000 0.000000" rpy="0.00000000 -0.00000000 0.00000000"/>
     <geometry>
     <mesh filename="package://robot_assembler/meshes/mesh_BATTERY-LEG-PLATE.dae" scale="1.000000 1.000000 1.000000"/>
     </geometry>
  </collision>
  <visual>
     <origin xyz="0.000000 -0.000000 0.016000" rpy="3.14159265 0.00000000 0.00000000"/>
     <geometry>
     <mesh filename="package://robot_assembler/meshes/mesh_BATTERY-BOX.dae" scale="1.000000 1.000000 1.000000"/>
     </geometry>
  </visual>
  <collision>
     <origin xyz="0.000000 -0.000000 0.016000" rpy="3.14159265 0.00000000 0.00000000"/>
     <geometry>
     <mesh filename="package://robot_assembler/meshes/mesh_BATTERY-BOX.dae" scale="1.000000 1.000000 1.000000"/>
     </geometry>
  </collision>
  <visual>
     <origin xyz="-0.000000 0.025500 0.016000" rpy="-0.78539816 1.57079633 -2.35619449"/>
     <geometry>
     <mesh filename="package://robot_assembler/meshes/mesh_BODY-PLATE.dae" scale="1.000000 1.000000 1.000000"/>
     </geometry>
  </visual>
  <collision>
     <origin xyz="-0.000000 0.025500 0.016000" rpy="-0.78539816 1.57079633 -2.35619449"/>
     <geometry>
     <mesh filename="package://robot_assembler/meshes/mesh_BODY-PLATE.dae" scale="1.000000 1.000000 1.000000"/>
     </geometry>
  </collision>
  <visual>
     <origin xyz="0.000000 -0.025500 0.016000" rpy="1.38080804 1.57079633 2.95160437"/>
     <geometry>
     <mesh filename="package://robot_assembler/meshes/mesh_BODY-PLATE.dae" scale="1.000000 1.000000 1.000000"/>
     </geometry>
  </visual>
  <collision>
     <origin xyz="0.000000 -0.025500 0.016000" rpy="1.38080804 1.57079633 2.95160437"/>
     <geometry>
     <mesh filename="package://robot_assembler/meshes/mesh_BODY-PLATE.dae" scale="1.000000 1.000000 1.000000"/>
     </geometry>
  </collision>
  <visual>
     <origin xyz="-0.047500 -0.024500 0.063500" rpy="-3.14159265 -0.00000000 0.00000000"/>
     <geometry>
     <mesh filename="package://robot_assembler/meshes/kxr_uav/uav_backpack_mount.STL" scale="0.001000 0.001000 0.001000"/>
     </geometry>
  </visual>
  <collision>
     <origin xyz="-0.047500 -0.024500 0.063500" rpy="-3.14159265 -0.00000000 0.00000000"/>
     <geometry>
     <mesh filename="package://robot_assembler/meshes/kxr_uav/uav_backpack_mount.STL" scale="0.001000 0.001000 0.001000"/>
     </geometry>
  </collision>
  <visual>
     <origin xyz="-0.052000 -0.032500 0.078500" rpy="3.14159265 -0.00000000 0.00000000"/>
     <geometry>
     <mesh filename="package://robot_assembler/meshes/kxr_uav/uav_backpack.STL" scale="0.001000 0.001000 0.001000"/>
     </geometry>
  </visual>
  <collision>
     <origin xyz="-0.052000 -0.032500 0.078500" rpy="3.14159265 -0.00000000 0.00000000"/>
     <geometry>
     <mesh filename="package://robot_assembler/meshes/kxr_uav/uav_backpack.STL" scale="0.001000 0.001000 0.001000"/>
     </geometry>
  </collision>
  <visual>
     <origin xyz="-0.033000 -0.074500 0.047500" rpy="1.57079633 -0.00000000 0.00000000"/>
     <geometry>
     <mesh filename="package://robot_assembler/meshes/mesh_JOINT-BASE.dae" scale="1.000000 1.000000 1.000000"/>
     </geometry>
  </visual>
  <collision>
     <origin xyz="-0.033000 -0.074500 0.047500" rpy="1.57079633 -0.00000000 0.00000000"/>
     <geometry>
     <mesh filename="package://robot_assembler/meshes/mesh_JOINT-BASE.dae" scale="1.000000 1.000000 1.000000"/>
     </geometry>
  </collision>
  <visual>
     <origin xyz="-0.046000 -0.074500 0.047500" rpy="-0.00000000 0.00000000 -3.14159265"/>
     <geometry>
     <mesh filename="package://robot_assembler/meshes/mesh_JOINT-FRAME-A.dae" scale="1.000000 1.000000 1.000000"/>
     </geometry>
  </visual>
  <collision>
     <origin xyz="-0.046000 -0.074500 0.047500" rpy="-0.00000000 0.00000000 -3.14159265"/>
     <geometry>
     <mesh filename="package://robot_assembler/meshes/mesh_JOINT-FRAME-A.dae" scale="1.000000 1.000000 1.000000"/>
     </geometry>
  </collision>
  <visual>
     <origin xyz="-0.033000 -0.094000 0.058000" rpy="-0.89112251 1.57079633 2.25047015"/>
     <geometry>
     <mesh filename="package://robot_assembler/meshes/mesh_SERVO-S3301.dae" scale="1.000000 1.000000 1.000000"/>
     </geometry>
  </visual>
  <collision>
     <origin xyz="-0.033000 -0.094000 0.058000" rpy="-0.89112251 1.57079633 2.25047015"/>
     <geometry>
     <mesh filename="package://robot_assembler/meshes/mesh_SERVO-S3301.dae" scale="1.000000 1.000000 1.000000"/>
     </geometry>
  </collision>
  <visual>
     <origin xyz="-0.020000 -0.074500 0.047500" rpy="3.14159265 -0.00000000 0.00000000"/>
     <geometry>
     <mesh filename="package://robot_assembler/meshes/mesh_JOINT-FRAME-A.dae" scale="1.000000 1.000000 1.000000"/>
     </geometry>
  </visual>
  <collision>
     <origin xyz="-0.020000 -0.074500 0.047500" rpy="3.14159265 -0.00000000 0.00000000"/>
     <geometry>
     <mesh filename="package://robot_assembler/meshes/mesh_JOINT-FRAME-A.dae" scale="1.000000 1.000000 1.000000"/>
     </geometry>
  </collision>
  <visual>
     <origin xyz="0.033000 -0.074500 0.047500" rpy="1.57079633 -0.00000000 0.00000000"/>
     <geometry>
     <mesh filename="package://robot_assembler/meshes/mesh_JOINT-BASE.dae" scale="1.000000 1.000000 1.000000"/>
     </geometry>
  </visual>
  <collision>
     <origin xyz="0.033000 -0.074500 0.047500" rpy="1.57079633 -0.00000000 0.00000000"/>
     <geometry>
     <mesh filename="package://robot_assembler/meshes/mesh_JOINT-BASE.dae" scale="1.000000 1.000000 1.000000"/>
     </geometry>
  </collision>
  <visual>
     <origin xyz="0.020000 -0.074500 0.047500" rpy="-0.00000000 0.00000000 -3.14159265"/>
     <geometry>
     <mesh filename="package://robot_assembler/meshes/mesh_JOINT-FRAME-A.dae" scale="1.000000 1.000000 1.000000"/>
     </geometry>
  </visual>
  <collision>
     <origin xyz="0.020000 -0.074500 0.047500" rpy="-0.00000000 0.00000000 -3.14159265"/>
     <geometry>
     <mesh filename="package://robot_assembler/meshes/mesh_JOINT-FRAME-A.dae" scale="1.000000 1.000000 1.000000"/>
     </geometry>
  </collision>
  <visual>
     <origin xyz="0.046000 -0.074500 0.047500" rpy="3.14159265 -0.00000000 0.00000000"/>
     <geometry>
     <mesh filename="package://robot_assembler/meshes/mesh_JOINT-FRAME-A.dae" scale="1.000000 1.000000 1.000000"/>
     </geometry>
  </visual>
  <collision>
     <origin xyz="0.046000 -0.074500 0.047500" rpy="3.14159265 -0.00000000 0.00000000"/>
     <geometry>
     <mesh filename="package://robot_assembler/meshes/mesh_JOINT-FRAME-A.dae" scale="1.000000 1.000000 1.000000"/>
     </geometry>
  </collision>
  <visual>
     <origin xyz="0.033000 -0.094000 0.058000" rpy="2.05519846 1.57079633 2.05519846"/>
     <geometry>
     <mesh filename="package://robot_assembler/meshes/mesh_SERVO-S3301.dae" scale="1.000000 1.000000 1.000000"/>
     </geometry>
  </visual>
  <collision>
     <origin xyz="0.033000 -0.094000 0.058000" rpy="2.05519846 1.57079633 2.05519846"/>
     <geometry>
     <mesh filename="package://robot_assembler/meshes/mesh_SERVO-S3301.dae" scale="1.000000 1.000000 1.000000"/>
     </geometry>
  </collision>
  <visual>
     <origin xyz="-0.033000 -0.019500 0.059500" rpy="1.57079633 -0.00000000 -3.14159265"/>
     <geometry>
     <mesh filename="package://robot_assembler/meshes/mesh_JOINT-BASE.dae" scale="1.000000 1.000000 1.000000"/>
     </geometry>
  </visual>
  <collision>
     <origin xyz="-0.033000 -0.019500 0.059500" rpy="1.57079633 -0.00000000 -3.14159265"/>
     <geometry>
     <mesh filename="package://robot_assembler/meshes/mesh_JOINT-BASE.dae" scale="1.000000 1.000000 1.000000"/>
     </geometry>
  </collision>
  <visual>
     <origin xyz="-0.046500 -0.007250 0.059500" rpy="-1.57079633 0.00000000 -3.14159265"/>
     <geometry>
     <mesh filename="package://robot_assembler/meshes/mesh_ARM-SUPPORTER-A.dae" scale="1.000000 1.000000 1.000000"/>
     </geometry>
  </visual>
  <collision>
     <origin xyz="-0.046500 -0.007250 0.059500" rpy="-1.57079633 0.00000000 -3.14159265"/>
     <geometry>
     <mesh filename="package://robot_assembler/meshes/mesh_ARM-SUPPORTER-A.dae" scale="1.000000 1.000000 1.000000"/>
     </geometry>
  </collision>
  <visual>
     <origin xyz="-0.033000 -0.007250 0.059500" rpy="-1.57079633 0.00000000 1.57079633"/>
     <geometry>
     <mesh filename="package://robot_assembler/meshes/mesh_SERVO-S3301.dae" scale="1.000000 1.000000 1.000000"/>
     </geometry>
  </visual>
  <collision>
     <origin xyz="-0.033000 -0.007250 0.059500" rpy="-1.57079633 0.00000000 1.57079633"/>
     <geometry>
     <mesh filename="package://robot_assembler/meshes/mesh_SERVO-S3301.dae" scale="1.000000 1.000000 1.000000"/>
     </geometry>
  </collision>
  <visual>
     <origin xyz="-0.033000 0.019500 0.059500" rpy="-2.65469342 1.57079633 -1.08389709"/>
     <geometry>
     <mesh filename="package://robot_assembler/meshes/mesh_JOINT-BASE.dae" scale="1.000000 1.000000 1.000000"/>
     </geometry>
  </visual>
  <collision>
     <origin xyz="-0.033000 0.019500 0.059500" rpy="-2.65469342 1.57079633 -1.08389709"/>
     <geometry>
     <mesh filename="package://robot_assembler/meshes/mesh_JOINT-BASE.dae" scale="1.000000 1.000000 1.000000"/>
     </geometry>
  </collision>
  <visual>
     <origin xyz="0.033000 -0.019500 0.059500" rpy="1.57079633 -0.00000000 -3.14159265"/>
     <geometry>
     <mesh filename="package://robot_assembler/meshes/mesh_JOINT-BASE.dae" scale="1.000000 1.000000 1.000000"/>
     </geometry>
  </visual>
  <collision>
     <origin xyz="0.033000 -0.019500 0.059500" rpy="1.57079633 -0.00000000 -3.14159265"/>
     <geometry>
     <mesh filename="package://robot_assembler/meshes/mesh_JOINT-BASE.dae" scale="1.000000 1.000000 1.000000"/>
     </geometry>
  </collision>
  <visual>
     <origin xyz="0.046500 -0.007250 0.059500" rpy="1.57079633 0.00000000 0.00000000"/>
     <geometry>
     <mesh filename="package://robot_assembler/meshes/mesh_ARM-SUPPORTER-A.dae" scale="1.000000 1.000000 1.000000"/>
     </geometry>
  </visual>
  <collision>
     <origin xyz="0.046500 -0.007250 0.059500" rpy="1.57079633 0.00000000 0.00000000"/>
     <geometry>
     <mesh filename="package://robot_assembler/meshes/mesh_ARM-SUPPORTER-A.dae" scale="1.000000 1.000000 1.000000"/>
     </geometry>
  </collision>
  <visual>
     <origin xyz="0.033000 -0.007250 0.059500" rpy="1.57079633 -0.00000000 1.57079633"/>
     <geometry>
     <mesh filename="package://robot_assembler/meshes/mesh_SERVO-S3301.dae" scale="1.000000 1.000000 1.000000"/>
     </geometry>
  </visual>
  <collision>
     <origin xyz="0.033000 -0.007250 0.059500" rpy="1.57079633 -0.00000000 1.57079633"/>
     <geometry>
     <mesh filename="package://robot_assembler/meshes/mesh_SERVO-S3301.dae" scale="1.000000 1.000000 1.000000"/>
     </geometry>
  </collision>
  <visual>
     <origin xyz="0.033000 0.019500 0.059500" rpy="1.57079633 -0.00000000 0.00000000"/>
     <geometry>
     <mesh filename="package://robot_assembler/meshes/mesh_JOINT-BASE.dae" scale="1.000000 1.000000 1.000000"/>
     </geometry>
  </visual>
  <collision>
     <origin xyz="0.033000 0.019500 0.059500" rpy="1.57079633 -0.00000000 0.00000000"/>
     <geometry>
     <mesh filename="package://robot_assembler/meshes/mesh_JOINT-BASE.dae" scale="1.000000 1.000000 1.000000"/>
     </geometry>
  </collision>
  <visual>
     <origin xyz="0.000000 -0.019500 0.059500" rpy="1.57079633 -0.00000000 -3.14159265"/>
     <geometry>
     <mesh filename="package://robot_assembler/meshes/mesh_JOINT-BASE.dae" scale="1.000000 1.000000 1.000000"/>
     </geometry>
  </visual>
  <collision>
     <origin xyz="0.000000 -0.019500 0.059500" rpy="1.57079633 -0.00000000 -3.14159265"/>
     <geometry>
     <mesh filename="package://robot_assembler/meshes/mesh_JOINT-BASE.dae" scale="1.000000 1.000000 1.000000"/>
     </geometry>
  </collision>
  <visual>
     <origin xyz="0.000000 -0.007250 0.073000" rpy="0.98279372 -1.57079633 0.58800260"/>
     <geometry>
     <mesh filename="package://robot_assembler/meshes/mesh_ARM-SUPPORTER-A.dae" scale="1.000000 1.000000 1.000000"/>
     </geometry>
  </visual>
  <collision>
     <origin xyz="0.000000 -0.007250 0.073000" rpy="0.98279372 -1.57079633 0.58800260"/>
     <geometry>
     <mesh filename="package://robot_assembler/meshes/mesh_ARM-SUPPORTER-A.dae" scale="1.000000 1.000000 1.000000"/>
     </geometry>
  </collision>
  <visual>
     <origin xyz="0.000000 -0.007250 0.059500" rpy="0.00000000 -0.00000000 1.57079633"/>
     <geometry>
     <mesh filename="package://robot_assembler/meshes/mesh_SERVO-S3301.dae" scale="1.000000 1.000000 1.000000"/>
     </geometry>
  </visual>
  <collision>
     <origin xyz="0.000000 -0.007250 0.059500" rpy="0.00000000 -0.00000000 1.57079633"/>
     <geometry>
     <mesh filename="package://robot_assembler/meshes/mesh_SERVO-S3301.dae" scale="1.000000 1.000000 1.000000"/>
     </geometry>
  </collision>
  <visual>
     <origin xyz="-0.000000 0.019500 0.059500" rpy="1.57079633 -0.00000000 -3.14159265"/>
     <geometry>
     <mesh filename="package://robot_assembler/meshes/mesh_JOINT-BASE.dae" scale="1.000000 1.000000 1.000000"/>
     </geometry>
  </visual>
  <collision>
     <origin xyz="-0.000000 0.019500 0.059500" rpy="1.57079633 -0.00000000 -3.14159265"/>
     <geometry>
     <mesh filename="package://robot_assembler/meshes/mesh_JOINT-BASE.dae" scale="1.000000 1.000000 1.000000"/>
     </geometry>
  </collision>
  <visual>
     <origin xyz="0.023500 -0.021000 -0.014000" rpy="-2.35619449 -1.57079633 0.78539816"/>
     <geometry>
     <mesh filename="package://robot_assembler/meshes/mesh_BOTTOM-SPACER.dae" scale="1.000000 1.000000 1.000000"/>
     </geometry>
  </visual>
  <collision>
     <origin xyz="0.023500 -0.021000 -0.014000" rpy="-2.35619449 -1.57079633 0.78539816"/>
     <geometry>
     <mesh filename="package://robot_assembler/meshes/mesh_BOTTOM-SPACER.dae" scale="1.000000 1.000000 1.000000"/>
     </geometry>
  </collision>
  <visual>
     <origin xyz="0.044500 -0.010500 -0.020000" rpy="-1.31911866 -1.57079633 1.31911866"/>
     <geometry>
     <mesh filename="package://robot_assembler/meshes/mesh_BOTTOM-SPACER.dae" scale="1.000000 1.000000 1.000000"/>
     </geometry>
  </visual>
  <collision>
     <origin xyz="0.044500 -0.010500 -0.020000" rpy="-1.31911866 -1.57079633 1.31911866"/>
     <geometry>
     <mesh filename="package://robot_assembler/meshes/mesh_BOTTOM-SPACER.dae" scale="1.000000 1.000000 1.000000"/>
     </geometry>
  </collision>
  <visual>
     <origin xyz="0.044500 -0.010500 -0.033000" rpy="-3.14159265 -0.00000000 -3.14159265"/>
     <geometry>
     <mesh filename="package://robot_assembler/meshes/mesh_SERVO-S3301.dae" scale="1.000000 1.000000 1.000000"/>
     </geometry>
  </visual>
  <collision>
     <origin xyz="0.044500 -0.010500 -0.033000" rpy="-3.14159265 -0.00000000 -3.14159265"/>
     <geometry>
     <mesh filename="package://robot_assembler/meshes/mesh_SERVO-S3301.dae" scale="1.000000 1.000000 1.000000"/>
     </geometry>
  </collision>
  <visual>
     <origin xyz="-0.023500 -0.021000 -0.014000" rpy="-2.35619449 -1.57079633 0.78539816"/>
     <geometry>
     <mesh filename="package://robot_assembler/meshes/mesh_BOTTOM-SPACER.dae" scale="1.000000 1.000000 1.000000"/>
     </geometry>
  </visual>
  <collision>
     <origin xyz="-0.023500 -0.021000 -0.014000" rpy="-2.35619449 -1.57079633 0.78539816"/>
     <geometry>
     <mesh filename="package://robot_assembler/meshes/mesh_BOTTOM-SPACER.dae" scale="1.000000 1.000000 1.000000"/>
     </geometry>
  </collision>
  <visual>
     <origin xyz="-0.044500 -0.010500 -0.020000" rpy="1.87529262 -1.57079633 1.26630004"/>
     <geometry>
     <mesh filename="package://robot_assembler/meshes/mesh_BOTTOM-SPACER.dae" scale="1.000000 1.000000 1.000000"/>
     </geometry>
  </visual>
  <collision>
     <origin xyz="-0.044500 -0.010500 -0.020000" rpy="1.87529262 -1.57079633 1.26630004"/>
     <geometry>
     <mesh filename="package://robot_assembler/meshes/mesh_BOTTOM-SPACER.dae" scale="1.000000 1.000000 1.000000"/>
     </geometry>
  </collision>
  <visual>
     <origin xyz="-0.044500 -0.010500 -0.033000" rpy="-3.14159265 -0.00000000 0.00000000"/>
     <geometry>
     <mesh filename="package://robot_assembler/meshes/mesh_SERVO-S3301.dae" scale="1.000000 1.000000 1.000000"/>
     </geometry>
  </visual>
  <collision>
     <origin xyz="-0.044500 -0.010500 -0.033000" rpy="-3.14159265 -0.00000000 0.00000000"/>
     <geometry>
     <mesh filename="package://robot_assembler/meshes/mesh_SERVO-S3301.dae" scale="1.000000 1.000000 1.000000"/>
     </geometry>
  </collision>
  </link>
  <xacro:gazebo_link_reference link_name="LINK0" />
  <link name="LINK0">
  <inertial>
     <mass value="0.035533"/>
     <origin rpy="0 0 0" xyz="1.440522e-17 2.727550e-17 0.025344"/>
     <inertia ixx="0.001006" ixy="5.842216e-22" ixz="-4.864635e-21" iyy="0.001006" iyz="-1.108675e-20" izz="0.001002"/>
  </inertial>
  <visual>
     <origin xyz="-0.000000 -0.000000 0.002500" rpy="-0.00000000 0.00000000 -1.57079633"/>
     <geometry>
     <mesh filename="package://robot_assembler/meshes/mesh_JOINT-BASE.dae" scale="1.000000 1.000000 1.000000"/>
     </geometry>
  </visual>
  <collision>
     <origin xyz="-0.000000 -0.000000 0.002500" rpy="-0.00000000 0.00000000 -1.57079633"/>
     <geometry>
     <mesh filename="package://robot_assembler/meshes/mesh_JOINT-BASE.dae" scale="1.000000 1.000000 1.000000"/>
     </geometry>
  </collision>
  <visual>
     <origin xyz="-0.000000 0.013000 0.002500" rpy="1.57079633 -0.00000000 1.57079633"/>
     <geometry>
     <mesh filename="package://robot_assembler/meshes/mesh_JOINT-FRAME-A.dae" scale="1.000000 1.000000 1.000000"/>
     </geometry>
  </visual>
  <collision>
     <origin xyz="-0.000000 0.013000 0.002500" rpy="1.57079633 -0.00000000 1.57079633"/>
     <geometry>
     <mesh filename="package://robot_assembler/meshes/mesh_JOINT-FRAME-A.dae" scale="1.000000 1.000000 1.000000"/>
     </geometry>
  </collision>
  <visual>
     <origin xyz="0.000000 -0.013000 0.002500" rpy="1.57079633 -0.00000000 -1.57079633"/>
     <geometry>
     <mesh filename="package://robot_assembler/meshes/mesh_JOINT-FRAME-A.dae" scale="1.000000 1.000000 1.000000"/>
     </geometry>
  </visual>
  <collision>
     <origin xyz="0.000000 -0.013000 0.002500" rpy="1.57079633 -0.00000000 -1.57079633"/>
     <geometry>
     <mesh filename="package://robot_assembler/meshes/mesh_JOINT-FRAME-A.dae" scale="1.000000 1.000000 1.000000"/>
     </geometry>
  </collision>
  <visual>
     <origin xyz="0.000000 0.000000 0.032500" rpy="-0.58138018 1.57079633 -2.15217651"/>
     <geometry>
     <mesh filename="package://robot_assembler/meshes/mesh_SERVO-S3301.dae" scale="1.000000 1.000000 1.000000"/>
     </geometry>
  </visual>
  <collision>
     <origin xyz="0.000000 0.000000 0.032500" rpy="-0.58138018 1.57079633 -2.15217651"/>
     <geometry>
     <mesh filename="package://robot_assembler/meshes/mesh_SERVO-S3301.dae" scale="1.000000 1.000000 1.000000"/>
     </geometry>
  </collision>
  </link>
  <xacro:gazebo_link_reference link_name="LINK1" />
  <link name="LINK1">
  <inertial>
     <mass value="0.045736"/>
     <origin rpy="0 0 0" xyz="0.03622 -3.246908e-17 -0.0183"/>
     <inertia ixx="0.001004" ixy="1.773341e-20" ixz="-2.000101e-07" iyy="0.001013" iyz="2.664187e-21" izz="0.001011"/>
  </inertial>
  <visual>
     <origin xyz="0.025000 0.000000 -0.004500" rpy="0.10835955 -1.57079633 -0.10835955"/>
     <geometry>
     <mesh filename="package://robot_assembler/meshes/mesh_UPPER-ARM28.dae" scale="1.000000 1.000000 1.000000"/>
     </geometry>
  </visual>
  <collision>
     <origin xyz="0.025000 0.000000 -0.004500" rpy="0.10835955 -1.57079633 -0.10835955"/>
     <geometry>
     <mesh filename="package://robot_assembler/meshes/mesh_UPPER-ARM28.dae" scale="1.000000 1.000000 1.000000"/>
     </geometry>
  </collision>
  <visual>
     <origin xyz="0.025000 -0.000000 -0.017500" rpy="0.31545875 -1.57079633 -0.31545875"/>
     <geometry>
     <mesh filename="package://robot_assembler/meshes/mesh_JOINT-BASE.dae" scale="1.000000 1.000000 1.000000"/>
     </geometry>
  </visual>
  <collision>
     <origin xyz="0.025000 -0.000000 -0.017500" rpy="0.31545875 -1.57079633 -0.31545875"/>
     <geometry>
     <mesh filename="package://robot_assembler/meshes/mesh_JOINT-BASE.dae" scale="1.000000 1.000000 1.000000"/>
     </geometry>
  </collision>
  <visual>
     <origin xyz="0.034000 -0.000000 -0.038500" rpy="-0.00000000 -0.00000000 3.14159265"/>
     <geometry>
     <mesh filename="package://robot_assembler/meshes/mesh_BOTTOM-SPACER.dae" scale="1.000000 1.000000 1.000000"/>
     </geometry>
  </visual>
  <collision>
     <origin xyz="0.034000 -0.000000 -0.038500" rpy="-0.00000000 -0.00000000 3.14159265"/>
     <geometry>
     <mesh filename="package://robot_assembler/meshes/mesh_BOTTOM-SPACER.dae" scale="1.000000 1.000000 1.000000"/>
     </geometry>
  </collision>
  <visual>
     <origin xyz="0.047000 -0.000000 -0.017500" rpy="-2.76087154 1.57079633 -2.76087154"/>
     <geometry>
     <mesh filename="package://robot_assembler/meshes/mesh_SERVO-S3301.dae" scale="1.000000 1.000000 1.000000"/>
     </geometry>
  </visual>
  <collision>
     <origin xyz="0.047000 -0.000000 -0.017500" rpy="-2.76087154 1.57079633 -2.76087154"/>
     <geometry>
     <mesh filename="package://robot_assembler/meshes/mesh_SERVO-S3301.dae" scale="1.000000 1.000000 1.000000"/>
     </geometry>
  </collision>
  <visual>
     <origin xyz="0.025000 0.000000 -0.030500" rpy="0.54488653 1.57079633 -2.59670612"/>
     <geometry>
     <mesh filename="package://robot_assembler/meshes/mesh_BOTTOM-ARM28.dae" scale="1.000000 1.000000 1.000000"/>
     </geometry>
  </visual>
  <collision>
     <origin xyz="0.025000 0.000000 -0.030500" rpy="0.54488653 1.57079633 -2.59670612"/>
     <geometry>
     <mesh filename="package://robot_assembler/meshes/mesh_BOTTOM-ARM28.dae" scale="1.000000 1.000000 1.000000"/>
     </geometry>
  </collision>
  </link>
  <xacro:gazebo_link_reference link_name="LINK2" />
  <link name="LINK2">
  <inertial>
     <mass value="0.03987"/>
     <origin rpy="0 0 0" xyz="0.0 0.0 0.002"/>
     <inertia ixx="1.292452e-05" ixy="0.0" ixz="0.0" iyy="1.292452e-05" iyz="0.0" izz="2.472604e-05"/>
  </inertial>
  <visual>
     <origin xyz="0.000000 0.000000 0.002000" rpy="0.00000000 -0.00000000 0.00000000"/>
     <geometry>
     <mesh filename="package://robot_assembler/meshes/mesh_WHEEL.dae" scale="1.000000 1.000000 1.000000"/>
     </geometry>
  </visual>
  <collision>
     <origin xyz="0.000000 0.000000 0.002000" rpy="0.00000000 -0.00000000 0.00000000"/>
     <geometry>
     <mesh filename="package://robot_assembler/meshes/mesh_WHEEL.dae" scale="1.000000 1.000000 1.000000"/>
     </geometry>
  </collision>
  </link>
  <xacro:gazebo_link_reference link_name="LINK3" />
  <link name="LINK3">
  <inertial>
     <mass value="0.035533"/>
     <origin rpy="0 0 0" xyz="-3.655977e-17 -2.031665e-17 0.025344"/>
     <inertia ixx="0.001006" ixy="2.841647e-22" ixz="9.743227e-21" iyy="0.001006" iyz="6.124879e-20" izz="0.001002"/>
  </inertial>
  <visual>
     <origin xyz="0.000000 0.000000 0.002500" rpy="0.00000000 0.00000000 1.57079633"/>
     <geometry>
     <mesh filename="package://robot_assembler/meshes/mesh_JOINT-BASE.dae" scale="1.000000 1.000000 1.000000"/>
     </geometry>
  </visual>
  <collision>
     <origin xyz="0.000000 0.000000 0.002500" rpy="0.00000000 0.00000000 1.57079633"/>
     <geometry>
     <mesh filename="package://robot_assembler/meshes/mesh_JOINT-BASE.dae" scale="1.000000 1.000000 1.000000"/>
     </geometry>
  </collision>
  <visual>
     <origin xyz="0.000000 -0.013000 0.002500" rpy="1.57079633 -0.00000000 -1.57079633"/>
     <geometry>
     <mesh filename="package://robot_assembler/meshes/mesh_JOINT-FRAME-A.dae" scale="1.000000 1.000000 1.000000"/>
     </geometry>
  </visual>
  <collision>
     <origin xyz="0.000000 -0.013000 0.002500" rpy="1.57079633 -0.00000000 -1.57079633"/>
     <geometry>
     <mesh filename="package://robot_assembler/meshes/mesh_JOINT-FRAME-A.dae" scale="1.000000 1.000000 1.000000"/>
     </geometry>
  </collision>
  <visual>
     <origin xyz="0.000000 0.013000 0.002500" rpy="1.57079633 0.00000000 1.57079633"/>
     <geometry>
     <mesh filename="package://robot_assembler/meshes/mesh_JOINT-FRAME-A.dae" scale="1.000000 1.000000 1.000000"/>
     </geometry>
  </visual>
  <collision>
     <origin xyz="0.000000 0.013000 0.002500" rpy="1.57079633 0.00000000 1.57079633"/>
     <geometry>
     <mesh filename="package://robot_assembler/meshes/mesh_JOINT-FRAME-A.dae" scale="1.000000 1.000000 1.000000"/>
     </geometry>
  </collision>
  <visual>
     <origin xyz="-0.000000 -0.000000 0.032500" rpy="-1.57079633 1.57079633 0.00000000"/>
     <geometry>
     <mesh filename="package://robot_assembler/meshes/mesh_SERVO-S3301.dae" scale="1.000000 1.000000 1.000000"/>
     </geometry>
  </visual>
  <collision>
     <origin xyz="-0.000000 -0.000000 0.032500" rpy="-1.57079633 1.57079633 0.00000000"/>
     <geometry>
     <mesh filename="package://robot_assembler/meshes/mesh_SERVO-S3301.dae" scale="1.000000 1.000000 1.000000"/>
     </geometry>
  </collision>
  </link>
  <xacro:gazebo_link_reference link_name="LINK4" />
  <link name="LINK4">
  <inertial>
     <mass value="0.045736"/>
     <origin rpy="0 0 0" xyz="0.03622 -3.573066e-17 -0.0183"/>
     <inertia ixx="0.001004" ixy="2.144241e-20" ixz="-2.000101e-07" iyy="0.001013" iyz="2.153678e-21" izz="0.001011"/>
  </inertial>
  <visual>
     <origin xyz="0.025000 0.000000 -0.004500" rpy="-0.16486786 -1.57079633 0.16486786"/>
     <geometry>
     <mesh filename="package://robot_assembler/meshes/mesh_UPPER-ARM28.dae" scale="1.000000 1.000000 1.000000"/>
     </geometry>
  </visual>
  <collision>
     <origin xyz="0.025000 0.000000 -0.004500" rpy="-0.16486786 -1.57079633 0.16486786"/>
     <geometry>
     <mesh filename="package://robot_assembler/meshes/mesh_UPPER-ARM28.dae" scale="1.000000 1.000000 1.000000"/>
     </geometry>
  </collision>
  <visual>
     <origin xyz="0.025000 0.000000 -0.017500" rpy="0.82451301 -1.57079633 -0.82451301"/>
     <geometry>
     <mesh filename="package://robot_assembler/meshes/mesh_JOINT-BASE.dae" scale="1.000000 1.000000 1.000000"/>
     </geometry>
  </visual>
  <collision>
     <origin xyz="0.025000 0.000000 -0.017500" rpy="0.82451301 -1.57079633 -0.82451301"/>
     <geometry>
     <mesh filename="package://robot_assembler/meshes/mesh_JOINT-BASE.dae" scale="1.000000 1.000000 1.000000"/>
     </geometry>
  </collision>
  <visual>
     <origin xyz="0.034000 0.000000 -0.038500" rpy="-0.00000000 -0.00000000 3.14159265"/>
     <geometry>
     <mesh filename="package://robot_assembler/meshes/mesh_BOTTOM-SPACER.dae" scale="1.000000 1.000000 1.000000"/>
     </geometry>
  </visual>
  <collision>
     <origin xyz="0.034000 0.000000 -0.038500" rpy="-0.00000000 -0.00000000 3.14159265"/>
     <geometry>
     <mesh filename="package://robot_assembler/meshes/mesh_BOTTOM-SPACER.dae" scale="1.000000 1.000000 1.000000"/>
     </geometry>
  </collision>
  <visual>
     <origin xyz="0.047000 -0.000000 -0.017500" rpy="3.01078904 1.57079633 3.01078904"/>
     <geometry>
     <mesh filename="package://robot_assembler/meshes/mesh_SERVO-S3301.dae" scale="1.000000 1.000000 1.000000"/>
     </geometry>
  </visual>
  <collision>
     <origin xyz="0.047000 -0.000000 -0.017500" rpy="3.01078904 1.57079633 3.01078904"/>
     <geometry>
     <mesh filename="package://robot_assembler/meshes/mesh_SERVO-S3301.dae" scale="1.000000 1.000000 1.000000"/>
     </geometry>
  </collision>
  <visual>
     <origin xyz="0.025000 0.000000 -0.030500" rpy="-0.55662220 1.57079633 2.58497045"/>
     <geometry>
     <mesh filename="package://robot_assembler/meshes/mesh_BOTTOM-ARM28.dae" scale="1.000000 1.000000 1.000000"/>
     </geometry>
  </visual>
  <collision>
     <origin xyz="0.025000 0.000000 -0.030500" rpy="-0.55662220 1.57079633 2.58497045"/>
     <geometry>
     <mesh filename="package://robot_assembler/meshes/mesh_BOTTOM-ARM28.dae" scale="1.000000 1.000000 1.000000"/>
     </geometry>
  </collision>
  </link>
  <xacro:gazebo_link_reference link_name="LINK5" />
  <link name="LINK5">
  <inertial>
     <mass value="0.03987"/>
     <origin rpy="0 0 0" xyz="0.0 7.105427e-18 0.002"/>
     <inertia ixx="1.292452e-05" ixy="0.0" ixz="0.0" iyy="1.292452e-05" iyz="-6.285349e-53" izz="2.472604e-05"/>
  </inertial>
  <visual>
     <origin xyz="0.000000 0.000000 0.002000" rpy="0.00000000 0.00000000 0.00000000"/>
     <geometry>
     <mesh filename="package://robot_assembler/meshes/mesh_WHEEL.dae" scale="1.000000 1.000000 1.000000"/>
     </geometry>
  </visual>
  <collision>
     <origin xyz="0.000000 0.000000 0.002000" rpy="0.00000000 0.00000000 0.00000000"/>
     <geometry>
     <mesh filename="package://robot_assembler/meshes/mesh_WHEEL.dae" scale="1.000000 1.000000 1.000000"/>
     </geometry>
  </collision>
  </link>
  <xacro:gazebo_link_reference link_name="LINK6" />
  <link name="LINK6">
  <inertial>
     <mass value="0.012371"/>
     <origin rpy="0 0 0" xyz="-4.008972e-18 1.091287e-17 0.011206"/>
     <inertia ixx="3.583435e-06" ixy="-1.415920e-21" ixz="7.941970e-22" iyy="1.937420e-06" iyz="1.136868e-22" izz="2.583068e-06"/>
  </inertial>
  <visual>
     <origin xyz="0.000000 0.000000 0.002500" rpy="0.00000000 0.00000000 1.57079633"/>
     <geometry>
     <mesh filename="package://robot_assembler/meshes/mesh_JOINT-BASE.dae" scale="1.000000 1.000000 1.000000"/>
     </geometry>
  </visual>
  <collision>
     <origin xyz="0.000000 0.000000 0.002500" rpy="0.00000000 0.00000000 1.57079633"/>
     <geometry>
     <mesh filename="package://robot_assembler/meshes/mesh_JOINT-BASE.dae" scale="1.000000 1.000000 1.000000"/>
     </geometry>
  </collision>
  <visual>
     <origin xyz="-0.000000 -0.013000 0.002500" rpy="0.00000000 -0.00000000 -1.57079633"/>
     <geometry>
     <mesh filename="package://robot_assembler/meshes/mesh_BOTTOM-ARM28.dae" scale="1.000000 1.000000 1.000000"/>
     </geometry>
  </visual>
  <collision>
     <origin xyz="-0.000000 -0.013000 0.002500" rpy="0.00000000 -0.00000000 -1.57079633"/>
     <geometry>
     <mesh filename="package://robot_assembler/meshes/mesh_BOTTOM-ARM28.dae" scale="1.000000 1.000000 1.000000"/>
     </geometry>
  </collision>
  <visual>
     <origin xyz="0.000000 0.013000 0.002500" rpy="0.00000000 0.00000000 1.57079633"/>
     <geometry>
     <mesh filename="package://robot_assembler/meshes/mesh_UPPER-ARM28.dae" scale="1.000000 1.000000 1.000000"/>
     </geometry>
  </visual>
  <collision>
     <origin xyz="0.000000 0.013000 0.002500" rpy="0.00000000 0.00000000 1.57079633"/>
     <geometry>
     <mesh filename="package://robot_assembler/meshes/mesh_UPPER-ARM28.dae" scale="1.000000 1.000000 1.000000"/>
     </geometry>
  </collision>
  </link>
  <xacro:gazebo_link_reference link_name="LINK7" />
  <link name="LINK7">
  <inertial>
     <mass value="0.061777"/>
     <origin rpy="0 0 0" xyz="-0.001295 5.519827e-19 0.001582"/>
     <inertia ixx="0.00202" ixy="-3.339293e-21" ixz="1.039537e-06" iyy="0.002021" iyz="7.392355e-22" izz="0.002002"/>
  </inertial>
  <visual>
     <origin xyz="0.000000 0.000000 -0.018000" rpy="0.00000000 -0.00000000 -3.14159265"/>
     <geometry>
     <mesh filename="package://robot_assembler/meshes/mesh_SERVO-S3301.dae" scale="1.000000 1.000000 1.000000"/>
     </geometry>
  </visual>
  <collision>
     <origin xyz="0.000000 0.000000 -0.018000" rpy="0.00000000 -0.00000000 -3.14159265"/>
     <geometry>
     <mesh filename="package://robot_assembler/meshes/mesh_SERVO-S3301.dae" scale="1.000000 1.000000 1.000000"/>
     </geometry>
  </collision>
  <visual>
     <origin xyz="-0.000000 0.000000 0.006500" rpy="1.40690422 1.57079633 1.40690422"/>
     <geometry>
     <mesh filename="package://robot_assembler/meshes/mesh_CROSS-SERVO-FRAME-A.dae" scale="1.000000 1.000000 1.000000"/>
     </geometry>
  </visual>
  <collision>
     <origin xyz="-0.000000 0.000000 0.006500" rpy="1.40690422 1.57079633 1.40690422"/>
     <geometry>
     <mesh filename="package://robot_assembler/meshes/mesh_CROSS-SERVO-FRAME-A.dae" scale="1.000000 1.000000 1.000000"/>
     </geometry>
  </collision>
  <visual>
     <origin xyz="-0.000000 0.000000 0.017000" rpy="-1.57079633 0.00000000 -3.14159265"/>
     <geometry>
     <mesh filename="package://robot_assembler/meshes/mesh_SERVO-S3301.dae" scale="1.000000 1.000000 1.000000"/>
     </geometry>
  </visual>
  <collision>
     <origin xyz="-0.000000 0.000000 0.017000" rpy="-1.57079633 0.00000000 -3.14159265"/>
     <geometry>
     <mesh filename="package://robot_assembler/meshes/mesh_SERVO-S3301.dae" scale="1.000000 1.000000 1.000000"/>
     </geometry>
  </collision>
  <visual>
     <origin xyz="-0.000000 -0.000000 0.027500" rpy="1.52387888 1.57079633 1.52387888"/>
     <geometry>
     <mesh filename="package://robot_assembler/meshes/mesh_CROSS-SERVO-FRAME-B.dae" scale="1.000000 1.000000 1.000000"/>
     </geometry>
  </visual>
  <collision>
     <origin xyz="-0.000000 -0.000000 0.027500" rpy="1.52387888 1.57079633 1.52387888"/>
     <geometry>
     <mesh filename="package://robot_assembler/meshes/mesh_CROSS-SERVO-FRAME-B.dae" scale="1.000000 1.000000 1.000000"/>
     </geometry>
  </collision>
  </link>
  <xacro:gazebo_link_reference link_name="LINK8" />
  <link name="LINK8">
  <inertial>
     <mass value="0.021241"/>
     <origin rpy="0 0 0" xyz="2.733253e-17 0.030705 -0.0175"/>
     <inertia ixx="9.742580e-06" ixy="-7.346266e-21" ixz="-2.798377e-21" iyy="4.994969e-06" iyz="2.273737e-21" izz="9.161660e-06"/>
  </inertial>
  <visual>
     <origin xyz="0.000000 0.035000 -0.004500" rpy="-0.34877100 -1.57079633 1.91956733"/>
     <geometry>
     <mesh filename="package://robot_assembler/meshes/mesh_UPPER-ARM38.dae" scale="1.000000 1.000000 1.000000"/>
     </geometry>
  </visual>
  <collision>
     <origin xyz="0.000000 0.035000 -0.004500" rpy="-0.34877100 -1.57079633 1.91956733"/>
     <geometry>
     <mesh filename="package://robot_assembler/meshes/mesh_UPPER-ARM38.dae" scale="1.000000 1.000000 1.000000"/>
     </geometry>
  </collision>
  <visual>
     <origin xyz="0.000000 0.035000 -0.017500" rpy="1.48765509 1.57079633 3.05845142"/>
     <geometry>
     <mesh filename="package://robot_assembler/meshes/mesh_JOINT-BASE.dae" scale="1.000000 1.000000 1.000000"/>
     </geometry>
  </visual>
  <collision>
     <origin xyz="0.000000 0.035000 -0.017500" rpy="1.48765509 1.57079633 3.05845142"/>
     <geometry>
     <mesh filename="package://robot_assembler/meshes/mesh_JOINT-BASE.dae" scale="1.000000 1.000000 1.000000"/>
     </geometry>
  </collision>
  <visual>
     <origin xyz="0.013000 0.035000 -0.017500" rpy="-1.57079633 0.00000000 0.00000000"/>
     <geometry>
     <mesh filename="package://robot_assembler/meshes/mesh_BOTTOM-ARM26.dae" scale="1.000000 1.000000 1.000000"/>
     </geometry>
  </visual>
  <collision>
     <origin xyz="0.013000 0.035000 -0.017500" rpy="-1.57079633 0.00000000 0.00000000"/>
     <geometry>
     <mesh filename="package://robot_assembler/meshes/mesh_BOTTOM-ARM26.dae" scale="1.000000 1.000000 1.000000"/>
     </geometry>
  </collision>
  <visual>
     <origin xyz="-0.013000 0.035000 -0.017500" rpy="1.57079633 -0.00000000 3.14159265"/>
     <geometry>
     <mesh filename="package://robot_assembler/meshes/mesh_UPPER-ARM26.dae" scale="1.000000 1.000000 1.000000"/>
     </geometry>
  </visual>
  <collision>
     <origin xyz="-0.013000 0.035000 -0.017500" rpy="1.57079633 -0.00000000 3.14159265"/>
     <geometry>
     <mesh filename="package://robot_assembler/meshes/mesh_UPPER-ARM26.dae" scale="1.000000 1.000000 1.000000"/>
     </geometry>
  </collision>
  <visual>
     <origin xyz="0.000000 0.035000 -0.030500" rpy="2.20354516 1.57079633 0.63274884"/>
     <geometry>
     <mesh filename="package://robot_assembler/meshes/mesh_BOTTOM-ARM38.dae" scale="1.000000 1.000000 1.000000"/>
     </geometry>
  </visual>
  <collision>
     <origin xyz="0.000000 0.035000 -0.030500" rpy="2.20354516 1.57079633 0.63274884"/>
     <geometry>
     <mesh filename="package://robot_assembler/meshes/mesh_BOTTOM-ARM38.dae" scale="1.000000 1.000000 1.000000"/>
     </geometry>
  </collision>
  </link>
  <xacro:gazebo_link_reference link_name="LINK9" />
  <link name="LINK9">
  <inertial>
     <mass value="0.068898"/>
     <origin rpy="0 0 0" xyz="-0.02723 -5.542577e-17 -0.017469"/>
     <inertia ixx="0.002003" ixy="-7.408144e-20" ixz="3.115518e-07" iyy="0.002039" iyz="1.528708e-22" izz="0.002037"/>
  </inertial>
  <visual>
     <origin xyz="0.000000 0.000000 -0.018000" rpy="0.00000000 0.00000000 -3.14159265"/>
     <geometry>
     <mesh filename="package://robot_assembler/meshes/mesh_SERVO-S3301.dae" scale="1.000000 1.000000 1.000000"/>
     </geometry>
  </visual>
  <collision>
     <origin xyz="0.000000 0.000000 -0.018000" rpy="0.00000000 0.00000000 -3.14159265"/>
     <geometry>
     <mesh filename="package://robot_assembler/meshes/mesh_SERVO-S3301.dae" scale="1.000000 1.000000 1.000000"/>
     </geometry>
  </collision>
  <visual>
     <origin xyz="-0.030000 -0.000000 -0.031000" rpy="-2.95461338 1.57079633 1.75777560"/>
     <geometry>
     <mesh filename="package://robot_assembler/meshes/mesh_JOINT-FRAME-A.dae" scale="1.000000 1.000000 1.000000"/>
     </geometry>
  </visual>
  <collision>
     <origin xyz="-0.030000 -0.000000 -0.031000" rpy="-2.95461338 1.57079633 1.75777560"/>
     <geometry>
     <mesh filename="package://robot_assembler/meshes/mesh_JOINT-FRAME-A.dae" scale="1.000000 1.000000 1.000000"/>
     </geometry>
  </collision>
  <visual>
     <origin xyz="-0.030000 -0.000000 -0.005000" rpy="0.46364761 -1.57079633 -2.03444394"/>
     <geometry>
     <mesh filename="package://robot_assembler/meshes/mesh_JOINT-FRAME-A.dae" scale="1.000000 1.000000 1.000000"/>
     </geometry>
  </visual>
  <collision>
     <origin xyz="-0.030000 -0.000000 -0.005000" rpy="0.46364761 -1.57079633 -2.03444394"/>
     <geometry>
     <mesh filename="package://robot_assembler/meshes/mesh_JOINT-FRAME-A.dae" scale="1.000000 1.000000 1.000000"/>
     </geometry>
  </collision>
  <visual>
     <origin xyz="-0.030000 -0.000000 -0.018000" rpy="-0.09726590 1.57079633 -0.09726590"/>
     <geometry>
     <mesh filename="package://robot_assembler/meshes/mesh_JOINT-BASE.dae" scale="1.000000 1.000000 1.000000"/>
     </geometry>
  </visual>
  <collision>
     <origin xyz="-0.030000 -0.000000 -0.018000" rpy="-0.09726590 1.57079633 -0.09726590"/>
     <geometry>
     <mesh filename="package://robot_assembler/meshes/mesh_JOINT-BASE.dae" scale="1.000000 1.000000 1.000000"/>
     </geometry>
  </collision>
  <visual>
     <origin xyz="-0.039000 -0.000000 0.003000" rpy="-3.14159265 -0.00000000 0.00000000"/>
     <geometry>
     <mesh filename="package://robot_assembler/meshes/mesh_BOTTOM-SPACER.dae" scale="1.000000 1.000000 1.000000"/>
     </geometry>
  </visual>
  <collision>
     <origin xyz="-0.039000 -0.000000 0.003000" rpy="-3.14159265 -0.00000000 0.00000000"/>
     <geometry>
     <mesh filename="package://robot_assembler/meshes/mesh_BOTTOM-SPACER.dae" scale="1.000000 1.000000 1.000000"/>
     </geometry>
  </collision>
  <visual>
     <origin xyz="-0.052000 -0.000000 -0.018000" rpy="0.88760506 -1.57079633 -0.88760506"/>
     <geometry>
     <mesh filename="package://robot_assembler/meshes/mesh_SERVO-S3301.dae" scale="1.000000 1.000000 1.000000"/>
     </geometry>
  </visual>
  <collision>
     <origin xyz="-0.052000 -0.000000 -0.018000" rpy="0.88760506 -1.57079633 -0.88760506"/>
     <geometry>
     <mesh filename="package://robot_assembler/meshes/mesh_SERVO-S3301.dae" scale="1.000000 1.000000 1.000000"/>
     </geometry>
  </collision>
  </link>
  <xacro:gazebo_link_reference link_name="LINK10" />
  <link name="LINK10">
  <inertial>
     <mass value="0.012371"/>
     <origin rpy="0 0 0" xyz="-1.723085e-18 5.154895e-18 0.011206"/>
     <inertia ixx="1.937420e-06" ixy="1.095076e-21" ixz="-2.273737e-22" iyy="3.583435e-06" iyz="-8.191352e-22" izz="2.583068e-06"/>
  </inertial>
  <visual>
     <origin xyz="0.000000 0.000000 0.002500" rpy="-0.00000000 -0.00000000 -0.00000000"/>
     <geometry>
     <mesh filename="package://robot_assembler/meshes/mesh_JOINT-BASE.dae" scale="1.000000 1.000000 1.000000"/>
     </geometry>
  </visual>
  <collision>
     <origin xyz="0.000000 0.000000 0.002500" rpy="-0.00000000 -0.00000000 -0.00000000"/>
     <geometry>
     <mesh filename="package://robot_assembler/meshes/mesh_JOINT-BASE.dae" scale="1.000000 1.000000 1.000000"/>
     </geometry>
  </collision>
  <visual>
     <origin xyz="-0.013000 0.000000 0.002500" rpy="0.00000000 -0.00000000 -3.14159265"/>
     <geometry>
     <mesh filename="package://robot_assembler/meshes/mesh_UPPER-ARM28.dae" scale="1.000000 1.000000 1.000000"/>
     </geometry>
  </visual>
  <collision>
     <origin xyz="-0.013000 0.000000 0.002500" rpy="0.00000000 -0.00000000 -3.14159265"/>
     <geometry>
     <mesh filename="package://robot_assembler/meshes/mesh_UPPER-ARM28.dae" scale="1.000000 1.000000 1.000000"/>
     </geometry>
  </collision>
  <visual>
     <origin xyz="0.013000 0.000000 0.002500" rpy="0.00000000 -0.00000000 -0.00000000"/>
     <geometry>
     <mesh filename="package://robot_assembler/meshes/mesh_BOTTOM-ARM28.dae" scale="1.000000 1.000000 1.000000"/>
     </geometry>
  </visual>
  <collision>
     <origin xyz="0.013000 0.000000 0.002500" rpy="0.00000000 -0.00000000 -0.00000000"/>
     <geometry>
     <mesh filename="package://robot_assembler/meshes/mesh_BOTTOM-ARM28.dae" scale="1.000000 1.000000 1.000000"/>
     </geometry>
  </collision>
  </link>
  <xacro:gazebo_link_reference link_name="LINK11" />
  <link name="LINK11">
  <inertial>
     <mass value="0.061777"/>
     <origin rpy="0 0 0" xyz="-0.001295 -2.522546e-18 0.001582"/>
     <inertia ixx="0.00202" ixy="-3.337558e-21" ixz="1.039537e-06" iyy="0.002021" iyz="3.872182e-21" izz="0.002002"/>
  </inertial>
  <visual>
     <origin xyz="0.000000 0.000000 -0.018000" rpy="0.00000000 -0.00000000 -3.14159265"/>
     <geometry>
     <mesh filename="package://robot_assembler/meshes/mesh_SERVO-S3301.dae" scale="1.000000 1.000000 1.000000"/>
     </geometry>
  </visual>
  <collision>
     <origin xyz="0.000000 0.000000 -0.018000" rpy="0.00000000 -0.00000000 -3.14159265"/>
     <geometry>
     <mesh filename="package://robot_assembler/meshes/mesh_SERVO-S3301.dae" scale="1.000000 1.000000 1.000000"/>
     </geometry>
  </collision>
  <visual>
     <origin xyz="0.000000 0.000000 0.006500" rpy="1.40690422 1.57079633 1.40690422"/>
     <geometry>
     <mesh filename="package://robot_assembler/meshes/mesh_CROSS-SERVO-FRAME-A.dae" scale="1.000000 1.000000 1.000000"/>
     </geometry>
  </visual>
  <collision>
     <origin xyz="0.000000 0.000000 0.006500" rpy="1.40690422 1.57079633 1.40690422"/>
     <geometry>
     <mesh filename="package://robot_assembler/meshes/mesh_CROSS-SERVO-FRAME-A.dae" scale="1.000000 1.000000 1.000000"/>
     </geometry>
  </collision>
  <visual>
     <origin xyz="-0.000000 0.000000 0.017000" rpy="-1.57079633 0.00000000 -3.14159265"/>
     <geometry>
     <mesh filename="package://robot_assembler/meshes/mesh_SERVO-S3301.dae" scale="1.000000 1.000000 1.000000"/>
     </geometry>
  </visual>
  <collision>
     <origin xyz="-0.000000 0.000000 0.017000" rpy="-1.57079633 0.00000000 -3.14159265"/>
     <geometry>
     <mesh filename="package://robot_assembler/meshes/mesh_SERVO-S3301.dae" scale="1.000000 1.000000 1.000000"/>
     </geometry>
  </collision>
  <visual>
     <origin xyz="-0.000000 -0.000000 0.027500" rpy="1.67701128 1.57079633 1.67701128"/>
     <geometry>
     <mesh filename="package://robot_assembler/meshes/mesh_CROSS-SERVO-FRAME-B.dae" scale="1.000000 1.000000 1.000000"/>
     </geometry>
  </visual>
  <collision>
     <origin xyz="-0.000000 -0.000000 0.027500" rpy="1.67701128 1.57079633 1.67701128"/>
     <geometry>
     <mesh filename="package://robot_assembler/meshes/mesh_CROSS-SERVO-FRAME-B.dae" scale="1.000000 1.000000 1.000000"/>
     </geometry>
  </collision>
  </link>
  <xacro:gazebo_link_reference link_name="LINK12" />
  <link name="LINK12">
  <inertial>
     <mass value="0.050016"/>
     <origin rpy="0 0 0" xyz="-0.046234 0.005542 -0.0175"/>
     <inertia ixx="0.001006" ixy="3.954600e-06" ixz="-3.319656e-20" iyy="0.001021" iyz="8.924417e-21" izz="0.001019"/>
  </inertial>
  <visual>
     <origin xyz="-0.035000 -0.000000 -0.004500" rpy="-0.61547971 -1.57079633 -2.52611294"/>
     <geometry>
     <mesh filename="package://robot_assembler/meshes/mesh_UPPER-ARM38.dae" scale="1.000000 1.000000 1.000000"/>
     </geometry>
  </visual>
  <collision>
     <origin xyz="-0.035000 -0.000000 -0.004500" rpy="-0.61547971 -1.57079633 -2.52611294"/>
     <geometry>
     <mesh filename="package://robot_assembler/meshes/mesh_UPPER-ARM38.dae" scale="1.000000 1.000000 1.000000"/>
     </geometry>
  </collision>
  <visual>
     <origin xyz="-0.035000 -0.000000 -0.017500" rpy="-0.38892645 1.57079633 -0.38892645"/>
     <geometry>
     <mesh filename="package://robot_assembler/meshes/mesh_JOINT-BASE.dae" scale="1.000000 1.000000 1.000000"/>
     </geometry>
  </visual>
  <collision>
     <origin xyz="-0.035000 -0.000000 -0.017500" rpy="-0.38892645 1.57079633 -0.38892645"/>
     <geometry>
     <mesh filename="package://robot_assembler/meshes/mesh_JOINT-BASE.dae" scale="1.000000 1.000000 1.000000"/>
     </geometry>
  </collision>
  <visual>
     <origin xyz="-0.041000 -0.000000 -0.017500" rpy="2.66350805 1.57079633 -0.47808460"/>
     <geometry>
     <mesh filename="package://robot_assembler/meshes/mesh_JOINT-BASE.dae" scale="1.000000 1.000000 1.000000"/>
     </geometry>
  </visual>
  <collision>
     <origin xyz="-0.041000 -0.000000 -0.017500" rpy="2.66350805 1.57079633 -0.47808460"/>
     <geometry>
     <mesh filename="package://robot_assembler/meshes/mesh_JOINT-BASE.dae" scale="1.000000 1.000000 1.000000"/>
     </geometry>
  </collision>
  <visual>
     <origin xyz="-0.041000 -0.000000 -0.004500" rpy="-1.07685496 -1.57079633 2.64765128"/>
     <geometry>
     <mesh filename="package://robot_assembler/meshes/mesh_JOINT-FRAME-A.dae" scale="1.000000 1.000000 1.000000"/>
     </geometry>
  </visual>
  <collision>
     <origin xyz="-0.041000 -0.000000 -0.004500" rpy="-1.07685496 -1.57079633 2.64765128"/>
     <geometry>
     <mesh filename="package://robot_assembler/meshes/mesh_JOINT-FRAME-A.dae" scale="1.000000 1.000000 1.000000"/>
     </geometry>
  </collision>
  <visual>
     <origin xyz="-0.060500 0.010500 -0.017500" rpy="0.00000000 -0.00000000 -1.57079633"/>
     <geometry>
     <mesh filename="package://robot_assembler/meshes/mesh_SERVO-S3301.dae" scale="1.000000 1.000000 1.000000"/>
     </geometry>
  </visual>
  <collision>
     <origin xyz="-0.060500 0.010500 -0.017500" rpy="0.00000000 -0.00000000 -1.57079633"/>
     <geometry>
     <mesh filename="package://robot_assembler/meshes/mesh_SERVO-S3301.dae" scale="1.000000 1.000000 1.000000"/>
     </geometry>
  </collision>
  <visual>
     <origin xyz="-0.041000 -0.000000 -0.030500" rpy="-1.67046498 1.57079633 -0.09966865"/>
     <geometry>
     <mesh filename="package://robot_assembler/meshes/mesh_JOINT-FRAME-A.dae" scale="1.000000 1.000000 1.000000"/>
     </geometry>
  </visual>
  <collision>
     <origin xyz="-0.041000 -0.000000 -0.030500" rpy="-1.67046498 1.57079633 -0.09966865"/>
     <geometry>
     <mesh filename="package://robot_assembler/meshes/mesh_JOINT-FRAME-A.dae" scale="1.000000 1.000000 1.000000"/>
     </geometry>
  </collision>
  <visual>
     <origin xyz="-0.035000 -0.000000 -0.030500" rpy="-0.52732047 1.57079633 -0.52732047"/>
     <geometry>
     <mesh filename="package://robot_assembler/meshes/mesh_BOTTOM-ARM38.dae" scale="1.000000 1.000000 1.000000"/>
     </geometry>
  </visual>
  <collision>
     <origin xyz="-0.035000 -0.000000 -0.030500" rpy="-0.52732047 1.57079633 -0.52732047"/>
     <geometry>
     <mesh filename="package://robot_assembler/meshes/mesh_BOTTOM-ARM38.dae" scale="1.000000 1.000000 1.000000"/>
     </geometry>
  </collision>
  </link>
  <xacro:gazebo_link_reference link_name="LINK13" />
  <link name="LINK13">
  <inertial>
     <mass value="0.013908"/>
     <origin rpy="0 0 0" xyz="0.0 0.016 -0.018"/>
     <inertia ixx="5.661715e-06" ixy="2.124697e-21" ixz="3.261907e-22" iyy="2.546323e-06" iyz="-1.509199e-21" izz="4.682360e-06"/>
  </inertial>
  <visual>
     <origin xyz="0.000000 0.000000 -0.033500" rpy="1.29515353 1.57079633 1.29515353"/>
     <geometry>
     <mesh filename="package://robot_assembler/meshes/mesh_FINGER.dae" scale="1.000000 1.000000 1.000000"/>
     </geometry>
  </visual>
  <collision>
     <origin xyz="0.000000 0.000000 -0.033500" rpy="1.29515353 1.57079633 1.29515353"/>
     <geometry>
     <mesh filename="package://robot_assembler/meshes/mesh_FINGER.dae" scale="1.000000 1.000000 1.000000"/>
     </geometry>
  </collision>
  </link>
  <xacro:gazebo_link_reference link_name="LINK14" />
  <link name="LINK14">
  <inertial>
     <mass value="0.012371"/>
     <origin rpy="0 0 0" xyz="3.608427e-18 0.0 0.011206"/>
     <inertia ixx="3.583435e-06" ixy="-3.508414e-22" ixz="-6.757543e-22" iyy="1.937420e-06" iyz="-5.115908e-22" izz="2.583068e-06"/>
  </inertial>
  <visual>
     <origin xyz="0.000000 0.000000 0.002500" rpy="0.00000000 0.00000000 -1.57079633"/>
     <geometry>
     <mesh filename="package://robot_assembler/meshes/mesh_JOINT-BASE.dae" scale="1.000000 1.000000 1.000000"/>
     </geometry>
  </visual>
  <collision>
     <origin xyz="0.000000 0.000000 0.002500" rpy="0.00000000 0.00000000 -1.57079633"/>
     <geometry>
     <mesh filename="package://robot_assembler/meshes/mesh_JOINT-BASE.dae" scale="1.000000 1.000000 1.000000"/>
     </geometry>
  </collision>
  <visual>
     <origin xyz="-0.000000 0.013000 0.002500" rpy="0.00000000 -0.00000000 1.57079633"/>
     <geometry>
     <mesh filename="package://robot_assembler/meshes/mesh_BOTTOM-ARM28.dae" scale="1.000000 1.000000 1.000000"/>
     </geometry>
  </visual>
  <collision>
     <origin xyz="-0.000000 0.013000 0.002500" rpy="0.00000000 -0.00000000 1.57079633"/>
     <geometry>
     <mesh filename="package://robot_assembler/meshes/mesh_BOTTOM-ARM28.dae" scale="1.000000 1.000000 1.000000"/>
     </geometry>
  </collision>
  <visual>
     <origin xyz="0.000000 -0.013000 0.002500" rpy="0.00000000 0.00000000 -1.57079633"/>
     <geometry>
     <mesh filename="package://robot_assembler/meshes/mesh_UPPER-ARM28.dae" scale="1.000000 1.000000 1.000000"/>
     </geometry>
  </visual>
  <collision>
     <origin xyz="0.000000 -0.013000 0.002500" rpy="0.00000000 0.00000000 -1.57079633"/>
     <geometry>
     <mesh filename="package://robot_assembler/meshes/mesh_UPPER-ARM28.dae" scale="1.000000 1.000000 1.000000"/>
     </geometry>
  </collision>
  </link>
  <xacro:gazebo_link_reference link_name="LINK15" />
  <link name="LINK15">
  <inertial>
     <mass value="0.061777"/>
     <origin rpy="0 0 0" xyz="-0.001295 -1.761347e-19 0.001582"/>
     <inertia ixx="0.00202" ixy="-2.594178e-21" ixz="1.039537e-06" iyy="0.002021" iyz="4.668571e-22" izz="0.002002"/>
  </inertial>
  <visual>
     <origin xyz="0.000000 0.000000 -0.018000" rpy="0.00000000 0.00000000 -3.14159265"/>
     <geometry>
     <mesh filename="package://robot_assembler/meshes/mesh_SERVO-S3301.dae" scale="1.000000 1.000000 1.000000"/>
     </geometry>
  </visual>
  <collision>
     <origin xyz="0.000000 0.000000 -0.018000" rpy="0.00000000 0.00000000 -3.14159265"/>
     <geometry>
     <mesh filename="package://robot_assembler/meshes/mesh_SERVO-S3301.dae" scale="1.000000 1.000000 1.000000"/>
     </geometry>
  </collision>
  <visual>
     <origin xyz="0.000000 0.000000 0.006500" rpy="1.40690422 1.57079633 1.40690422"/>
     <geometry>
     <mesh filename="package://robot_assembler/meshes/mesh_CROSS-SERVO-FRAME-A.dae" scale="1.000000 1.000000 1.000000"/>
     </geometry>
  </visual>
  <collision>
     <origin xyz="0.000000 0.000000 0.006500" rpy="1.40690422 1.57079633 1.40690422"/>
     <geometry>
     <mesh filename="package://robot_assembler/meshes/mesh_CROSS-SERVO-FRAME-A.dae" scale="1.000000 1.000000 1.000000"/>
     </geometry>
  </collision>
  <visual>
     <origin xyz="-0.000000 0.000000 0.017000" rpy="-1.57079633 0.00000000 -3.14159265"/>
     <geometry>
     <mesh filename="package://robot_assembler/meshes/mesh_SERVO-S3301.dae" scale="1.000000 1.000000 1.000000"/>
     </geometry>
  </visual>
  <collision>
     <origin xyz="-0.000000 0.000000 0.017000" rpy="-1.57079633 0.00000000 -3.14159265"/>
     <geometry>
     <mesh filename="package://robot_assembler/meshes/mesh_SERVO-S3301.dae" scale="1.000000 1.000000 1.000000"/>
     </geometry>
  </collision>
  <visual>
     <origin xyz="-0.000000 -0.000000 0.027500" rpy="1.61657552 1.57079633 1.61657552"/>
     <geometry>
     <mesh filename="package://robot_assembler/meshes/mesh_CROSS-SERVO-FRAME-B.dae" scale="1.000000 1.000000 1.000000"/>
     </geometry>
  </visual>
  <collision>
     <origin xyz="-0.000000 -0.000000 0.027500" rpy="1.61657552 1.57079633 1.61657552"/>
     <geometry>
     <mesh filename="package://robot_assembler/meshes/mesh_CROSS-SERVO-FRAME-B.dae" scale="1.000000 1.000000 1.000000"/>
     </geometry>
  </collision>
  </link>
  <xacro:gazebo_link_reference link_name="LINK16" />
  <link name="LINK16">
  <inertial>
     <mass value="0.021241"/>
     <origin rpy="0 0 0" xyz="-4.039332e-17 0.030705 -0.0175"/>
     <inertia ixx="9.742580e-06" ixy="-1.652456e-21" ixz="-6.347568e-21" iyy="4.994969e-06" iyz="-2.273737e-22" izz="9.161660e-06"/>
  </inertial>
  <visual>
     <origin xyz="0.000000 0.035000 -0.004500" rpy="-0.78539816 -1.57079633 2.35619449"/>
     <geometry>
     <mesh filename="package://robot_assembler/meshes/mesh_UPPER-ARM38.dae" scale="1.000000 1.000000 1.000000"/>
     </geometry>
  </visual>
  <collision>
     <origin xyz="0.000000 0.035000 -0.004500" rpy="-0.78539816 -1.57079633 2.35619449"/>
     <geometry>
     <mesh filename="package://robot_assembler/meshes/mesh_UPPER-ARM38.dae" scale="1.000000 1.000000 1.000000"/>
     </geometry>
  </collision>
  <visual>
     <origin xyz="-0.000000 0.035000 -0.017500" rpy="1.33705315 1.57079633 2.90784947"/>
     <geometry>
     <mesh filename="package://robot_assembler/meshes/mesh_JOINT-BASE.dae" scale="1.000000 1.000000 1.000000"/>
     </geometry>
  </visual>
  <collision>
     <origin xyz="-0.000000 0.035000 -0.017500" rpy="1.33705315 1.57079633 2.90784947"/>
     <geometry>
     <mesh filename="package://robot_assembler/meshes/mesh_JOINT-BASE.dae" scale="1.000000 1.000000 1.000000"/>
     </geometry>
  </collision>
  <visual>
     <origin xyz="0.013000 0.035000 -0.017500" rpy="-1.57079633 0.00000000 0.00000000"/>
     <geometry>
     <mesh filename="package://robot_assembler/meshes/mesh_BOTTOM-ARM26.dae" scale="1.000000 1.000000 1.000000"/>
     </geometry>
  </visual>
  <collision>
     <origin xyz="0.013000 0.035000 -0.017500" rpy="-1.57079633 0.00000000 0.00000000"/>
     <geometry>
     <mesh filename="package://robot_assembler/meshes/mesh_BOTTOM-ARM26.dae" scale="1.000000 1.000000 1.000000"/>
     </geometry>
  </collision>
  <visual>
     <origin xyz="-0.013000 0.035000 -0.017500" rpy="1.57079633 -0.00000000 -3.14159265"/>
     <geometry>
     <mesh filename="package://robot_assembler/meshes/mesh_UPPER-ARM26.dae" scale="1.000000 1.000000 1.000000"/>
     </geometry>
  </visual>
  <collision>
     <origin xyz="-0.013000 0.035000 -0.017500" rpy="1.57079633 -0.00000000 -3.14159265"/>
     <geometry>
     <mesh filename="package://robot_assembler/meshes/mesh_UPPER-ARM26.dae" scale="1.000000 1.000000 1.000000"/>
     </geometry>
  </collision>
  <visual>
     <origin xyz="-0.000000 0.035000 -0.030500" rpy="1.98530320 1.57079633 0.41450687"/>
     <geometry>
     <mesh filename="package://robot_assembler/meshes/mesh_BOTTOM-ARM38.dae" scale="1.000000 1.000000 1.000000"/>
     </geometry>
  </visual>
  <collision>
     <origin xyz="-0.000000 0.035000 -0.030500" rpy="1.98530320 1.57079633 0.41450687"/>
     <geometry>
     <mesh filename="package://robot_assembler/meshes/mesh_BOTTOM-ARM38.dae" scale="1.000000 1.000000 1.000000"/>
     </geometry>
  </collision>
  </link>
  <xacro:gazebo_link_reference link_name="LINK17" />
  <link name="LINK17">
  <inertial>
     <mass value="0.068898"/>
     <origin rpy="0 0 0" xyz="-0.02723 -5.099371e-17 -0.017469"/>
     <inertia ixx="0.002003" ixy="-6.703368e-20" ixz="3.115518e-07" iyy="0.002039" iyz="3.710156e-22" izz="0.002037"/>
  </inertial>
  <visual>
     <origin xyz="-0.000000 0.000000 -0.018000" rpy="0.00000000 -0.00000000 -3.14159265"/>
     <geometry>
     <mesh filename="package://robot_assembler/meshes/mesh_SERVO-S3301.dae" scale="1.000000 1.000000 1.000000"/>
     </geometry>
  </visual>
  <collision>
     <origin xyz="-0.000000 0.000000 -0.018000" rpy="0.00000000 -0.00000000 -3.14159265"/>
     <geometry>
     <mesh filename="package://robot_assembler/meshes/mesh_SERVO-S3301.dae" scale="1.000000 1.000000 1.000000"/>
     </geometry>
  </collision>
  <visual>
     <origin xyz="-0.030000 -0.000000 -0.031000" rpy="-2.92027821 1.57079633 1.79211077"/>
     <geometry>
     <mesh filename="package://robot_assembler/meshes/mesh_JOINT-FRAME-A.dae" scale="1.000000 1.000000 1.000000"/>
     </geometry>
  </visual>
  <collision>
     <origin xyz="-0.030000 -0.000000 -0.031000" rpy="-2.92027821 1.57079633 1.79211077"/>
     <geometry>
     <mesh filename="package://robot_assembler/meshes/mesh_JOINT-FRAME-A.dae" scale="1.000000 1.000000 1.000000"/>
     </geometry>
  </collision>
  <visual>
     <origin xyz="-0.030000 -0.000000 -0.005000" rpy="0.00000000 -1.57079633 -1.57079633"/>
     <geometry>
     <mesh filename="package://robot_assembler/meshes/mesh_JOINT-FRAME-A.dae" scale="1.000000 1.000000 1.000000"/>
     </geometry>
  </visual>
  <collision>
     <origin xyz="-0.030000 -0.000000 -0.005000" rpy="0.00000000 -1.57079633 -1.57079633"/>
     <geometry>
     <mesh filename="package://robot_assembler/meshes/mesh_JOINT-FRAME-A.dae" scale="1.000000 1.000000 1.000000"/>
     </geometry>
  </collision>
  <visual>
     <origin xyz="-0.030000 -0.000000 -0.018000" rpy="-0.09221532 1.57079633 -0.09221532"/>
     <geometry>
     <mesh filename="package://robot_assembler/meshes/mesh_JOINT-BASE.dae" scale="1.000000 1.000000 1.000000"/>
     </geometry>
  </visual>
  <collision>
     <origin xyz="-0.030000 -0.000000 -0.018000" rpy="-0.09221532 1.57079633 -0.09221532"/>
     <geometry>
     <mesh filename="package://robot_assembler/meshes/mesh_JOINT-BASE.dae" scale="1.000000 1.000000 1.000000"/>
     </geometry>
  </collision>
  <visual>
     <origin xyz="-0.039000 -0.000000 0.003000" rpy="-3.14159265 -0.00000000 0.00000000"/>
     <geometry>
     <mesh filename="package://robot_assembler/meshes/mesh_BOTTOM-SPACER.dae" scale="1.000000 1.000000 1.000000"/>
     </geometry>
  </visual>
  <collision>
     <origin xyz="-0.039000 -0.000000 0.003000" rpy="-3.14159265 -0.00000000 0.00000000"/>
     <geometry>
     <mesh filename="package://robot_assembler/meshes/mesh_BOTTOM-SPACER.dae" scale="1.000000 1.000000 1.000000"/>
     </geometry>
  </collision>
  <visual>
     <origin xyz="-0.052000 -0.000000 -0.018000" rpy="1.02207046 -1.57079633 -1.02207046"/>
     <geometry>
     <mesh filename="package://robot_assembler/meshes/mesh_SERVO-S3301.dae" scale="1.000000 1.000000 1.000000"/>
     </geometry>
  </visual>
  <collision>
     <origin xyz="-0.052000 -0.000000 -0.018000" rpy="1.02207046 -1.57079633 -1.02207046"/>
     <geometry>
     <mesh filename="package://robot_assembler/meshes/mesh_SERVO-S3301.dae" scale="1.000000 1.000000 1.000000"/>
     </geometry>
  </collision>
  </link>
  <xacro:gazebo_link_reference link_name="LINK18" />
  <link name="LINK18">
  <inertial>
     <mass value="0.012371"/>
     <origin rpy="0 0 0" xyz="4.020531e-18 4.639406e-18 0.011206"/>
     <inertia ixx="1.937420e-06" ixy="1.095076e-21" ixz="-5.684342e-22" iyy="3.583435e-06" iyz="-7.789966e-22" izz="2.583068e-06"/>
  </inertial>
  <visual>
     <origin xyz="0.000000 0.000000 0.002500" rpy="0.00000000 -0.00000000 -0.00000000"/>
     <geometry>
     <mesh filename="package://robot_assembler/meshes/mesh_JOINT-BASE.dae" scale="1.000000 1.000000 1.000000"/>
     </geometry>
  </visual>
  <collision>
     <origin xyz="0.000000 0.000000 0.002500" rpy="0.00000000 -0.00000000 -0.00000000"/>
     <geometry>
     <mesh filename="package://robot_assembler/meshes/mesh_JOINT-BASE.dae" scale="1.000000 1.000000 1.000000"/>
     </geometry>
  </collision>
  <visual>
     <origin xyz="-0.013000 0.000000 0.002500" rpy="0.00000000 -0.00000000 -3.14159265"/>
     <geometry>
     <mesh filename="package://robot_assembler/meshes/mesh_UPPER-ARM28.dae" scale="1.000000 1.000000 1.000000"/>
     </geometry>
  </visual>
  <collision>
     <origin xyz="-0.013000 0.000000 0.002500" rpy="0.00000000 -0.00000000 -3.14159265"/>
     <geometry>
     <mesh filename="package://robot_assembler/meshes/mesh_UPPER-ARM28.dae" scale="1.000000 1.000000 1.000000"/>
     </geometry>
  </collision>
  <visual>
     <origin xyz="0.013000 0.000000 0.002500" rpy="0.00000000 -0.00000000 -0.00000000"/>
     <geometry>
     <mesh filename="package://robot_assembler/meshes/mesh_BOTTOM-ARM28.dae" scale="1.000000 1.000000 1.000000"/>
     </geometry>
  </visual>
  <collision>
     <origin xyz="0.013000 0.000000 0.002500" rpy="0.00000000 -0.00000000 -0.00000000"/>
     <geometry>
     <mesh filename="package://robot_assembler/meshes/mesh_BOTTOM-ARM28.dae" scale="1.000000 1.000000 1.000000"/>
     </geometry>
  </collision>
  </link>
  <xacro:gazebo_link_reference link_name="LINK19" />
  <link name="LINK19">
  <inertial>
     <mass value="0.061777"/>
     <origin rpy="0 0 0" xyz="-0.001295 3.850925e-19 0.001582"/>
     <inertia ixx="0.00202" ixy="-3.208933e-21" ixz="1.039537e-06" iyy="0.002021" iyz="8.891905e-22" izz="0.002002"/>
  </inertial>
  <visual>
     <origin xyz="0.000000 0.000000 -0.018000" rpy="0.00000000 -0.00000000 -3.14159265"/>
     <geometry>
     <mesh filename="package://robot_assembler/meshes/mesh_SERVO-S3301.dae" scale="1.000000 1.000000 1.000000"/>
     </geometry>
  </visual>
  <collision>
     <origin xyz="0.000000 0.000000 -0.018000" rpy="0.00000000 -0.00000000 -3.14159265"/>
     <geometry>
     <mesh filename="package://robot_assembler/meshes/mesh_SERVO-S3301.dae" scale="1.000000 1.000000 1.000000"/>
     </geometry>
  </collision>
  <visual>
     <origin xyz="0.000000 0.000000 0.006500" rpy="1.40690422 1.57079633 1.40690422"/>
     <geometry>
     <mesh filename="package://robot_assembler/meshes/mesh_CROSS-SERVO-FRAME-A.dae" scale="1.000000 1.000000 1.000000"/>
     </geometry>
  </visual>
  <collision>
     <origin xyz="0.000000 0.000000 0.006500" rpy="1.40690422 1.57079633 1.40690422"/>
     <geometry>
     <mesh filename="package://robot_assembler/meshes/mesh_CROSS-SERVO-FRAME-A.dae" scale="1.000000 1.000000 1.000000"/>
     </geometry>
  </collision>
  <visual>
     <origin xyz="-0.000000 0.000000 0.017000" rpy="-1.57079633 0.00000000 -3.14159265"/>
     <geometry>
     <mesh filename="package://robot_assembler/meshes/mesh_SERVO-S3301.dae" scale="1.000000 1.000000 1.000000"/>
     </geometry>
  </visual>
  <collision>
     <origin xyz="-0.000000 0.000000 0.017000" rpy="-1.57079633 0.00000000 -3.14159265"/>
     <geometry>
     <mesh filename="package://robot_assembler/meshes/mesh_SERVO-S3301.dae" scale="1.000000 1.000000 1.000000"/>
     </geometry>
  </collision>
  <visual>
     <origin xyz="-0.000000 -0.000000 0.027500" rpy="1.84083099 1.57079633 1.84083099"/>
     <geometry>
     <mesh filename="package://robot_assembler/meshes/mesh_CROSS-SERVO-FRAME-B.dae" scale="1.000000 1.000000 1.000000"/>
     </geometry>
  </visual>
  <collision>
     <origin xyz="-0.000000 -0.000000 0.027500" rpy="1.84083099 1.57079633 1.84083099"/>
     <geometry>
     <mesh filename="package://robot_assembler/meshes/mesh_CROSS-SERVO-FRAME-B.dae" scale="1.000000 1.000000 1.000000"/>
     </geometry>
  </collision>
  </link>
  <xacro:gazebo_link_reference link_name="LINK20" />
  <link name="LINK20">
  <inertial>
     <mass value="0.050016"/>
     <origin rpy="0 0 0" xyz="-0.046234 0.005542 -0.0175"/>
     <inertia ixx="0.001006" ixy="3.954600e-06" ixz="-2.501110e-20" iyy="0.001021" iyz="4.888534e-21" izz="0.001019"/>
  </inertial>
  <visual>
     <origin xyz="-0.035000 -0.000000 -0.004500" rpy="-0.10835955 -1.57079633 -3.03323311"/>
     <geometry>
     <mesh filename="package://robot_assembler/meshes/mesh_UPPER-ARM38.dae" scale="1.000000 1.000000 1.000000"/>
     </geometry>
  </visual>
  <collision>
     <origin xyz="-0.035000 -0.000000 -0.004500" rpy="-0.10835955 -1.57079633 -3.03323311"/>
     <geometry>
     <mesh filename="package://robot_assembler/meshes/mesh_UPPER-ARM38.dae" scale="1.000000 1.000000 1.000000"/>
     </geometry>
  </collision>
  <visual>
     <origin xyz="-0.035000 -0.000000 -0.017500" rpy="-0.16716665 1.57079633 -0.16716665"/>
     <geometry>
     <mesh filename="package://robot_assembler/meshes/mesh_JOINT-BASE.dae" scale="1.000000 1.000000 1.000000"/>
     </geometry>
  </visual>
  <collision>
     <origin xyz="-0.035000 -0.000000 -0.017500" rpy="-0.16716665 1.57079633 -0.16716665"/>
     <geometry>
     <mesh filename="package://robot_assembler/meshes/mesh_JOINT-BASE.dae" scale="1.000000 1.000000 1.000000"/>
     </geometry>
  </collision>
  <visual>
     <origin xyz="-0.041000 -0.000000 -0.017500" rpy="3.01652269 1.57079633 -0.12506997"/>
     <geometry>
     <mesh filename="package://robot_assembler/meshes/mesh_JOINT-BASE.dae" scale="1.000000 1.000000 1.000000"/>
     </geometry>
  </visual>
  <collision>
     <origin xyz="-0.041000 -0.000000 -0.017500" rpy="3.01652269 1.57079633 -0.12506997"/>
     <geometry>
     <mesh filename="package://robot_assembler/meshes/mesh_JOINT-BASE.dae" scale="1.000000 1.000000 1.000000"/>
     </geometry>
  </collision>
  <visual>
     <origin xyz="-0.041000 -0.000000 -0.004500" rpy="-1.41814700 -1.57079633 2.98894333"/>
     <geometry>
     <mesh filename="package://robot_assembler/meshes/mesh_JOINT-FRAME-A.dae" scale="1.000000 1.000000 1.000000"/>
     </geometry>
  </visual>
  <collision>
     <origin xyz="-0.041000 -0.000000 -0.004500" rpy="-1.41814700 -1.57079633 2.98894333"/>
     <geometry>
     <mesh filename="package://robot_assembler/meshes/mesh_JOINT-FRAME-A.dae" scale="1.000000 1.000000 1.000000"/>
     </geometry>
  </collision>
  <visual>
     <origin xyz="-0.060500 0.010500 -0.017500" rpy="0.00000000 -0.00000000 -1.57079633"/>
     <geometry>
     <mesh filename="package://robot_assembler/meshes/mesh_SERVO-S3301.dae" scale="1.000000 1.000000 1.000000"/>
     </geometry>
  </visual>
  <collision>
     <origin xyz="-0.060500 0.010500 -0.017500" rpy="0.00000000 -0.00000000 -1.57079633"/>
     <geometry>
     <mesh filename="package://robot_assembler/meshes/mesh_SERVO-S3301.dae" scale="1.000000 1.000000 1.000000"/>
     </geometry>
  </collision>
  <visual>
     <origin xyz="-0.041000 -0.000000 -0.030500" rpy="-0.78539816 1.57079633 0.78539816"/>
     <geometry>
     <mesh filename="package://robot_assembler/meshes/mesh_JOINT-FRAME-A.dae" scale="1.000000 1.000000 1.000000"/>
     </geometry>
  </visual>
  <collision>
     <origin xyz="-0.041000 -0.000000 -0.030500" rpy="-0.78539816 1.57079633 0.78539816"/>
     <geometry>
     <mesh filename="package://robot_assembler/meshes/mesh_JOINT-FRAME-A.dae" scale="1.000000 1.000000 1.000000"/>
     </geometry>
  </collision>
  <visual>
     <origin xyz="-0.035000 -0.000000 -0.030500" rpy="-0.19050860 1.57079633 -0.19050860"/>
     <geometry>
     <mesh filename="package://robot_assembler/meshes/mesh_BOTTOM-ARM38.dae" scale="1.000000 1.000000 1.000000"/>
     </geometry>
  </visual>
  <collision>
     <origin xyz="-0.035000 -0.000000 -0.030500" rpy="-0.19050860 1.57079633 -0.19050860"/>
     <geometry>
     <mesh filename="package://robot_assembler/meshes/mesh_BOTTOM-ARM38.dae" scale="1.000000 1.000000 1.000000"/>
     </geometry>
  </collision>
  </link>
  <xacro:gazebo_link_reference link_name="LINK21" />
  <link name="LINK21">
  <inertial>
     <mass value="0.013908"/>
     <origin rpy="0 0 0" xyz="0.0 0.016 -0.018"/>
     <inertia ixx="5.661715e-06" ixy="1.467436e-21" ixz="8.086215e-37" iyy="2.546323e-06" iyz="-1.341510e-21" izz="4.682360e-06"/>
  </inertial>
  <visual>
     <origin xyz="0.000000 0.000000 -0.033500" rpy="1.57079633 1.57079633 1.57079633"/>
     <geometry>
     <mesh filename="package://robot_assembler/meshes/mesh_FINGER.dae" scale="1.000000 1.000000 1.000000"/>
     </geometry>
  </visual>
  <collision>
     <origin xyz="0.000000 0.000000 -0.033500" rpy="1.57079633 1.57079633 1.57079633"/>
     <geometry>
     <mesh filename="package://robot_assembler/meshes/mesh_FINGER.dae" scale="1.000000 1.000000 1.000000"/>
     </geometry>
  </collision>
  </link>
  <xacro:gazebo_link_reference link_name="LINK22" />
  <link name="LINK22">
  <inertial>
     <mass value="0.035533"/>
     <origin rpy="0 0 0" xyz="1.004617e-17 -1.542530e-17 0.025344"/>
     <inertia ixx="0.001006" ixy="-3.984119e-22" ixz="-2.369632e-21" iyy="0.001006" iyz="4.475604e-21" izz="0.001002"/>
  </inertial>
  <visual>
     <origin xyz="0.000000 0.000000 0.002500" rpy="0.00000000 -0.00000000 0.00000000"/>
     <geometry>
     <mesh filename="package://robot_assembler/meshes/mesh_JOINT-BASE.dae" scale="1.000000 1.000000 1.000000"/>
     </geometry>
  </visual>
  <collision>
     <origin xyz="0.000000 0.000000 0.002500" rpy="0.00000000 -0.00000000 0.00000000"/>
     <geometry>
     <mesh filename="package://robot_assembler/meshes/mesh_JOINT-BASE.dae" scale="1.000000 1.000000 1.000000"/>
     </geometry>
  </collision>
  <visual>
     <origin xyz="-0.000000 -0.013000 0.002500" rpy="1.57079633 -0.00000000 -1.57079633"/>
     <geometry>
     <mesh filename="package://robot_assembler/meshes/mesh_JOINT-FRAME-A.dae" scale="1.000000 1.000000 1.000000"/>
     </geometry>
  </visual>
  <collision>
     <origin xyz="-0.000000 -0.013000 0.002500" rpy="1.57079633 -0.00000000 -1.57079633"/>
     <geometry>
     <mesh filename="package://robot_assembler/meshes/mesh_JOINT-FRAME-A.dae" scale="1.000000 1.000000 1.000000"/>
     </geometry>
  </collision>
  <visual>
     <origin xyz="0.000000 0.013000 0.002500" rpy="1.57079633 -0.00000000 1.57079633"/>
     <geometry>
     <mesh filename="package://robot_assembler/meshes/mesh_JOINT-FRAME-A.dae" scale="1.000000 1.000000 1.000000"/>
     </geometry>
  </visual>
  <collision>
     <origin xyz="0.000000 0.013000 0.002500" rpy="1.57079633 -0.00000000 1.57079633"/>
     <geometry>
     <mesh filename="package://robot_assembler/meshes/mesh_JOINT-FRAME-A.dae" scale="1.000000 1.000000 1.000000"/>
     </geometry>
  </collision>
  <visual>
     <origin xyz="0.000000 -0.000000 0.032500" rpy="-2.03444394 1.57079633 2.67794504"/>
     <geometry>
     <mesh filename="package://robot_assembler/meshes/mesh_SERVO-S3301.dae" scale="1.000000 1.000000 1.000000"/>
     </geometry>
  </visual>
  <collision>
     <origin xyz="0.000000 -0.000000 0.032500" rpy="-2.03444394 1.57079633 2.67794504"/>
     <geometry>
     <mesh filename="package://robot_assembler/meshes/mesh_SERVO-S3301.dae" scale="1.000000 1.000000 1.000000"/>
     </geometry>
  </collision>
  </link>
  <xacro:gazebo_link_reference link_name="LINK23" />
  <link name="LINK23">
  <inertial>
     <mass value="0.01216"/>
     <origin rpy="0 0 0" xyz="0.014681 3.641517e-17 -0.017773"/>
     <inertia ixx="2.524786e-06" ixy="1.315184e-21" ixz="-7.542271e-08" iyy="3.418106e-06" iyz="4.602190e-21" izz="1.821371e-06"/>
  </inertial>
  <visual>
     <origin xyz="0.023000 0.000000 -0.004500" rpy="0.00000000 -1.57079633 -0.00000000"/>
     <geometry>
     <mesh filename="package://robot_assembler/meshes/mesh_UPPER-ARM26.dae" scale="1.000000 1.000000 1.000000"/>
     </geometry>
  </visual>
  <collision>
     <origin xyz="0.023000 0.000000 -0.004500" rpy="0.00000000 -1.57079633 -0.00000000"/>
     <geometry>
     <mesh filename="package://robot_assembler/meshes/mesh_UPPER-ARM26.dae" scale="1.000000 1.000000 1.000000"/>
     </geometry>
  </collision>
  <visual>
     <origin xyz="0.023000 0.000000 -0.017500" rpy="1.57079633 0.00000000 -1.57079633"/>
     <geometry>
     <mesh filename="package://robot_assembler/meshes/mesh_JOINT-BASE.dae" scale="1.000000 1.000000 1.000000"/>
     </geometry>
  </visual>
  <collision>
     <origin xyz="0.023000 0.000000 -0.017500" rpy="1.57079633 0.00000000 -1.57079633"/>
     <geometry>
     <mesh filename="package://robot_assembler/meshes/mesh_JOINT-BASE.dae" scale="1.000000 1.000000 1.000000"/>
     </geometry>
  </collision>
  <visual>
     <origin xyz="0.023000 0.000000 -0.030500" rpy="-0.82178958 1.57079633 2.31980307"/>
     <geometry>
     <mesh filename="package://robot_assembler/meshes/mesh_BOTTOM-ARM28.dae" scale="1.000000 1.000000 1.000000"/>
     </geometry>
  </visual>
  <collision>
     <origin xyz="0.023000 0.000000 -0.030500" rpy="-0.82178958 1.57079633 2.31980307"/>
     <geometry>
     <mesh filename="package://robot_assembler/meshes/mesh_BOTTOM-ARM28.dae" scale="1.000000 1.000000 1.000000"/>
     </geometry>
  </collision>
  </link>
  <xacro:gazebo_link_reference link_name="LINK24" />
  <link name="LINK24">
  <inertial>
     <mass value="0.012371"/>
     <origin rpy="0 0 0" xyz="6.185874e-18 -4.020531e-18 0.011206"/>
     <inertia ixx="3.583435e-06" ixy="-6.341998e-22" ixz="-7.431646e-22" iyy="1.937420e-06" iyz="2.842171e-21" izz="2.583068e-06"/>
  </inertial>
  <visual>
     <origin xyz="0.000000 0.000000 0.002500" rpy="-0.00000000 -0.00000000 -1.57079633"/>
     <geometry>
     <mesh filename="package://robot_assembler/meshes/mesh_JOINT-BASE.dae" scale="1.000000 1.000000 1.000000"/>
     </geometry>
  </visual>
  <collision>
     <origin xyz="0.000000 0.000000 0.002500" rpy="-0.00000000 -0.00000000 -1.57079633"/>
     <geometry>
     <mesh filename="package://robot_assembler/meshes/mesh_JOINT-BASE.dae" scale="1.000000 1.000000 1.000000"/>
     </geometry>
  </collision>
  <visual>
     <origin xyz="0.000000 0.013000 0.002500" rpy="0.00000000 -0.00000000 1.57079633"/>
     <geometry>
     <mesh filename="package://robot_assembler/meshes/mesh_UPPER-ARM28.dae" scale="1.000000 1.000000 1.000000"/>
     </geometry>
  </visual>
  <collision>
     <origin xyz="0.000000 0.013000 0.002500" rpy="0.00000000 -0.00000000 1.57079633"/>
     <geometry>
     <mesh filename="package://robot_assembler/meshes/mesh_UPPER-ARM28.dae" scale="1.000000 1.000000 1.000000"/>
     </geometry>
  </collision>
  <visual>
     <origin xyz="0.000000 -0.013000 0.002500" rpy="0.00000000 0.00000000 -1.57079633"/>
     <geometry>
     <mesh filename="package://robot_assembler/meshes/mesh_BOTTOM-ARM28.dae" scale="1.000000 1.000000 1.000000"/>
     </geometry>
  </visual>
  <collision>
     <origin xyz="0.000000 -0.013000 0.002500" rpy="0.00000000 0.00000000 -1.57079633"/>
     <geometry>
     <mesh filename="package://robot_assembler/meshes/mesh_BOTTOM-ARM28.dae" scale="1.000000 1.000000 1.000000"/>
     </geometry>
  </collision>
  </link>
  <xacro:gazebo_link_reference link_name="LINK25" />
  <link name="LINK25">
  <inertial>
     <mass value="0.061777"/>
     <origin rpy="0 0 0" xyz="-0.001295 -5.467695e-18 0.001582"/>
     <inertia ixx="0.00202" ixy="-2.953871e-21" ixz="1.039537e-06" iyy="0.002021" iyz="1.264507e-20" izz="0.002002"/>
  </inertial>
  <visual>
     <origin xyz="-0.000000 0.000000 -0.018000" rpy="-0.00000000 0.00000000 -3.14159265"/>
     <geometry>
     <mesh filename="package://robot_assembler/meshes/mesh_SERVO-S3301.dae" scale="1.000000 1.000000 1.000000"/>
     </geometry>
  </visual>
  <collision>
     <origin xyz="-0.000000 0.000000 -0.018000" rpy="-0.00000000 0.00000000 -3.14159265"/>
     <geometry>
     <mesh filename="package://robot_assembler/meshes/mesh_SERVO-S3301.dae" scale="1.000000 1.000000 1.000000"/>
     </geometry>
  </collision>
  <visual>
     <origin xyz="-0.000000 0.000000 0.006500" rpy="1.30362167 1.57079633 1.30362167"/>
     <geometry>
     <mesh filename="package://robot_assembler/meshes/mesh_CROSS-SERVO-FRAME-A.dae" scale="1.000000 1.000000 1.000000"/>
     </geometry>
  </visual>
  <collision>
     <origin xyz="-0.000000 0.000000 0.006500" rpy="1.30362167 1.57079633 1.30362167"/>
     <geometry>
     <mesh filename="package://robot_assembler/meshes/mesh_CROSS-SERVO-FRAME-A.dae" scale="1.000000 1.000000 1.000000"/>
     </geometry>
  </collision>
  <visual>
     <origin xyz="-0.000000 -0.000000 0.017000" rpy="-1.57079633 0.00000000 -3.14159265"/>
     <geometry>
     <mesh filename="package://robot_assembler/meshes/mesh_SERVO-S3301.dae" scale="1.000000 1.000000 1.000000"/>
     </geometry>
  </visual>
  <collision>
     <origin xyz="-0.000000 -0.000000 0.017000" rpy="-1.57079633 0.00000000 -3.14159265"/>
     <geometry>
     <mesh filename="package://robot_assembler/meshes/mesh_SERVO-S3301.dae" scale="1.000000 1.000000 1.000000"/>
     </geometry>
  </collision>
  <visual>
     <origin xyz="-0.000000 -0.000000 0.027500" rpy="1.69795983 1.57079633 1.69795983"/>
     <geometry>
     <mesh filename="package://robot_assembler/meshes/mesh_CROSS-SERVO-FRAME-B.dae" scale="1.000000 1.000000 1.000000"/>
     </geometry>
  </visual>
  <collision>
     <origin xyz="-0.000000 -0.000000 0.027500" rpy="1.69795983 1.57079633 1.69795983"/>
     <geometry>
     <mesh filename="package://robot_assembler/meshes/mesh_CROSS-SERVO-FRAME-B.dae" scale="1.000000 1.000000 1.000000"/>
     </geometry>
  </collision>
  </link>
  <xacro:gazebo_link_reference link_name="LINK26" />
  <link name="LINK26">
  <inertial>
     <mass value="0.026432"/>
     <origin rpy="0 0 0" xyz="-0.034261 -8.180596e-17 -0.0175"/>
     <inertia ixx="5.625676e-06" ixy="-7.157577e-21" ixz="-9.094947e-21" iyy="1.356566e-05" iyz="-5.259471e-21" izz="9.886202e-06"/>
  </inertial>
  <visual>
     <origin xyz="-0.035000 -0.000000 -0.004500" rpy="0.00000000 -1.57079633 -3.14159265"/>
     <geometry>
     <mesh filename="package://robot_assembler/meshes/mesh_UPPER-ARM38.dae" scale="1.000000 1.000000 1.000000"/>
     </geometry>
  </visual>
  <collision>
     <origin xyz="-0.035000 -0.000000 -0.004500" rpy="0.00000000 -1.57079633 -3.14159265"/>
     <geometry>
     <mesh filename="package://robot_assembler/meshes/mesh_UPPER-ARM38.dae" scale="1.000000 1.000000 1.000000"/>
     </geometry>
  </collision>
  <visual>
     <origin xyz="-0.035000 -0.000000 -0.017500" rpy="-1.57079633 -0.00000000 -1.57079633"/>
     <geometry>
     <mesh filename="package://robot_assembler/meshes/mesh_JOINT-BASE.dae" scale="1.000000 1.000000 1.000000"/>
     </geometry>
  </visual>
  <collision>
     <origin xyz="-0.035000 -0.000000 -0.017500" rpy="-1.57079633 -0.00000000 -1.57079633"/>
     <geometry>
     <mesh filename="package://robot_assembler/meshes/mesh_JOINT-BASE.dae" scale="1.000000 1.000000 1.000000"/>
     </geometry>
  </collision>
  <visual>
     <origin xyz="-0.041000 -0.000000 -0.017500" rpy="1.57079633 -0.00000000 -1.57079633"/>
     <geometry>
     <mesh filename="package://robot_assembler/meshes/mesh_JOINT-BASE.dae" scale="1.000000 1.000000 1.000000"/>
     </geometry>
  </visual>
  <collision>
     <origin xyz="-0.041000 -0.000000 -0.017500" rpy="1.57079633 -0.00000000 -1.57079633"/>
     <geometry>
     <mesh filename="package://robot_assembler/meshes/mesh_JOINT-BASE.dae" scale="1.000000 1.000000 1.000000"/>
     </geometry>
  </collision>
  <visual>
     <origin xyz="-0.041000 -0.000000 -0.030500" rpy="2.52900494 1.57079633 -0.61258771"/>
     <geometry>
     <mesh filename="package://robot_assembler/meshes/mesh_BOTTOM-ARM26.dae" scale="1.000000 1.000000 1.000000"/>
     </geometry>
  </visual>
  <collision>
     <origin xyz="-0.041000 -0.000000 -0.030500" rpy="2.52900494 1.57079633 -0.61258771"/>
     <geometry>
     <mesh filename="package://robot_assembler/meshes/mesh_BOTTOM-ARM26.dae" scale="1.000000 1.000000 1.000000"/>
     </geometry>
  </collision>
  <visual>
     <origin xyz="-0.041000 -0.000000 -0.004500" rpy="-2.46811862 -1.57079633 2.46811862"/>
     <geometry>
     <mesh filename="package://robot_assembler/meshes/mesh_UPPER-ARM26.dae" scale="1.000000 1.000000 1.000000"/>
     </geometry>
  </visual>
  <collision>
     <origin xyz="-0.041000 -0.000000 -0.004500" rpy="-2.46811862 -1.57079633 2.46811862"/>
     <geometry>
     <mesh filename="package://robot_assembler/meshes/mesh_UPPER-ARM26.dae" scale="1.000000 1.000000 1.000000"/>
     </geometry>
  </collision>
  <visual>
     <origin xyz="-0.035000 -0.000000 -0.030500" rpy="0.42911069 1.57079633 0.42911069"/>
     <geometry>
     <mesh filename="package://robot_assembler/meshes/mesh_BOTTOM-ARM38.dae" scale="1.000000 1.000000 1.000000"/>
     </geometry>
  </visual>
  <collision>
     <origin xyz="-0.035000 -0.000000 -0.030500" rpy="0.42911069 1.57079633 0.42911069"/>
     <geometry>
     <mesh filename="package://robot_assembler/meshes/mesh_BOTTOM-ARM38.dae" scale="1.000000 1.000000 1.000000"/>
     </geometry>
  </collision>
  </link>
  <xacro:gazebo_link_reference link_name="LINK27" />
  <link name="LINK27">
  <inertial>
     <mass value="0.055048"/>
     <origin rpy="0 0 0" xyz="-0.01223 -0.007733 -0.018"/>
     <inertia ixx="0.001018" ixy="-4.797495e-06" ixz="-2.728484e-21" iyy="0.001012" iyz="-3.637979e-21" izz="0.001022"/>
  </inertial>
  <visual>
     <origin xyz="0.000000 0.000000 -0.018000" rpy="-0.00000000 -0.00000000 -3.14159265"/>
     <geometry>
     <mesh filename="package://robot_assembler/meshes/mesh_SERVO-S3301.dae" scale="1.000000 1.000000 1.000000"/>
     </geometry>
  </visual>
  <collision>
     <origin xyz="0.000000 0.000000 -0.018000" rpy="-0.00000000 -0.00000000 -3.14159265"/>
     <geometry>
     <mesh filename="package://robot_assembler/meshes/mesh_SERVO-S3301.dae" scale="1.000000 1.000000 1.000000"/>
     </geometry>
  </collision>
  <visual>
     <origin xyz="-0.023500 -0.000000 -0.033000" rpy="-1.95065744 1.57079633 1.19093521"/>
     <geometry>
     <mesh filename="package://robot_assembler/meshes/mesh_ANGLE-BRACKET.dae" scale="1.000000 1.000000 1.000000"/>
     </geometry>
  </visual>
  <collision>
     <origin xyz="-0.023500 -0.000000 -0.033000" rpy="-1.95065744 1.57079633 1.19093521"/>
     <geometry>
     <mesh filename="package://robot_assembler/meshes/mesh_ANGLE-BRACKET.dae" scale="1.000000 1.000000 1.000000"/>
     </geometry>
  </collision>
  <visual>
     <origin xyz="-0.023500 -0.018000 -0.031000" rpy="2.40615289 1.57079633 0.83535656"/>
     <geometry>
     <mesh filename="package://robot_assembler/meshes/mesh_BOTTOM-ARM38.dae" scale="1.000000 1.000000 1.000000"/>
     </geometry>
  </visual>
  <collision>
     <origin xyz="-0.023500 -0.018000 -0.031000" rpy="2.40615289 1.57079633 0.83535656"/>
     <geometry>
     <mesh filename="package://robot_assembler/meshes/mesh_BOTTOM-ARM38.dae" scale="1.000000 1.000000 1.000000"/>
     </geometry>
  </collision>
  <visual>
     <origin xyz="-0.023500 -0.000000 -0.018000" rpy="0.00000000 1.57079633 -3.14159265"/>
     <geometry>
     <mesh filename="package://robot_assembler/meshes/mesh_ANGLE-BRACKET.dae" scale="1.000000 1.000000 1.000000"/>
     </geometry>
  </visual>
  <collision>
     <origin xyz="-0.023500 -0.000000 -0.018000" rpy="0.00000000 1.57079633 -3.14159265"/>
     <geometry>
     <mesh filename="package://robot_assembler/meshes/mesh_ANGLE-BRACKET.dae" scale="1.000000 1.000000 1.000000"/>
     </geometry>
  </collision>
  <visual>
     <origin xyz="-0.023500 -0.018000 -0.005000" rpy="-1.57079633 -1.57079633 3.14159265"/>
     <geometry>
     <mesh filename="package://robot_assembler/meshes/mesh_UPPER-ARM38.dae" scale="1.000000 1.000000 1.000000"/>
     </geometry>
  </visual>
  <collision>
     <origin xyz="-0.023500 -0.018000 -0.005000" rpy="-1.57079633 -1.57079633 3.14159265"/>
     <geometry>
     <mesh filename="package://robot_assembler/meshes/mesh_UPPER-ARM38.dae" scale="1.000000 1.000000 1.000000"/>
     </geometry>
  </collision>
  </link>
  <xacro:gazebo_link_reference link_name="LINK28" />
  <link name="LINK28">
  <inertial>
     <mass value="0.061777"/>
     <origin rpy="0 0 0" xyz="-0.010731 -0.015418 -0.018"/>
     <inertia ixx="0.00202" ixy="-9.587219e-06" ixz="-9.584968e-21" iyy="0.002007" iyz="-1.842928e-20" izz="0.002026"/>
  </inertial>
  <visual>
     <origin xyz="-0.000000 0.000000 -0.018000" rpy="0.00000000 -0.00000000 -3.14159265"/>
     <geometry>
     <mesh filename="package://robot_assembler/meshes/mesh_SERVO-S3301.dae" scale="1.000000 1.000000 1.000000"/>
     </geometry>
  </visual>
  <collision>
     <origin xyz="-0.000000 0.000000 -0.018000" rpy="0.00000000 -0.00000000 -3.14159265"/>
     <geometry>
     <mesh filename="package://robot_assembler/meshes/mesh_SERVO-S3301.dae" scale="1.000000 1.000000 1.000000"/>
     </geometry>
  </collision>
  <visual>
     <origin xyz="-0.021000 0.010500 -0.018000" rpy="1.57079633 -0.00000000 -1.57079633"/>
     <geometry>
     <mesh filename="package://robot_assembler/meshes/mesh_CROSS-SERVO-FRAME-B.dae" scale="1.000000 1.000000 1.000000"/>
     </geometry>
  </visual>
  <collision>
     <origin xyz="-0.021000 0.010500 -0.018000" rpy="1.57079633 -0.00000000 -1.57079633"/>
     <geometry>
     <mesh filename="package://robot_assembler/meshes/mesh_CROSS-SERVO-FRAME-B.dae" scale="1.000000 1.000000 1.000000"/>
     </geometry>
  </collision>
  <visual>
     <origin xyz="-0.021000 -0.010500 -0.018000" rpy="1.57079633 -0.00000000 -1.57079633"/>
     <geometry>
     <mesh filename="package://robot_assembler/meshes/mesh_CROSS-SERVO-FRAME-A.dae" scale="1.000000 1.000000 1.000000"/>
     </geometry>
  </visual>
  <collision>
     <origin xyz="-0.021000 -0.010500 -0.018000" rpy="1.57079633 -0.00000000 -1.57079633"/>
     <geometry>
     <mesh filename="package://robot_assembler/meshes/mesh_CROSS-SERVO-FRAME-A.dae" scale="1.000000 1.000000 1.000000"/>
     </geometry>
  </collision>
  <visual>
     <origin xyz="-0.021000 -0.035000 -0.018000" rpy="-1.57079633 -0.00000000 0.00000000"/>
     <geometry>
     <mesh filename="package://robot_assembler/meshes/mesh_SERVO-S3301.dae" scale="1.000000 1.000000 1.000000"/>
     </geometry>
  </visual>
  <collision>
     <origin xyz="-0.021000 -0.035000 -0.018000" rpy="-1.57079633 -0.00000000 0.00000000"/>
     <geometry>
     <mesh filename="package://robot_assembler/meshes/mesh_SERVO-S3301.dae" scale="1.000000 1.000000 1.000000"/>
     </geometry>
  </collision>
  </link>
  <xacro:gazebo_link_reference link_name="LINK29" />
  <link name="LINK29">
  <inertial>
     <mass value="0.045736"/>
     <origin rpy="0 0 0" xyz="0.03622 -8.334056e-17 0.0162"/>
     <inertia ixx="0.001004" ixy="1.124337e-20" ixz="-2.000101e-07" iyy="0.001013" iyz="7.987531e-21" izz="0.001011"/>
  </inertial>
  <visual>
     <origin xyz="0.025000 -0.000000 0.004000" rpy="-1.23095942 1.57079633 1.91063324"/>
     <geometry>
     <mesh filename="package://robot_assembler/meshes/mesh_UPPER-ARM28.dae" scale="1.000000 1.000000 1.000000"/>
     </geometry>
  </visual>
  <collision>
     <origin xyz="0.025000 -0.000000 0.004000" rpy="-1.23095942 1.57079633 1.91063324"/>
     <geometry>
     <mesh filename="package://robot_assembler/meshes/mesh_UPPER-ARM28.dae" scale="1.000000 1.000000 1.000000"/>
     </geometry>
  </collision>
  <visual>
     <origin xyz="0.025000 -0.000000 0.017000" rpy="1.44293286 -1.57079633 -1.44293286"/>
     <geometry>
     <mesh filename="package://robot_assembler/meshes/mesh_JOINT-BASE.dae" scale="1.000000 1.000000 1.000000"/>
     </geometry>
  </visual>
  <collision>
     <origin xyz="0.025000 -0.000000 0.017000" rpy="1.44293286 -1.57079633 -1.44293286"/>
     <geometry>
     <mesh filename="package://robot_assembler/meshes/mesh_JOINT-BASE.dae" scale="1.000000 1.000000 1.000000"/>
     </geometry>
  </collision>
  <visual>
     <origin xyz="0.034000 -0.000000 -0.004000" rpy="-0.00000000 -0.00000000 3.14159265"/>
     <geometry>
     <mesh filename="package://robot_assembler/meshes/mesh_BOTTOM-SPACER.dae" scale="1.000000 1.000000 1.000000"/>
     </geometry>
  </visual>
  <collision>
     <origin xyz="0.034000 -0.000000 -0.004000" rpy="-0.00000000 -0.00000000 3.14159265"/>
     <geometry>
     <mesh filename="package://robot_assembler/meshes/mesh_BOTTOM-SPACER.dae" scale="1.000000 1.000000 1.000000"/>
     </geometry>
  </collision>
  <visual>
     <origin xyz="0.047000 -0.000000 0.017000" rpy="0.82745315 1.57079633 0.82745315"/>
     <geometry>
     <mesh filename="package://robot_assembler/meshes/mesh_SERVO-S3301.dae" scale="1.000000 1.000000 1.000000"/>
     </geometry>
  </visual>
  <collision>
     <origin xyz="0.047000 -0.000000 0.017000" rpy="0.82745315 1.57079633 0.82745315"/>
     <geometry>
     <mesh filename="package://robot_assembler/meshes/mesh_SERVO-S3301.dae" scale="1.000000 1.000000 1.000000"/>
     </geometry>
  </collision>
  <visual>
     <origin xyz="0.025000 -0.000000 0.030000" rpy="1.62312679 -1.57079633 -1.62312679"/>
     <geometry>
     <mesh filename="package://robot_assembler/meshes/mesh_BOTTOM-ARM28.dae" scale="1.000000 1.000000 1.000000"/>
     </geometry>
  </visual>
  <collision>
     <origin xyz="0.025000 -0.000000 0.030000" rpy="1.62312679 -1.57079633 -1.62312679"/>
     <geometry>
     <mesh filename="package://robot_assembler/meshes/mesh_BOTTOM-ARM28.dae" scale="1.000000 1.000000 1.000000"/>
     </geometry>
  </collision>
  </link>
  <xacro:gazebo_link_reference link_name="LINK30" />
  <link name="LINK30">
  <inertial>
     <mass value="0.03987"/>
     <origin rpy="0 0 0" xyz="0.031 -0.031 -0.005"/>
     <inertia ixx="2.472604e-05" ixy="-7.064363e-21" ixz="-1.441255e-20" iyy="1.292452e-05" iyz="6.263253e-36" izz="1.292452e-05"/>
  </inertial>
  <visual>
     <origin xyz="0.031000 -0.031000 -0.005000" rpy="0.74595001 -1.57079633 -0.74595001"/>
     <geometry>
     <mesh filename="package://robot_assembler/meshes/kxr_uav/wheel_foot.STL" scale="0.001000 0.001000 0.001000"/>
     </geometry>
  </visual>
  <collision>
     <origin xyz="0.031000 -0.031000 -0.005000" rpy="0.74595001 -1.57079633 -0.74595001"/>
     <geometry>
     <mesh filename="package://robot_assembler/meshes/kxr_uav/wheel_foot.STL" scale="0.001000 0.001000 0.001000"/>
     </geometry>
  </collision>
  </link>
  <xacro:gazebo_link_reference link_name="LINK31" />
  <link name="LINK31">
  <inertial>
     <mass value="0.012371"/>
     <origin rpy="0 0 0" xyz="0.0 -5.743616e-19 0.011206"/>
     <inertia ixx="3.583435e-06" ixy="-3.262807e-21" ixz="3.979844e-22" iyy="1.937420e-06" iyz="5.115908e-22" izz="2.583068e-06"/>
  </inertial>
  <visual>
     <origin xyz="0.000000 -0.000000 0.002500" rpy="0.00000000 0.00000000 1.57079633"/>
     <geometry>
     <mesh filename="package://robot_assembler/meshes/mesh_JOINT-BASE.dae" scale="1.000000 1.000000 1.000000"/>
     </geometry>
  </visual>
  <collision>
     <origin xyz="0.000000 -0.000000 0.002500" rpy="0.00000000 0.00000000 1.57079633"/>
     <geometry>
     <mesh filename="package://robot_assembler/meshes/mesh_JOINT-BASE.dae" scale="1.000000 1.000000 1.000000"/>
     </geometry>
  </collision>
  <visual>
     <origin xyz="-0.000000 -0.013000 0.002500" rpy="0.00000000 -0.00000000 -1.57079633"/>
     <geometry>
     <mesh filename="package://robot_assembler/meshes/mesh_UPPER-ARM28.dae" scale="1.000000 1.000000 1.000000"/>
     </geometry>
  </visual>
  <collision>
     <origin xyz="-0.000000 -0.013000 0.002500" rpy="0.00000000 -0.00000000 -1.57079633"/>
     <geometry>
     <mesh filename="package://robot_assembler/meshes/mesh_UPPER-ARM28.dae" scale="1.000000 1.000000 1.000000"/>
     </geometry>
  </collision>
  <visual>
     <origin xyz="0.000000 0.013000 0.002500" rpy="0.00000000 0.00000000 1.57079633"/>
     <geometry>
     <mesh filename="package://robot_assembler/meshes/mesh_BOTTOM-ARM28.dae" scale="1.000000 1.000000 1.000000"/>
     </geometry>
  </visual>
  <collision>
     <origin xyz="0.000000 0.013000 0.002500" rpy="0.00000000 0.00000000 1.57079633"/>
     <geometry>
     <mesh filename="package://robot_assembler/meshes/mesh_BOTTOM-ARM28.dae" scale="1.000000 1.000000 1.000000"/>
     </geometry>
  </collision>
  </link>
  <xacro:gazebo_link_reference link_name="LINK32" />
  <link name="LINK32">
  <inertial>
     <mass value="0.061777"/>
     <origin rpy="0 0 0" xyz="-0.001295 1.129516e-17 0.001582"/>
     <inertia ixx="0.00202" ixy="-1.668146e-21" ixz="1.039537e-06" iyy="0.002021" iyz="-4.374341e-21" izz="0.002002"/>
  </inertial>
  <visual>
     <origin xyz="0.000000 0.000000 -0.018000" rpy="0.00000000 -0.00000000 -3.14159265"/>
     <geometry>
     <mesh filename="package://robot_assembler/meshes/mesh_SERVO-S3301.dae" scale="1.000000 1.000000 1.000000"/>
     </geometry>
  </visual>
  <collision>
     <origin xyz="0.000000 0.000000 -0.018000" rpy="0.00000000 -0.00000000 -3.14159265"/>
     <geometry>
     <mesh filename="package://robot_assembler/meshes/mesh_SERVO-S3301.dae" scale="1.000000 1.000000 1.000000"/>
     </geometry>
  </collision>
  <visual>
     <origin xyz="-0.000000 0.000000 0.006500" rpy="1.20268268 1.57079633 1.20268268"/>
     <geometry>
     <mesh filename="package://robot_assembler/meshes/mesh_CROSS-SERVO-FRAME-A.dae" scale="1.000000 1.000000 1.000000"/>
     </geometry>
  </visual>
  <collision>
     <origin xyz="-0.000000 0.000000 0.006500" rpy="1.20268268 1.57079633 1.20268268"/>
     <geometry>
     <mesh filename="package://robot_assembler/meshes/mesh_CROSS-SERVO-FRAME-A.dae" scale="1.000000 1.000000 1.000000"/>
     </geometry>
  </collision>
  <visual>
     <origin xyz="-0.000000 0.000000 0.017000" rpy="-1.57079633 0.00000000 -3.14159265"/>
     <geometry>
     <mesh filename="package://robot_assembler/meshes/mesh_SERVO-S3301.dae" scale="1.000000 1.000000 1.000000"/>
     </geometry>
  </visual>
  <collision>
     <origin xyz="-0.000000 0.000000 0.017000" rpy="-1.57079633 0.00000000 -3.14159265"/>
     <geometry>
     <mesh filename="package://robot_assembler/meshes/mesh_SERVO-S3301.dae" scale="1.000000 1.000000 1.000000"/>
     </geometry>
  </collision>
  <visual>
     <origin xyz="-0.000000 0.000000 0.027500" rpy="1.82724238 1.57079633 1.82724238"/>
     <geometry>
     <mesh filename="package://robot_assembler/meshes/mesh_CROSS-SERVO-FRAME-B.dae" scale="1.000000 1.000000 1.000000"/>
     </geometry>
  </visual>
  <collision>
     <origin xyz="-0.000000 0.000000 0.027500" rpy="1.82724238 1.57079633 1.82724238"/>
     <geometry>
     <mesh filename="package://robot_assembler/meshes/mesh_CROSS-SERVO-FRAME-B.dae" scale="1.000000 1.000000 1.000000"/>
     </geometry>
  </collision>
  </link>
  <xacro:gazebo_link_reference link_name="LINK33" />
  <link name="LINK33">
  <inertial>
     <mass value="0.026432"/>
     <origin rpy="0 0 0" xyz="-0.034261 -8.344401e-17 -0.0175"/>
     <inertia ixx="5.625676e-06" ixy="-4.725823e-21" ixz="-3.865352e-21" iyy="1.356566e-05" iyz="-8.224757e-21" izz="9.886202e-06"/>
  </inertial>
  <visual>
     <origin xyz="-0.035000 -0.000000 -0.004500" rpy="-0.00000000 -1.57079633 -3.14159265"/>
     <geometry>
     <mesh filename="package://robot_assembler/meshes/mesh_UPPER-ARM38.dae" scale="1.000000 1.000000 1.000000"/>
     </geometry>
  </visual>
  <collision>
     <origin xyz="-0.035000 -0.000000 -0.004500" rpy="-0.00000000 -1.57079633 -3.14159265"/>
     <geometry>
     <mesh filename="package://robot_assembler/meshes/mesh_UPPER-ARM38.dae" scale="1.000000 1.000000 1.000000"/>
     </geometry>
  </collision>
  <visual>
     <origin xyz="-0.035000 -0.000000 -0.017500" rpy="-1.57079633 -0.00000000 -1.57079633"/>
     <geometry>
     <mesh filename="package://robot_assembler/meshes/mesh_JOINT-BASE.dae" scale="1.000000 1.000000 1.000000"/>
     </geometry>
  </visual>
  <collision>
     <origin xyz="-0.035000 -0.000000 -0.017500" rpy="-1.57079633 -0.00000000 -1.57079633"/>
     <geometry>
     <mesh filename="package://robot_assembler/meshes/mesh_JOINT-BASE.dae" scale="1.000000 1.000000 1.000000"/>
     </geometry>
  </collision>
  <visual>
     <origin xyz="-0.041000 -0.000000 -0.017500" rpy="1.57079633 -0.00000000 -1.57079633"/>
     <geometry>
     <mesh filename="package://robot_assembler/meshes/mesh_JOINT-BASE.dae" scale="1.000000 1.000000 1.000000"/>
     </geometry>
  </visual>
  <collision>
     <origin xyz="-0.041000 -0.000000 -0.017500" rpy="1.57079633 -0.00000000 -1.57079633"/>
     <geometry>
     <mesh filename="package://robot_assembler/meshes/mesh_JOINT-BASE.dae" scale="1.000000 1.000000 1.000000"/>
     </geometry>
  </collision>
  <visual>
     <origin xyz="-0.041000 -0.000000 -0.030500" rpy="2.20480221 1.57079633 -0.93679045"/>
     <geometry>
     <mesh filename="package://robot_assembler/meshes/mesh_BOTTOM-ARM26.dae" scale="1.000000 1.000000 1.000000"/>
     </geometry>
  </visual>
  <collision>
     <origin xyz="-0.041000 -0.000000 -0.030500" rpy="2.20480221 1.57079633 -0.93679045"/>
     <geometry>
     <mesh filename="package://robot_assembler/meshes/mesh_BOTTOM-ARM26.dae" scale="1.000000 1.000000 1.000000"/>
     </geometry>
  </collision>
  <visual>
     <origin xyz="-0.041000 -0.000000 -0.004500" rpy="-2.14517755 -1.57079633 2.14517755"/>
     <geometry>
     <mesh filename="package://robot_assembler/meshes/mesh_UPPER-ARM26.dae" scale="1.000000 1.000000 1.000000"/>
     </geometry>
  </visual>
  <collision>
     <origin xyz="-0.041000 -0.000000 -0.004500" rpy="-2.14517755 -1.57079633 2.14517755"/>
     <geometry>
     <mesh filename="package://robot_assembler/meshes/mesh_UPPER-ARM26.dae" scale="1.000000 1.000000 1.000000"/>
     </geometry>
  </collision>
  <visual>
     <origin xyz="-0.035000 -0.000000 -0.030500" rpy="-0.23008562 1.57079633 -0.23008562"/>
     <geometry>
     <mesh filename="package://robot_assembler/meshes/mesh_BOTTOM-ARM38.dae" scale="1.000000 1.000000 1.000000"/>
     </geometry>
  </visual>
  <collision>
     <origin xyz="-0.035000 -0.000000 -0.030500" rpy="-0.23008562 1.57079633 -0.23008562"/>
     <geometry>
     <mesh filename="package://robot_assembler/meshes/mesh_BOTTOM-ARM38.dae" scale="1.000000 1.000000 1.000000"/>
     </geometry>
  </collision>
  </link>
  <xacro:gazebo_link_reference link_name="LINK34" />
  <link name="LINK34">
  <inertial>
     <mass value="0.055048"/>
     <origin rpy="0 0 0" xyz="-0.01223 -0.007733 -0.018"/>
     <inertia ixx="0.001018" ixy="-4.797495e-06" ixz="-3.637979e-21" iyy="0.001012" iyz="-7.730705e-21" izz="0.001022"/>
  </inertial>
  <visual>
     <origin xyz="0.000000 0.000000 -0.018000" rpy="0.00000000 0.00000000 -3.14159265"/>
     <geometry>
     <mesh filename="package://robot_assembler/meshes/mesh_SERVO-S3301.dae" scale="1.000000 1.000000 1.000000"/>
     </geometry>
  </visual>
  <collision>
     <origin xyz="0.000000 0.000000 -0.018000" rpy="0.00000000 0.00000000 -3.14159265"/>
     <geometry>
     <mesh filename="package://robot_assembler/meshes/mesh_SERVO-S3301.dae" scale="1.000000 1.000000 1.000000"/>
     </geometry>
  </collision>
  <visual>
     <origin xyz="-0.023500 -0.000000 -0.033000" rpy="-1.95065744 1.57079633 1.19093521"/>
     <geometry>
     <mesh filename="package://robot_assembler/meshes/mesh_ANGLE-BRACKET.dae" scale="1.000000 1.000000 1.000000"/>
     </geometry>
  </visual>
  <collision>
     <origin xyz="-0.023500 -0.000000 -0.033000" rpy="-1.95065744 1.57079633 1.19093521"/>
     <geometry>
     <mesh filename="package://robot_assembler/meshes/mesh_ANGLE-BRACKET.dae" scale="1.000000 1.000000 1.000000"/>
     </geometry>
  </collision>
  <visual>
     <origin xyz="-0.023500 -0.018000 -0.031000" rpy="2.57227946 1.57079633 1.00148314"/>
     <geometry>
     <mesh filename="package://robot_assembler/meshes/mesh_BOTTOM-ARM38.dae" scale="1.000000 1.000000 1.000000"/>
     </geometry>
  </visual>
  <collision>
     <origin xyz="-0.023500 -0.018000 -0.031000" rpy="2.57227946 1.57079633 1.00148314"/>
     <geometry>
     <mesh filename="package://robot_assembler/meshes/mesh_BOTTOM-ARM38.dae" scale="1.000000 1.000000 1.000000"/>
     </geometry>
  </collision>
  <visual>
     <origin xyz="-0.023500 -0.000000 -0.018000" rpy="0.00000000 1.57079633 -3.14159265"/>
     <geometry>
     <mesh filename="package://robot_assembler/meshes/mesh_ANGLE-BRACKET.dae" scale="1.000000 1.000000 1.000000"/>
     </geometry>
  </visual>
  <collision>
     <origin xyz="-0.023500 -0.000000 -0.018000" rpy="0.00000000 1.57079633 -3.14159265"/>
     <geometry>
     <mesh filename="package://robot_assembler/meshes/mesh_ANGLE-BRACKET.dae" scale="1.000000 1.000000 1.000000"/>
     </geometry>
  </collision>
  <visual>
     <origin xyz="-0.023500 -0.018000 -0.005000" rpy="-1.51821327 -1.57079633 3.08900959"/>
     <geometry>
     <mesh filename="package://robot_assembler/meshes/mesh_UPPER-ARM38.dae" scale="1.000000 1.000000 1.000000"/>
     </geometry>
  </visual>
  <collision>
     <origin xyz="-0.023500 -0.018000 -0.005000" rpy="-1.51821327 -1.57079633 3.08900959"/>
     <geometry>
     <mesh filename="package://robot_assembler/meshes/mesh_UPPER-ARM38.dae" scale="1.000000 1.000000 1.000000"/>
     </geometry>
  </collision>
  </link>
  <xacro:gazebo_link_reference link_name="LINK35" />
  <link name="LINK35">
  <inertial>
     <mass value="0.061777"/>
     <origin rpy="0 0 0" xyz="-0.010731 -0.015418 -0.018"/>
     <inertia ixx="0.00202" ixy="-9.587219e-06" ixz="-1.546649e-20" iyy="0.002007" iyz="-2.820054e-20" izz="0.002026"/>
  </inertial>
  <visual>
     <origin xyz="-0.000000 0.000000 -0.018000" rpy="-0.00000000 -0.00000000 -3.14159265"/>
     <geometry>
     <mesh filename="package://robot_assembler/meshes/mesh_SERVO-S3301.dae" scale="1.000000 1.000000 1.000000"/>
     </geometry>
  </visual>
  <collision>
     <origin xyz="-0.000000 0.000000 -0.018000" rpy="-0.00000000 -0.00000000 -3.14159265"/>
     <geometry>
     <mesh filename="package://robot_assembler/meshes/mesh_SERVO-S3301.dae" scale="1.000000 1.000000 1.000000"/>
     </geometry>
  </collision>
  <visual>
     <origin xyz="-0.021000 0.010500 -0.018000" rpy="1.57079633 0.00000000 -1.57079633"/>
     <geometry>
     <mesh filename="package://robot_assembler/meshes/mesh_CROSS-SERVO-FRAME-B.dae" scale="1.000000 1.000000 1.000000"/>
     </geometry>
  </visual>
  <collision>
     <origin xyz="-0.021000 0.010500 -0.018000" rpy="1.57079633 0.00000000 -1.57079633"/>
     <geometry>
     <mesh filename="package://robot_assembler/meshes/mesh_CROSS-SERVO-FRAME-B.dae" scale="1.000000 1.000000 1.000000"/>
     </geometry>
  </collision>
  <visual>
     <origin xyz="-0.021000 -0.010500 -0.018000" rpy="1.57079633 0.00000000 -1.57079633"/>
     <geometry>
     <mesh filename="package://robot_assembler/meshes/mesh_CROSS-SERVO-FRAME-A.dae" scale="1.000000 1.000000 1.000000"/>
     </geometry>
  </visual>
  <collision>
     <origin xyz="-0.021000 -0.010500 -0.018000" rpy="1.57079633 0.00000000 -1.57079633"/>
     <geometry>
     <mesh filename="package://robot_assembler/meshes/mesh_CROSS-SERVO-FRAME-A.dae" scale="1.000000 1.000000 1.000000"/>
     </geometry>
  </collision>
  <visual>
     <origin xyz="-0.021000 -0.035000 -0.018000" rpy="-1.57079633 -0.00000000 0.00000000"/>
     <geometry>
     <mesh filename="package://robot_assembler/meshes/mesh_SERVO-S3301.dae" scale="1.000000 1.000000 1.000000"/>
     </geometry>
  </visual>
  <collision>
     <origin xyz="-0.021000 -0.035000 -0.018000" rpy="-1.57079633 -0.00000000 0.00000000"/>
     <geometry>
     <mesh filename="package://robot_assembler/meshes/mesh_SERVO-S3301.dae" scale="1.000000 1.000000 1.000000"/>
     </geometry>
  </collision>
  </link>
  <xacro:gazebo_link_reference link_name="LINK36" />
  <link name="LINK36">
  <inertial>
     <mass value="0.045736"/>
     <origin rpy="0 0 0" xyz="0.03622 -8.007899e-17 0.0162"/>
     <inertia ixx="0.001004" ixy="8.009762e-21" ixz="-2.000101e-07" iyy="0.001013" iyz="7.834925e-21" izz="0.001011"/>
  </inertial>
  <visual>
     <origin xyz="0.025000 -0.000000 0.004000" rpy="-1.28142416 1.57079633 1.86016849"/>
     <geometry>
     <mesh filename="package://robot_assembler/meshes/mesh_UPPER-ARM28.dae" scale="1.000000 1.000000 1.000000"/>
     </geometry>
  </visual>
  <collision>
     <origin xyz="0.025000 -0.000000 0.004000" rpy="-1.28142416 1.57079633 1.86016849"/>
     <geometry>
     <mesh filename="package://robot_assembler/meshes/mesh_UPPER-ARM28.dae" scale="1.000000 1.000000 1.000000"/>
     </geometry>
  </collision>
  <visual>
     <origin xyz="0.025000 -0.000000 0.017000" rpy="1.79505844 -1.57079633 -1.79505844"/>
     <geometry>
     <mesh filename="package://robot_assembler/meshes/mesh_JOINT-BASE.dae" scale="1.000000 1.000000 1.000000"/>
     </geometry>
  </visual>
  <collision>
     <origin xyz="0.025000 -0.000000 0.017000" rpy="1.79505844 -1.57079633 -1.79505844"/>
     <geometry>
     <mesh filename="package://robot_assembler/meshes/mesh_JOINT-BASE.dae" scale="1.000000 1.000000 1.000000"/>
     </geometry>
  </collision>
  <visual>
     <origin xyz="0.034000 -0.000000 -0.004000" rpy="-0.00000000 0.00000000 3.14159265"/>
     <geometry>
     <mesh filename="package://robot_assembler/meshes/mesh_BOTTOM-SPACER.dae" scale="1.000000 1.000000 1.000000"/>
     </geometry>
  </visual>
  <collision>
     <origin xyz="0.034000 -0.000000 -0.004000" rpy="-0.00000000 0.00000000 3.14159265"/>
     <geometry>
     <mesh filename="package://robot_assembler/meshes/mesh_BOTTOM-SPACER.dae" scale="1.000000 1.000000 1.000000"/>
     </geometry>
  </collision>
  <visual>
     <origin xyz="0.047000 -0.000000 0.017000" rpy="-0.21747616 1.57079633 -0.21747616"/>
     <geometry>
     <mesh filename="package://robot_assembler/meshes/mesh_SERVO-S3301.dae" scale="1.000000 1.000000 1.000000"/>
     </geometry>
  </visual>
  <collision>
     <origin xyz="0.047000 -0.000000 0.017000" rpy="-0.21747616 1.57079633 -0.21747616"/>
     <geometry>
     <mesh filename="package://robot_assembler/meshes/mesh_SERVO-S3301.dae" scale="1.000000 1.000000 1.000000"/>
     </geometry>
  </collision>
  <visual>
     <origin xyz="0.025000 -0.000000 0.030000" rpy="1.77732216 -1.57079633 -1.77732216"/>
     <geometry>
     <mesh filename="package://robot_assembler/meshes/mesh_BOTTOM-ARM28.dae" scale="1.000000 1.000000 1.000000"/>
     </geometry>
  </visual>
  <collision>
     <origin xyz="0.025000 -0.000000 0.030000" rpy="1.77732216 -1.57079633 -1.77732216"/>
     <geometry>
     <mesh filename="package://robot_assembler/meshes/mesh_BOTTOM-ARM28.dae" scale="1.000000 1.000000 1.000000"/>
     </geometry>
  </collision>
  </link>
  <xacro:gazebo_link_reference link_name="LINK37" />
  <link name="LINK37">
  <inertial>
     <mass value="0.03987"/>
     <origin rpy="0 0 0" xyz="0.031 -0.031 -0.005"/>
     <inertia ixx="2.472604e-05" ixy="3.247232e-36" ixz="-8.516507e-21" iyy="1.292452e-05" iyz="-5.032301e-37" izz="1.292452e-05"/>
  </inertial>
  <visual>
     <origin xyz="0.031000 -0.031000 -0.005000" rpy="0.00000000 -1.57079633 -0.00000000"/>
     <geometry>
     <mesh filename="package://robot_assembler/meshes/kxr_uav/wheel_foot.STL" scale="0.001000 0.001000 0.001000"/>
     </geometry>
  </visual>
  <collision>
     <origin xyz="0.031000 -0.031000 -0.005000" rpy="0.00000000 -1.57079633 -0.00000000"/>
     <geometry>
     <mesh filename="package://robot_assembler/meshes/kxr_uav/wheel_foot.STL" scale="0.001000 0.001000 0.001000"/>
     </geometry>
  </collision>
  </link>
  <xacro:gazebo_transmission joint_name="JOINT0" />
  <joint name="JOINT0" type="revolute">
     <parent link="BASE"/>
     <child link="LINK0"/>
     <origin xyz="-0.051000 -0.094000 0.058000" rpy="1.46899367 -1.57079633 -1.46899367"/>
     <axis xyz="0 0 1"/>
     <limit effort="200" lower="-3.14159" upper="3.14159" velocity="40"/>
  </joint>
  <xacro:gazebo_transmission joint_name="JOINT1" />
  <joint name="JOINT1" type="revolute">
     <parent link="LINK0"/>
     <child link="LINK1"/>
     <origin xyz="0.000000 -0.018000 0.032500" rpy="1.03037683 -1.57079633 0.54041950"/>
     <axis xyz="0 0 1"/>
     <limit effort="200" lower="-3.14159" upper="3.14159" velocity="40"/>
  </joint>
  <xacro:gazebo_transmission joint_name="JOINT2" />
  <joint name="JOINT2" type="revolute">
     <parent link="LINK1"/>
     <child link="LINK2"/>
     <origin xyz="0.065000 -0.000000 -0.017500" rpy="2.30721689 -1.57079633 0.83437577"/>
     <axis xyz="0 0 1"/>
     <limit effort="200" lower="-3.14159" upper="3.14159" velocity="40"/>
  </joint>
  <xacro:gazebo_transmission joint_name="JOINT3" />
  <joint name="JOINT3" type="revolute">
     <parent link="BASE"/>
     <child link="LINK3"/>
     <origin xyz="0.051000 -0.094000 0.058000" rpy="1.96925607 -1.57079633 1.17233659"/>
     <axis xyz="0 0 1"/>
     <limit effort="200" lower="-3.14159" upper="3.14159" velocity="40"/>
  </joint>
  <xacro:gazebo_transmission joint_name="JOINT4" />
  <joint name="JOINT4" type="revolute">
     <parent link="LINK3"/>
     <child link="LINK4"/>
     <origin xyz="-0.000000 0.018000 0.032500" rpy="1.57079633 -1.57079633 3.14159265"/>
     <axis xyz="0 0 1"/>
     <limit effort="200" lower="-3.14159" upper="3.14159" velocity="40"/>
  </joint>
  <xacro:gazebo_transmission joint_name="JOINT5" />
  <joint name="JOINT5" type="revolute">
     <parent link="LINK4"/>
     <child link="LINK5"/>
     <origin xyz="0.065000 -0.000000 -0.017500" rpy="2.49245391 -1.57079633 0.64913874"/>
     <axis xyz="0 0 1"/>
     <limit effort="200" lower="-3.14159" upper="3.14159" velocity="40"/>
  </joint>
  <xacro:gazebo_transmission joint_name="JOINT6" />
  <joint name="JOINT6" type="revolute">
     <parent link="BASE"/>
     <child link="LINK6"/>
     <origin xyz="-0.051000 -0.007250 0.059500" rpy="1.57079633 -0.00000000 -1.57079633"/>
     <axis xyz="0 0 1"/>
     <limit effort="200" lower="-3.14159" upper="3.14159" velocity="40"/>
  </joint>
  <xacro:gazebo_transmission joint_name="JOINT7" />
  <joint name="JOINT7" type="revolute">
     <parent link="LINK6"/>
     <child link="LINK7"/>
     <origin xyz="0.000000 0.017000 0.027500" rpy="1.32581766 1.57079633 -0.24497866"/>
     <axis xyz="0 0 1"/>
     <limit effort="200" lower="-3.14159" upper="3.14159" velocity="40"/>
  </joint>
  <xacro:gazebo_transmission joint_name="JOINT8" />
  <joint name="JOINT8" type="revolute">
     <parent link="LINK7"/>
     <child link="LINK8"/>
     <origin xyz="0.000000 -0.018000 0.017000" rpy="1.57079633 0.00000000 0.00000000"/>
     <axis xyz="0 0 1"/>
     <limit effort="200" lower="-3.14159" upper="3.14159" velocity="40"/>
  </joint>
  <xacro:gazebo_transmission joint_name="JOINT9" />
  <joint name="JOINT9" type="revolute">
     <parent link="LINK8"/>
     <child link="LINK9"/>
     <origin xyz="-0.017500 0.058000 -0.017500" rpy="1.57079633 -0.00000000 -1.57079633"/>
     <axis xyz="0 0 1"/>
     <limit effort="200" lower="-3.14159" upper="3.14159" velocity="40"/>
  </joint>
  <xacro:gazebo_transmission joint_name="JOINT10" />
  <joint name="JOINT10" type="revolute">
     <parent link="LINK9"/>
     <child link="LINK10"/>
     <origin xyz="-0.070000 -0.000000 -0.018000" rpy="-1.20321187 1.57079633 1.93838078"/>
     <axis xyz="0 0 1"/>
     <limit effort="200" lower="-3.14159" upper="3.14159" velocity="40"/>
  </joint>
  <xacro:gazebo_transmission joint_name="JOINT11" />
  <joint name="JOINT11" type="revolute">
     <parent link="LINK10"/>
     <child link="LINK11"/>
     <origin xyz="-0.017000 0.000000 0.027500" rpy="3.14159265 1.57079633 3.14159265"/>
     <axis xyz="0 0 1"/>
     <limit effort="200" lower="-3.14159" upper="3.14159" velocity="40"/>
  </joint>
  <xacro:gazebo_transmission joint_name="JOINT12" />
  <joint name="JOINT12" type="revolute">
     <parent link="LINK11"/>
     <child link="LINK12"/>
     <origin xyz="0.000000 -0.018000 0.017000" rpy="1.57079633 0.00000000 0.00000000"/>
     <axis xyz="0 0 1"/>
     <limit effort="200" lower="-3.14159" upper="3.14159" velocity="40"/>
  </joint>
  <xacro:gazebo_transmission joint_name="JOINT13" />
  <joint name="JOINT13" type="revolute">
     <parent link="LINK12"/>
     <child link="LINK13"/>
     <origin xyz="-0.060500 0.010500 0.000500" rpy="-0.00000000 0.00000000 1.57079633"/>
     <axis xyz="0 0 1"/>
     <limit effort="200" lower="-3.14159" upper="3.14159" velocity="40"/>
  </joint>
  <xacro:gazebo_transmission joint_name="JOINT14" />
  <joint name="JOINT14" type="revolute">
     <parent link="BASE"/>
     <child link="LINK14"/>
     <origin xyz="0.051000 -0.007250 0.059500" rpy="-1.57079633 0.00000000 -1.57079633"/>
     <axis xyz="0 0 1"/>
     <limit effort="200" lower="-3.14159" upper="3.14159" velocity="40"/>
  </joint>
  <xacro:gazebo_transmission joint_name="JOINT15" />
  <joint name="JOINT15" type="revolute">
     <parent link="LINK14"/>
     <child link="LINK15"/>
     <origin xyz="0.000000 -0.017000 0.027500" rpy="1.12637712 1.57079633 2.69717344"/>
     <axis xyz="0 0 1"/>
     <limit effort="200" lower="-3.14159" upper="3.14159" velocity="40"/>
  </joint>
  <xacro:gazebo_transmission joint_name="JOINT16" />
  <joint name="JOINT16" type="revolute">
     <parent link="LINK15"/>
     <child link="LINK16"/>
     <origin xyz="0.000000 -0.018000 0.017000" rpy="1.57079633 0.00000000 0.00000000"/>
     <axis xyz="0 0 1"/>
     <limit effort="200" lower="-3.14159" upper="3.14159" velocity="40"/>
  </joint>
  <xacro:gazebo_transmission joint_name="JOINT17" />
  <joint name="JOINT17" type="revolute">
     <parent link="LINK16"/>
     <child link="LINK17"/>
     <origin xyz="-0.017500 0.058000 -0.017500" rpy="1.57079633 -0.00000000 -1.57079633"/>
     <axis xyz="0 0 1"/>
     <limit effort="200" lower="-3.14159" upper="3.14159" velocity="40"/>
  </joint>
  <xacro:gazebo_transmission joint_name="JOINT18" />
  <joint name="JOINT18" type="revolute">
     <parent link="LINK17"/>
     <child link="LINK18"/>
     <origin xyz="-0.070000 -0.000000 -0.018000" rpy="-1.28038351 1.57079633 1.86120914"/>
     <axis xyz="0 0 1"/>
     <limit effort="200" lower="-3.14159" upper="3.14159" velocity="40"/>
  </joint>
  <xacro:gazebo_transmission joint_name="JOINT19" />
  <joint name="JOINT19" type="revolute">
     <parent link="LINK18"/>
     <child link="LINK19"/>
     <origin xyz="-0.017000 0.000000 0.027500" rpy="3.14159265 1.57079633 3.14159265"/>
     <axis xyz="0 0 1"/>
     <limit effort="200" lower="-3.14159" upper="3.14159" velocity="40"/>
  </joint>
  <xacro:gazebo_transmission joint_name="JOINT20" />
  <joint name="JOINT20" type="revolute">
     <parent link="LINK19"/>
     <child link="LINK20"/>
     <origin xyz="0.000000 -0.018000 0.017000" rpy="1.57079633 0.00000000 0.00000000"/>
     <axis xyz="0 0 1"/>
     <limit effort="200" lower="-3.14159" upper="3.14159" velocity="40"/>
  </joint>
  <xacro:gazebo_transmission joint_name="JOINT21" />
  <joint name="JOINT21" type="revolute">
     <parent link="LINK20"/>
     <child link="LINK21"/>
     <origin xyz="-0.060500 0.010500 0.000500" rpy="-0.00000000 0.00000000 1.57079633"/>
     <axis xyz="0 0 1"/>
     <limit effort="200" lower="-3.14159" upper="3.14159" velocity="40"/>
  </joint>
  <xacro:gazebo_transmission joint_name="JOINT22" />
  <joint name="JOINT22" type="revolute">
     <parent link="BASE"/>
     <child link="LINK22"/>
     <origin xyz="0.000000 -0.007250 0.077500" rpy="-0.00000000 0.00000000 -1.57079633"/>
     <axis xyz="0 0 1"/>
     <limit effort="200" lower="-3.14159" upper="3.14159" velocity="40"/>
  </joint>
  <xacro:gazebo_transmission joint_name="JOINT23" />
  <joint name="JOINT23" type="revolute">
     <parent link="LINK22"/>
     <child link="LINK23"/>
     <origin xyz="-0.000000 -0.018000 0.032500" rpy="1.78188966 -1.57079633 -0.21109333"/>
     <axis xyz="0 0 1"/>
     <limit effort="200" lower="-3.14159" upper="3.14159" velocity="40"/>
  </joint>
  <xacro:gazebo_transmission joint_name="JOINT24" />
  <joint name="JOINT24" type="revolute">
     <parent link="BASE"/>
     <child link="LINK24"/>
     <origin xyz="0.044500 -0.010500 -0.051000" rpy="3.14159265 0.00000000 0.00000000"/>
     <axis xyz="0 0 1"/>
     <limit effort="200" lower="-3.14159" upper="3.14159" velocity="40"/>
  </joint>
  <xacro:gazebo_transmission joint_name="JOINT25" />
  <joint name="JOINT25" type="revolute">
     <parent link="LINK24"/>
     <child link="LINK25"/>
     <origin xyz="0.000000 0.017000 0.027500" rpy="2.48054948 1.57079633 0.90975316"/>
     <axis xyz="0 0 1"/>
     <limit effort="200" lower="-3.14159" upper="3.14159" velocity="40"/>
  </joint>
  <xacro:gazebo_transmission joint_name="JOINT26" />
  <joint name="JOINT26" type="revolute">
     <parent link="LINK25"/>
     <child link="LINK26"/>
     <origin xyz="0.000000 -0.018000 0.017000" rpy="1.57079633 0.00000000 0.00000000"/>
     <axis xyz="0 0 1"/>
     <limit effort="200" lower="-3.14159" upper="3.14159" velocity="40"/>
  </joint>
  <xacro:gazebo_transmission joint_name="JOINT27" />
  <joint name="JOINT27" type="revolute">
     <parent link="LINK26"/>
     <child link="LINK27"/>
     <origin xyz="-0.064000 -0.000000 -0.000000" rpy="-0.00000000 -0.00000000 0.00000000"/>
     <axis xyz="0 0 1"/>
     <limit effort="200" lower="-3.14159" upper="3.14159" velocity="40"/>
  </joint>
  <xacro:gazebo_transmission joint_name="JOINT28" />
  <joint name="JOINT28" type="revolute">
     <parent link="LINK27"/>
     <child link="LINK28"/>
     <origin xyz="-0.023500 -0.053000 -0.000500" rpy="-0.00000000 -0.00000000 1.57079633"/>
     <axis xyz="0 0 1"/>
     <limit effort="200" lower="-3.14159" upper="3.14159" velocity="40"/>
  </joint>
  <xacro:gazebo_transmission joint_name="JOINT29" />
  <joint name="JOINT29" type="revolute">
     <parent link="LINK28"/>
     <child link="LINK29"/>
     <origin xyz="-0.021000 -0.017000 -0.018000" rpy="1.57079633 0.00000000 -3.14159265"/>
     <axis xyz="0 0 1"/>
     <limit effort="200" lower="-3.14159" upper="3.14159" velocity="40"/>
  </joint>
  <xacro:gazebo_transmission joint_name="JOINT30" />
  <joint name="JOINT30" type="revolute">
     <parent link="LINK29"/>
     <child link="LINK30"/>
     <origin xyz="0.065000 -0.000000 0.017000" rpy="1.07262664 -1.57079633 2.06896601"/>
     <axis xyz="0 0 1"/>
     <limit effort="200" lower="-3.14159" upper="3.14159" velocity="40"/>
  </joint>
  <xacro:gazebo_transmission joint_name="JOINT31" />
  <joint name="JOINT31" type="revolute">
     <parent link="BASE"/>
     <child link="LINK31"/>
     <origin xyz="-0.044500 -0.010500 -0.051000" rpy="3.14159265 0.00000000 -3.14159265"/>
     <axis xyz="0 0 1"/>
     <limit effort="200" lower="-3.14159" upper="3.14159" velocity="40"/>
  </joint>
  <xacro:gazebo_transmission joint_name="JOINT32" />
  <joint name="JOINT32" type="revolute">
     <parent link="LINK31"/>
     <child link="LINK32"/>
     <origin xyz="-0.000000 -0.017000 0.027500" rpy="-1.57079633 1.57079633 0.00000000"/>
     <axis xyz="0 0 1"/>
     <limit effort="200" lower="-3.14159" upper="3.14159" velocity="40"/>
  </joint>
  <xacro:gazebo_transmission joint_name="JOINT33" />
  <joint name="JOINT33" type="revolute">
     <parent link="LINK32"/>
     <child link="LINK33"/>
     <origin xyz="0.000000 -0.018000 0.017000" rpy="1.57079633 0.00000000 0.00000000"/>
     <axis xyz="0 0 1"/>
     <limit effort="200" lower="-3.14159" upper="3.14159" velocity="40"/>
  </joint>
  <xacro:gazebo_transmission joint_name="JOINT34" />
  <joint name="JOINT34" type="revolute">
     <parent link="LINK33"/>
     <child link="LINK34"/>
     <origin xyz="-0.064000 -0.000000 -0.000000" rpy="-0.00000000 -0.00000000 0.00000000"/>
     <axis xyz="0 0 1"/>
     <limit effort="200" lower="-3.14159" upper="3.14159" velocity="40"/>
  </joint>
  <xacro:gazebo_transmission joint_name="JOINT35" />
  <joint name="JOINT35" type="revolute">
     <parent link="LINK34"/>
     <child link="LINK35"/>
     <origin xyz="-0.023500 -0.053000 -0.000500" rpy="-0.00000000 -0.00000000 1.57079633"/>
     <axis xyz="0 0 1"/>
     <limit effort="200" lower="-3.14159" upper="3.14159" velocity="40"/>
  </joint>
  <xacro:gazebo_transmission joint_name="JOINT36" />
  <joint name="JOINT36" type="revolute">
     <parent link="LINK35"/>
     <child link="LINK36"/>
     <origin xyz="-0.021000 -0.017000 -0.018000" rpy="1.57079633 0.00000000 -3.14159265"/>
     <axis xyz="0 0 1"/>
     <limit effort="200" lower="-3.14159" upper="3.14159" velocity="40"/>
  </joint>
  <xacro:gazebo_transmission joint_name="JOINT37" />
  <joint name="JOINT37" type="revolute">
     <parent link="LINK36"/>
     <child link="LINK37"/>
     <origin xyz="0.065000 -0.000000 0.017000" rpy="0.90821104 -1.57079633 2.23338162"/>
     <axis xyz="0 0 1"/>
     <limit effort="200" lower="-3.14159" upper="3.14159" velocity="40"/>
  </joint>

  <!-- Gazebo plugin for ROS Control -->
  <gazebo>
    <plugin name="gazebo_ros_control" filename="libgazebo_ros_control.so">
      <!--robotNamespace>/</robotNamespace-->
      <legacyModeNS>false</legacyModeNS>
      <robotSimType>gazebo_ros_control/DefaultRobotHWSim</robotSimType>
    </plugin>
  </gazebo>
</robot>
