<?xml version="1.0" ?>
<!-- This file was generated by robot assembler -->
<robot name="larm"
       xmlns:xi="http://www.w3.org/2001/XInclude"
       xmlns:gazebo="http://playerstage.sourceforge.net/gazebo/xmlschema/#gz"
       xmlns:model="http://playerstage.sourceforge.net/gazebo/xmlschema/#model"
       xmlns:sensor="http://playerstage.sourceforge.net/gazebo/xmlschema/#sensor"
       xmlns:body="http://playerstage.sourceforge.net/gazebo/xmlschema/#body"
       xmlns:geom="http://playerstage.sourceforge.net/gazebo/xmlschema/#geom"
       xmlns:joint="http://playerstage.sourceforge.net/gazebo/xmlschema/#joint"
       xmlns:interface="http://playerstage.sourceforge.net/gazebo/xmlschema/#interface"
       xmlns:rendering="http://playerstage.sourceforge.net/gazebo/xmlschema/#rendering"
       xmlns:renderable="http://playerstage.sourceforge.net/gazebo/xmlschema/#renderable"
       xmlns:controller="http://playerstage.sourceforge.net/gazebo/xmlschema/#controller"
       xmlns:physics="http://playerstage.sourceforge.net/gazebo/xmlschema/#physics"
       xmlns:xacro="http://www.ros.org/wiki/xacro">
  <xacro:macro name="gazebo_link_reference" params="link_name mu1:=0.9 mu2:=0.9" >
    <gazebo reference="${link_name}">
      <mu1>${mu1}</mu1>
      <mu2>${mu2}</mu2>
    </gazebo>
  </xacro:macro>
  <xacro:macro name="gazebo_transmission" params="joint_name" >
    <transmission name="${joint_name}_trans">
      <type>transmission_interface/SimpleTransmission</type>
      <joint name="${joint_name}">
        <hardwareInterface>hardware_interface/VelocityJointInterface</hardwareInterface>
        <!--hardwareInterface>hardware_interface/EffortJointInterface</hardwareInterface-->
      </joint>
      <actuator name="${joint_name}_motor">
        <hardwareInterface>hardware_interface/VelocityJointInterface</hardwareInterface>
        <!--hardwareInterface>hardware_interface/EffortJointInterface</hardwareInterface-->
        <mechanicalReduction>1</mechanicalReduction>
      </actuator>
    </transmission>
  </xacro:macro>

  <xacro:macro name="no_gazebo_transmission" params="joint_name" >
    <!-- dummy for fixed joint -->
  </xacro:macro>
  <xacro:gazebo_link_reference link_name="BASE" />
  <link name="BASE">
  <inertial>
     <mass value="0.012371"/>
     <origin rpy="0 0 0" xyz="2.297446e-18 4.967856e-18 0.008706"/>
     <inertia ixx="1.937420e-06" ixy="1.058633e-21" ixz="-1.705303e-22" iyy="3.583435e-06" iyz="-8.045714e-22" izz="2.583068e-06"/>
  </inertial>
  <visual>
     <origin xyz="0.000000 0.000000 0.000000" rpy="0.00000000 -0.00000000 0.00000000"/>
     <geometry>
     <mesh filename="package://robot_assembler/meshes/mesh_JOINT-BASE.dae" scale="1.000000 1.000000 1.000000"/>
     </geometry>
  </visual>
  <collision>
     <origin xyz="0.000000 0.000000 0.000000" rpy="0.00000000 -0.00000000 0.00000000"/>
     <geometry>
     <mesh filename="package://robot_assembler/meshes/mesh_JOINT-BASE.dae" scale="1.000000 1.000000 1.000000"/>
     </geometry>
  </collision>
  <visual>
     <origin xyz="-0.013000 0.000000 -0.000000" rpy="0.00000000 -0.00000000 -3.14159265"/>
     <geometry>
     <mesh filename="package://robot_assembler/meshes/mesh_BOTTOM-ARM28.dae" scale="1.000000 1.000000 1.000000"/>
     </geometry>
  </visual>
  <collision>
     <origin xyz="-0.013000 0.000000 -0.000000" rpy="0.00000000 -0.00000000 -3.14159265"/>
     <geometry>
     <mesh filename="package://robot_assembler/meshes/mesh_BOTTOM-ARM28.dae" scale="1.000000 1.000000 1.000000"/>
     </geometry>
  </collision>
  <visual>
     <origin xyz="0.013000 0.000000 0.000000" rpy="0.00000000 -0.00000000 0.00000000"/>
     <geometry>
     <mesh filename="package://robot_assembler/meshes/mesh_UPPER-ARM28.dae" scale="1.000000 1.000000 1.000000"/>
     </geometry>
  </visual>
  <collision>
     <origin xyz="0.013000 0.000000 0.000000" rpy="0.00000000 -0.00000000 0.00000000"/>
     <geometry>
     <mesh filename="package://robot_assembler/meshes/mesh_UPPER-ARM28.dae" scale="1.000000 1.000000 1.000000"/>
     </geometry>
  </collision>
  </link>
  <xacro:gazebo_link_reference link_name="LINK0" />
  <link name="LINK0">
  <inertial>
     <mass value="0.061777"/>
     <origin rpy="0 0 0" xyz="-0.001295 -1.885958e-19 0.001582"/>
     <inertia ixx="0.00202" ixy="-2.653554e-21" ixz="1.039537e-06" iyy="0.002021" iyz="7.989181e-22" izz="0.002002"/>
  </inertial>
  <visual>
     <origin xyz="0.000000 0.000000 -0.018000" rpy="-0.00000000 0.00000000 -3.14159265"/>
     <geometry>
     <mesh filename="package://robot_assembler/meshes/mesh_SERVO-S3301.dae" scale="1.000000 1.000000 1.000000"/>
     </geometry>
  </visual>
  <collision>
     <origin xyz="0.000000 0.000000 -0.018000" rpy="-0.00000000 0.00000000 -3.14159265"/>
     <geometry>
     <mesh filename="package://robot_assembler/meshes/mesh_SERVO-S3301.dae" scale="1.000000 1.000000 1.000000"/>
     </geometry>
  </collision>
  <visual>
     <origin xyz="-0.000000 0.000000 0.006500" rpy="1.40690422 1.57079633 1.40690422"/>
     <geometry>
     <mesh filename="package://robot_assembler/meshes/mesh_CROSS-SERVO-FRAME-A.dae" scale="1.000000 1.000000 1.000000"/>
     </geometry>
  </visual>
  <collision>
     <origin xyz="-0.000000 0.000000 0.006500" rpy="1.40690422 1.57079633 1.40690422"/>
     <geometry>
     <mesh filename="package://robot_assembler/meshes/mesh_CROSS-SERVO-FRAME-A.dae" scale="1.000000 1.000000 1.000000"/>
     </geometry>
  </collision>
  <visual>
     <origin xyz="-0.000000 0.000000 0.017000" rpy="-1.57079633 0.00000000 -3.14159265"/>
     <geometry>
     <mesh filename="package://robot_assembler/meshes/mesh_SERVO-S3301.dae" scale="1.000000 1.000000 1.000000"/>
     </geometry>
  </visual>
  <collision>
     <origin xyz="-0.000000 0.000000 0.017000" rpy="-1.57079633 0.00000000 -3.14159265"/>
     <geometry>
     <mesh filename="package://robot_assembler/meshes/mesh_SERVO-S3301.dae" scale="1.000000 1.000000 1.000000"/>
     </geometry>
  </collision>
  <visual>
     <origin xyz="-0.000000 -0.000000 0.027500" rpy="1.67873135 1.57079633 1.67873135"/>
     <geometry>
     <mesh filename="package://robot_assembler/meshes/mesh_CROSS-SERVO-FRAME-B.dae" scale="1.000000 1.000000 1.000000"/>
     </geometry>
  </visual>
  <collision>
     <origin xyz="-0.000000 -0.000000 0.027500" rpy="1.67873135 1.57079633 1.67873135"/>
     <geometry>
     <mesh filename="package://robot_assembler/meshes/mesh_CROSS-SERVO-FRAME-B.dae" scale="1.000000 1.000000 1.000000"/>
     </geometry>
  </collision>
  </link>
  <xacro:gazebo_link_reference link_name="LINK1" />
  <link name="LINK1">
  <inertial>
     <mass value="0.021241"/>
     <origin rpy="0 0 0" xyz="-0.002095 0.030634 -0.0175"/>
     <inertia ixx="9.720470e-06" ixy="3.232331e-07" ixz="-4.206413e-21" iyy="5.017079e-06" iyz="4.547474e-22" izz="9.161660e-06"/>
  </inertial>
  <visual>
     <origin xyz="-0.002388 0.034918 -0.004500" rpy="0.06829549 -1.57079633 1.57079633"/>
     <geometry>
     <mesh filename="package://robot_assembler/meshes/mesh_UPPER-ARM38.dae" scale="1.000000 1.000000 1.000000"/>
     </geometry>
  </visual>
  <collision>
     <origin xyz="-0.002388 0.034918 -0.004500" rpy="0.06829549 -1.57079633 1.57079633"/>
     <geometry>
     <mesh filename="package://robot_assembler/meshes/mesh_UPPER-ARM38.dae" scale="1.000000 1.000000 1.000000"/>
     </geometry>
  </collision>
  <visual>
     <origin xyz="-0.002388 0.034918 -0.017500" rpy="0.94819334 1.57079633 2.58728516"/>
     <geometry>
     <mesh filename="package://robot_assembler/meshes/mesh_JOINT-BASE.dae" scale="1.000000 1.000000 1.000000"/>
     </geometry>
  </visual>
  <collision>
     <origin xyz="-0.002388 0.034918 -0.017500" rpy="0.94819334 1.57079633 2.58728516"/>
     <geometry>
     <mesh filename="package://robot_assembler/meshes/mesh_JOINT-BASE.dae" scale="1.000000 1.000000 1.000000"/>
     </geometry>
  </collision>
  <visual>
     <origin xyz="0.010581 0.035806 -0.017500" rpy="-1.57079633 0.00000000 0.06829549"/>
     <geometry>
     <mesh filename="package://robot_assembler/meshes/mesh_BOTTOM-ARM26.dae" scale="1.000000 1.000000 1.000000"/>
     </geometry>
  </visual>
  <collision>
     <origin xyz="0.010581 0.035806 -0.017500" rpy="-1.57079633 0.00000000 0.06829549"/>
     <geometry>
     <mesh filename="package://robot_assembler/meshes/mesh_BOTTOM-ARM26.dae" scale="1.000000 1.000000 1.000000"/>
     </geometry>
  </collision>
  <visual>
     <origin xyz="-0.015358 0.034031 -0.017500" rpy="1.57079633 -0.00000000 -3.07329716"/>
     <geometry>
     <mesh filename="package://robot_assembler/meshes/mesh_UPPER-ARM26.dae" scale="1.000000 1.000000 1.000000"/>
     </geometry>
  </visual>
  <collision>
     <origin xyz="-0.015358 0.034031 -0.017500" rpy="1.57079633 -0.00000000 -3.07329716"/>
     <geometry>
     <mesh filename="package://robot_assembler/meshes/mesh_UPPER-ARM26.dae" scale="1.000000 1.000000 1.000000"/>
     </geometry>
  </collision>
  <visual>
     <origin xyz="-0.002388 0.034918 -0.030500" rpy="2.32159411 1.57079633 0.81909327"/>
     <geometry>
     <mesh filename="package://robot_assembler/meshes/mesh_BOTTOM-ARM38.dae" scale="1.000000 1.000000 1.000000"/>
     </geometry>
  </visual>
  <collision>
     <origin xyz="-0.002388 0.034918 -0.030500" rpy="2.32159411 1.57079633 0.81909327"/>
     <geometry>
     <mesh filename="package://robot_assembler/meshes/mesh_BOTTOM-ARM38.dae" scale="1.000000 1.000000 1.000000"/>
     </geometry>
  </collision>
  </link>
  <xacro:gazebo_link_reference link_name="LINK2" />
  <link name="LINK2">
  <inertial>
     <mass value="0.068898"/>
     <origin rpy="0 0 0" xyz="-0.02723 -6.232703e-17 -0.017469"/>
     <inertia ixx="0.002003" ixy="-8.568040e-20" ixz="3.115518e-07" iyy="0.002039" iyz="1.816568e-22" izz="0.002037"/>
  </inertial>
  <visual>
     <origin xyz="0.000000 0.000000 -0.018000" rpy="-0.00000000 -0.00000000 -3.14159265"/>
     <geometry>
     <mesh filename="package://robot_assembler/meshes/mesh_SERVO-S3301.dae" scale="1.000000 1.000000 1.000000"/>
     </geometry>
  </visual>
  <collision>
     <origin xyz="0.000000 0.000000 -0.018000" rpy="-0.00000000 -0.00000000 -3.14159265"/>
     <geometry>
     <mesh filename="package://robot_assembler/meshes/mesh_SERVO-S3301.dae" scale="1.000000 1.000000 1.000000"/>
     </geometry>
  </collision>
  <visual>
     <origin xyz="-0.030000 -0.000000 -0.031000" rpy="-2.98382392 1.57079633 1.72856506"/>
     <geometry>
     <mesh filename="package://robot_assembler/meshes/mesh_JOINT-FRAME-A.dae" scale="1.000000 1.000000 1.000000"/>
     </geometry>
  </visual>
  <collision>
     <origin xyz="-0.030000 -0.000000 -0.031000" rpy="-2.98382392 1.57079633 1.72856506"/>
     <geometry>
     <mesh filename="package://robot_assembler/meshes/mesh_JOINT-FRAME-A.dae" scale="1.000000 1.000000 1.000000"/>
     </geometry>
  </collision>
  <visual>
     <origin xyz="-0.030000 -0.000000 -0.005000" rpy="0.55859932 -1.57079633 -2.12939564"/>
     <geometry>
     <mesh filename="package://robot_assembler/meshes/mesh_JOINT-FRAME-A.dae" scale="1.000000 1.000000 1.000000"/>
     </geometry>
  </visual>
  <collision>
     <origin xyz="-0.030000 -0.000000 -0.005000" rpy="0.55859932 -1.57079633 -2.12939564"/>
     <geometry>
     <mesh filename="package://robot_assembler/meshes/mesh_JOINT-FRAME-A.dae" scale="1.000000 1.000000 1.000000"/>
     </geometry>
  </collision>
  <visual>
     <origin xyz="-0.030000 -0.000000 -0.018000" rpy="-0.01214824 1.57079633 -0.01214824"/>
     <geometry>
     <mesh filename="package://robot_assembler/meshes/mesh_JOINT-BASE.dae" scale="1.000000 1.000000 1.000000"/>
     </geometry>
  </visual>
  <collision>
     <origin xyz="-0.030000 -0.000000 -0.018000" rpy="-0.01214824 1.57079633 -0.01214824"/>
     <geometry>
     <mesh filename="package://robot_assembler/meshes/mesh_JOINT-BASE.dae" scale="1.000000 1.000000 1.000000"/>
     </geometry>
  </collision>
  <visual>
     <origin xyz="-0.039000 -0.000000 0.003000" rpy="-3.14159265 -0.00000000 0.00000000"/>
     <geometry>
     <mesh filename="package://robot_assembler/meshes/mesh_BOTTOM-SPACER.dae" scale="1.000000 1.000000 1.000000"/>
     </geometry>
  </visual>
  <collision>
     <origin xyz="-0.039000 -0.000000 0.003000" rpy="-3.14159265 -0.00000000 0.00000000"/>
     <geometry>
     <mesh filename="package://robot_assembler/meshes/mesh_BOTTOM-SPACER.dae" scale="1.000000 1.000000 1.000000"/>
     </geometry>
  </collision>
  <visual>
     <origin xyz="-0.052000 -0.000000 -0.018000" rpy="1.21805543 -1.57079633 -1.21805543"/>
     <geometry>
     <mesh filename="package://robot_assembler/meshes/mesh_SERVO-S3301.dae" scale="1.000000 1.000000 1.000000"/>
     </geometry>
  </visual>
  <collision>
     <origin xyz="-0.052000 -0.000000 -0.018000" rpy="1.21805543 -1.57079633 -1.21805543"/>
     <geometry>
     <mesh filename="package://robot_assembler/meshes/mesh_SERVO-S3301.dae" scale="1.000000 1.000000 1.000000"/>
     </geometry>
  </collision>
  </link>
  <xacro:gazebo_link_reference link_name="LINK3" />
  <link name="LINK3">
  <inertial>
     <mass value="0.012371"/>
     <origin rpy="0 0 0" xyz="5.743616e-19 4.961587e-18 0.011206"/>
     <inertia ixx="1.937420e-06" ixy="1.057411e-21" ixz="-5.684342e-22" iyy="3.583435e-06" iyz="-8.040832e-22" izz="2.583068e-06"/>
  </inertial>
  <visual>
     <origin xyz="-0.000000 0.000000 0.002500" rpy="0.00000000 -0.00000000 0.00000000"/>
     <geometry>
     <mesh filename="package://robot_assembler/meshes/mesh_JOINT-BASE.dae" scale="1.000000 1.000000 1.000000"/>
     </geometry>
  </visual>
  <collision>
     <origin xyz="-0.000000 0.000000 0.002500" rpy="0.00000000 -0.00000000 0.00000000"/>
     <geometry>
     <mesh filename="package://robot_assembler/meshes/mesh_JOINT-BASE.dae" scale="1.000000 1.000000 1.000000"/>
     </geometry>
  </collision>
  <visual>
     <origin xyz="-0.013000 0.000000 0.002500" rpy="0.00000000 -0.00000000 -3.14159265"/>
     <geometry>
     <mesh filename="package://robot_assembler/meshes/mesh_UPPER-ARM28.dae" scale="1.000000 1.000000 1.000000"/>
     </geometry>
  </visual>
  <collision>
     <origin xyz="-0.013000 0.000000 0.002500" rpy="0.00000000 -0.00000000 -3.14159265"/>
     <geometry>
     <mesh filename="package://robot_assembler/meshes/mesh_UPPER-ARM28.dae" scale="1.000000 1.000000 1.000000"/>
     </geometry>
  </collision>
  <visual>
     <origin xyz="0.013000 -0.000000 0.002500" rpy="-0.00000000 -0.00000000 0.00000000"/>
     <geometry>
     <mesh filename="package://robot_assembler/meshes/mesh_BOTTOM-ARM28.dae" scale="1.000000 1.000000 1.000000"/>
     </geometry>
  </visual>
  <collision>
     <origin xyz="0.013000 -0.000000 0.002500" rpy="-0.00000000 -0.00000000 0.00000000"/>
     <geometry>
     <mesh filename="package://robot_assembler/meshes/mesh_BOTTOM-ARM28.dae" scale="1.000000 1.000000 1.000000"/>
     </geometry>
  </collision>
  </link>
  <xacro:gazebo_link_reference link_name="LINK4" />
  <link name="LINK4">
  <inertial>
     <mass value="0.061777"/>
     <origin rpy="0 0 0" xyz="-0.001295 5.411081e-19 0.001582"/>
     <inertia ixx="0.00202" ixy="-2.736992e-21" ixz="1.039537e-06" iyy="0.002021" iyz="4.279212e-23" izz="0.002002"/>
  </inertial>
  <visual>
     <origin xyz="0.000000 0.000000 -0.018000" rpy="-0.00000000 0.00000000 -3.14159265"/>
     <geometry>
     <mesh filename="package://robot_assembler/meshes/mesh_SERVO-S3301.dae" scale="1.000000 1.000000 1.000000"/>
     </geometry>
  </visual>
  <collision>
     <origin xyz="0.000000 0.000000 -0.018000" rpy="-0.00000000 0.00000000 -3.14159265"/>
     <geometry>
     <mesh filename="package://robot_assembler/meshes/mesh_SERVO-S3301.dae" scale="1.000000 1.000000 1.000000"/>
     </geometry>
  </collision>
  <visual>
     <origin xyz="0.000000 0.000000 0.006500" rpy="1.32764137 1.57079633 1.32764137"/>
     <geometry>
     <mesh filename="package://robot_assembler/meshes/mesh_CROSS-SERVO-FRAME-A.dae" scale="1.000000 1.000000 1.000000"/>
     </geometry>
  </visual>
  <collision>
     <origin xyz="0.000000 0.000000 0.006500" rpy="1.32764137 1.57079633 1.32764137"/>
     <geometry>
     <mesh filename="package://robot_assembler/meshes/mesh_CROSS-SERVO-FRAME-A.dae" scale="1.000000 1.000000 1.000000"/>
     </geometry>
  </collision>
  <visual>
     <origin xyz="0.000000 0.000000 0.017000" rpy="-1.57079633 0.00000000 -3.14159265"/>
     <geometry>
     <mesh filename="package://robot_assembler/meshes/mesh_SERVO-S3301.dae" scale="1.000000 1.000000 1.000000"/>
     </geometry>
  </visual>
  <collision>
     <origin xyz="0.000000 0.000000 0.017000" rpy="-1.57079633 0.00000000 -3.14159265"/>
     <geometry>
     <mesh filename="package://robot_assembler/meshes/mesh_SERVO-S3301.dae" scale="1.000000 1.000000 1.000000"/>
     </geometry>
  </collision>
  <visual>
     <origin xyz="0.000000 -0.000000 0.027500" rpy="1.69172069 1.57079633 1.69172069"/>
     <geometry>
     <mesh filename="package://robot_assembler/meshes/mesh_CROSS-SERVO-FRAME-B.dae" scale="1.000000 1.000000 1.000000"/>
     </geometry>
  </visual>
  <collision>
     <origin xyz="0.000000 -0.000000 0.027500" rpy="1.69172069 1.57079633 1.69172069"/>
     <geometry>
     <mesh filename="package://robot_assembler/meshes/mesh_CROSS-SERVO-FRAME-B.dae" scale="1.000000 1.000000 1.000000"/>
     </geometry>
  </collision>
  </link>
  <xacro:gazebo_link_reference link_name="LINK5" />
  <link name="LINK5">
  <inertial>
     <mass value="0.050016"/>
     <origin rpy="0 0 0" xyz="-0.045048 0.011786 -0.0175"/>
     <inertia ixx="0.001007" ixy="5.772586e-06" ixz="-2.546585e-20" iyy="0.001019" iyz="8.753887e-21" izz="0.001019"/>
  </inertial>
  <visual>
     <origin xyz="-0.034674 0.004766 -0.004500" rpy="-0.45834154 -1.57079633 -2.81984210"/>
     <geometry>
     <mesh filename="package://robot_assembler/meshes/mesh_UPPER-ARM38.dae" scale="1.000000 1.000000 1.000000"/>
     </geometry>
  </visual>
  <collision>
     <origin xyz="-0.034674 0.004766 -0.004500" rpy="-0.45834154 -1.57079633 -2.81984210"/>
     <geometry>
     <mesh filename="package://robot_assembler/meshes/mesh_UPPER-ARM38.dae" scale="1.000000 1.000000 1.000000"/>
     </geometry>
  </collision>
  <visual>
     <origin xyz="-0.034674 0.004766 -0.017500" rpy="-0.59111363 1.57079633 -0.72770462"/>
     <geometry>
     <mesh filename="package://robot_assembler/meshes/mesh_JOINT-BASE.dae" scale="1.000000 1.000000 1.000000"/>
     </geometry>
  </visual>
  <collision>
     <origin xyz="-0.034674 0.004766 -0.017500" rpy="-0.59111363 1.57079633 -0.72770462"/>
     <geometry>
     <mesh filename="package://robot_assembler/meshes/mesh_JOINT-BASE.dae" scale="1.000000 1.000000 1.000000"/>
     </geometry>
  </collision>
  <visual>
     <origin xyz="-0.040618 0.005583 -0.017500" rpy="2.42313090 1.57079633 -0.85505274"/>
     <geometry>
     <mesh filename="package://robot_assembler/meshes/mesh_JOINT-BASE.dae" scale="1.000000 1.000000 1.000000"/>
     </geometry>
  </visual>
  <collision>
     <origin xyz="-0.040618 0.005583 -0.017500" rpy="2.42313090 1.57079633 -0.85505274"/>
     <geometry>
     <mesh filename="package://robot_assembler/meshes/mesh_JOINT-BASE.dae" scale="1.000000 1.000000 1.000000"/>
     </geometry>
  </collision>
  <visual>
     <origin xyz="-0.040618 0.005583 -0.004500" rpy="-1.05551820 -1.57079633 2.48972354"/>
     <geometry>
     <mesh filename="package://robot_assembler/meshes/mesh_JOINT-FRAME-A.dae" scale="1.000000 1.000000 1.000000"/>
     </geometry>
  </visual>
  <collision>
     <origin xyz="-0.040618 0.005583 -0.004500" rpy="-1.05551820 -1.57079633 2.48972354"/>
     <geometry>
     <mesh filename="package://robot_assembler/meshes/mesh_JOINT-FRAME-A.dae" scale="1.000000 1.000000 1.000000"/>
     </geometry>
  </collision>
  <visual>
     <origin xyz="-0.058507 0.018640 -0.017500" rpy="0.00000000 -0.00000000 -1.70738731"/>
     <geometry>
     <mesh filename="package://robot_assembler/meshes/mesh_SERVO-S3301.dae" scale="1.000000 1.000000 1.000000"/>
     </geometry>
  </visual>
  <collision>
     <origin xyz="-0.058507 0.018640 -0.017500" rpy="0.00000000 -0.00000000 -1.70738731"/>
     <geometry>
     <mesh filename="package://robot_assembler/meshes/mesh_SERVO-S3301.dae" scale="1.000000 1.000000 1.000000"/>
     </geometry>
  </collision>
  <visual>
     <origin xyz="-0.040618 0.005583 -0.030500" rpy="-1.11245479 1.57079633 0.32175055"/>
     <geometry>
     <mesh filename="package://robot_assembler/meshes/mesh_JOINT-FRAME-A.dae" scale="1.000000 1.000000 1.000000"/>
     </geometry>
  </visual>
  <collision>
     <origin xyz="-0.040618 0.005583 -0.030500" rpy="-1.11245479 1.57079633 0.32175055"/>
     <geometry>
     <mesh filename="package://robot_assembler/meshes/mesh_JOINT-FRAME-A.dae" scale="1.000000 1.000000 1.000000"/>
     </geometry>
  </collision>
  <visual>
     <origin xyz="-0.034674 0.004766 -0.030500" rpy="-0.35146407 1.57079633 -0.48805506"/>
     <geometry>
     <mesh filename="package://robot_assembler/meshes/mesh_BOTTOM-ARM38.dae" scale="1.000000 1.000000 1.000000"/>
     </geometry>
  </visual>
  <collision>
     <origin xyz="-0.034674 0.004766 -0.030500" rpy="-0.35146407 1.57079633 -0.48805506"/>
     <geometry>
     <mesh filename="package://robot_assembler/meshes/mesh_BOTTOM-ARM38.dae" scale="1.000000 1.000000 1.000000"/>
     </geometry>
  </collision>
  </link>
  <xacro:gazebo_link_reference link_name="LINK6" />
  <link name="LINK6">
  <inertial>
     <mass value="0.013908"/>
     <origin rpy="0 0 0" xyz="0.007157 0.01431 -0.018"/>
     <inertia ixx="5.038421e-06" ixy="-1.246318e-06" ixz="-1.613605e-22" iyy="3.169617e-06" iyz="-8.313980e-22" izz="4.682360e-06"/>
  </inertial>
  <visual>
     <origin xyz="0.000000 0.000000 -0.033500" rpy="0.63872134 1.57079633 0.17498736"/>
     <geometry>
     <mesh filename="package://robot_assembler/meshes/mesh_FINGER.dae" scale="1.000000 1.000000 1.000000"/>
     </geometry>
  </visual>
  <collision>
     <origin xyz="0.000000 0.000000 -0.033500" rpy="0.63872134 1.57079633 0.17498736"/>
     <geometry>
     <mesh filename="package://robot_assembler/meshes/mesh_FINGER.dae" scale="1.000000 1.000000 1.000000"/>
     </geometry>
  </collision>
  </link>
  <xacro:gazebo_link_reference link_name="LINK7" />
  <link name="LINK7">
  <inertial>
     <mass value="0.013908"/>
     <origin rpy="0 0 0" xyz="0.007157 0.01431 -0.018"/>
     <inertia ixx="5.038421e-06" ixy="-1.246318e-06" ixz="4.145848e-22" iyy="3.169617e-06" iyz="1.880259e-21" izz="4.682360e-06"/>
  </inertial>
  <visual>
     <origin xyz="0.000000 0.000000 -0.002500" rpy="-1.13443046 -1.57079633 0.67069647"/>
     <geometry>
     <mesh filename="package://robot_assembler/meshes/mesh_FINGER.dae" scale="1.000000 1.000000 1.000000"/>
     </geometry>
  </visual>
  <collision>
     <origin xyz="0.000000 0.000000 -0.002500" rpy="-1.13443046 -1.57079633 0.67069647"/>
     <geometry>
     <mesh filename="package://robot_assembler/meshes/mesh_FINGER.dae" scale="1.000000 1.000000 1.000000"/>
     </geometry>
  </collision>
  </link>
  <xacro:gazebo_transmission joint_name="JOINT0" />
  <joint name="JOINT0" type="revolute">
     <parent link="BASE"/>
     <child link="LINK0"/>
     <origin xyz="0.017000 -0.000000 0.025000" rpy="1.40690422 1.57079633 -1.73468844"/>
     <axis xyz="0 0 1"/>
     <limit effort="200" lower="-3.14159" upper="3.14159" velocity="40"/>
  </joint>
  <xacro:gazebo_transmission joint_name="JOINT1" />
  <joint name="JOINT1" type="revolute">
     <parent link="LINK0"/>
     <child link="LINK1"/>
     <origin xyz="0.000000 -0.018000 0.017000" rpy="1.57079633 0.00000000 0.00000000"/>
     <axis xyz="0 0 1"/>
     <limit effort="200" lower="-3.14159" upper="3.14159" velocity="40"/>
  </joint>
  <xacro:gazebo_transmission joint_name="JOINT2" />
  <joint name="JOINT2" type="revolute">
     <parent link="LINK1"/>
     <child link="LINK2"/>
     <origin xyz="-0.021417 0.056671 -0.017500" rpy="1.57079633 -0.00000000 -1.50250083"/>
     <axis xyz="0 0 1"/>
     <limit effort="200" lower="-3.14159" upper="3.14159" velocity="40"/>
  </joint>
  <xacro:gazebo_transmission joint_name="JOINT3" />
  <joint name="JOINT3" type="revolute">
     <parent link="LINK2"/>
     <child link="LINK3"/>
     <origin xyz="-0.070000 -0.000000 -0.018000" rpy="-1.36238365 1.57079633 1.77920900"/>
     <axis xyz="0 0 1"/>
     <limit effort="200" lower="-3.14159" upper="3.14159" velocity="40"/>
  </joint>
  <xacro:gazebo_transmission joint_name="JOINT4" />
  <joint name="JOINT4" type="revolute">
     <parent link="LINK3"/>
     <child link="LINK4"/>
     <origin xyz="-0.017000 0.000000 0.027500" rpy="3.14159265 1.57079633 -3.14159265"/>
     <axis xyz="0 0 1"/>
     <limit effort="200" lower="-3.14159" upper="3.14159" velocity="40"/>
  </joint>
  <xacro:gazebo_transmission joint_name="JOINT5" />
  <joint name="JOINT5" type="revolute">
     <parent link="LINK4"/>
     <child link="LINK5"/>
     <origin xyz="0.000000 -0.018000 0.017000" rpy="1.57079633 0.00000000 0.00000000"/>
     <axis xyz="0 0 1"/>
     <limit effort="200" lower="-3.14159" upper="3.14159" velocity="40"/>
  </joint>
  <xacro:gazebo_transmission joint_name="JOINT6" />
  <joint name="JOINT6" type="revolute">
     <parent link="LINK5"/>
     <child link="LINK6"/>
     <origin xyz="-0.058507 0.018640 0.000500" rpy="-0.00000000 0.00000000 1.43420534"/>
     <axis xyz="0 0 1"/>
     <limit effort="200" lower="-3.14159" upper="3.14159" velocity="40"/>
  </joint>
  <xacro:gazebo_transmission joint_name="JOINT7" />
  <joint name="JOINT7" type="revolute">
     <parent link="LINK5"/>
     <child link="LINK7"/>
     <origin xyz="-0.071768 -0.000734 0.000500" rpy="-0.00000000 0.00000000 1.43420534"/>
     <axis xyz="0 0 1"/>
     <limit effort="200" lower="-3.14159" upper="3.14159" velocity="40"/>
  </joint>

  <!-- Gazebo plugin for ROS Control -->
  <gazebo>
    <plugin name="gazebo_ros_control" filename="libgazebo_ros_control.so">
      <!--robotNamespace>/</robotNamespace-->
      <legacyModeNS>false</legacyModeNS>
      <robotSimType>gazebo_ros_control/DefaultRobotHWSim</robotSimType>
    </plugin>
  </gazebo>
</robot>
