<?xml version="1.0" ?>
<!-- This file was generated by robot assembler -->
<robot name="rtilt"
       xmlns:xi="http://www.w3.org/2001/XInclude"
       xmlns:gazebo="http://playerstage.sourceforge.net/gazebo/xmlschema/#gz"
       xmlns:model="http://playerstage.sourceforge.net/gazebo/xmlschema/#model"
       xmlns:sensor="http://playerstage.sourceforge.net/gazebo/xmlschema/#sensor"
       xmlns:body="http://playerstage.sourceforge.net/gazebo/xmlschema/#body"
       xmlns:geom="http://playerstage.sourceforge.net/gazebo/xmlschema/#geom"
       xmlns:joint="http://playerstage.sourceforge.net/gazebo/xmlschema/#joint"
       xmlns:interface="http://playerstage.sourceforge.net/gazebo/xmlschema/#interface"
       xmlns:rendering="http://playerstage.sourceforge.net/gazebo/xmlschema/#rendering"
       xmlns:renderable="http://playerstage.sourceforge.net/gazebo/xmlschema/#renderable"
       xmlns:controller="http://playerstage.sourceforge.net/gazebo/xmlschema/#controller"
       xmlns:physics="http://playerstage.sourceforge.net/gazebo/xmlschema/#physics"
       xmlns:xacro="http://www.ros.org/wiki/xacro">
  <xacro:macro name="gazebo_link_reference" params="link_name mu1:=0.9 mu2:=0.9" >
    <gazebo reference="${link_name}">
      <mu1>${mu1}</mu1>
      <mu2>${mu2}</mu2>
    </gazebo>
  </xacro:macro>
  <xacro:macro name="gazebo_transmission" params="joint_name" >
    <transmission name="${joint_name}_trans">
      <type>transmission_interface/SimpleTransmission</type>
      <joint name="${joint_name}">
        <hardwareInterface>hardware_interface/VelocityJointInterface</hardwareInterface>
        <!--hardwareInterface>hardware_interface/EffortJointInterface</hardwareInterface-->
      </joint>
      <actuator name="${joint_name}_motor">
        <hardwareInterface>hardware_interface/VelocityJointInterface</hardwareInterface>
        <!--hardwareInterface>hardware_interface/EffortJointInterface</hardwareInterface-->
        <mechanicalReduction>1</mechanicalReduction>
      </actuator>
    </transmission>
  </xacro:macro>

  <xacro:macro name="no_gazebo_transmission" params="joint_name" >
    <!-- dummy for fixed joint -->
  </xacro:macro>
  <xacro:gazebo_link_reference link_name="BASE" />
  <link name="BASE">
  <inertial>
     <mass value="0.035533"/>
     <origin rpy="0 0 0" xyz="-2.761544e-17 1.835246e-17 0.022844"/>
     <inertia ixx="0.001006" ixy="-1.386659e-22" ixz="7.173575e-21" iyy="0.001006" iyz="-4.657026e-21" izz="0.001002"/>
  </inertial>
  <visual>
     <origin xyz="0.000000 0.000000 0.000000" rpy="0.00000000 -0.00000000 0.00000000"/>
     <geometry>
     <mesh filename="package://robot_assembler/meshes/mesh_JOINT-BASE.dae" scale="1.000000 1.000000 1.000000"/>
     </geometry>
  </visual>
  <collision>
     <origin xyz="0.000000 0.000000 0.000000" rpy="0.00000000 -0.00000000 0.00000000"/>
     <geometry>
     <mesh filename="package://robot_assembler/meshes/mesh_JOINT-BASE.dae" scale="1.000000 1.000000 1.000000"/>
     </geometry>
  </collision>
  <visual>
     <origin xyz="-0.013000 0.000000 -0.000000" rpy="1.57079633 -0.00000000 -3.14159265"/>
     <geometry>
     <mesh filename="package://robot_assembler/meshes/mesh_JOINT-FRAME-A.dae" scale="1.000000 1.000000 1.000000"/>
     </geometry>
  </visual>
  <collision>
     <origin xyz="-0.013000 0.000000 -0.000000" rpy="1.57079633 -0.00000000 -3.14159265"/>
     <geometry>
     <mesh filename="package://robot_assembler/meshes/mesh_JOINT-FRAME-A.dae" scale="1.000000 1.000000 1.000000"/>
     </geometry>
  </collision>
  <visual>
     <origin xyz="0.013000 0.000000 -0.000000" rpy="1.57079633 -0.00000000 -0.00000000"/>
     <geometry>
     <mesh filename="package://robot_assembler/meshes/mesh_JOINT-FRAME-A.dae" scale="1.000000 1.000000 1.000000"/>
     </geometry>
  </visual>
  <collision>
     <origin xyz="0.013000 0.000000 -0.000000" rpy="1.57079633 -0.00000000 -0.00000000"/>
     <geometry>
     <mesh filename="package://robot_assembler/meshes/mesh_JOINT-FRAME-A.dae" scale="1.000000 1.000000 1.000000"/>
     </geometry>
  </collision>
  <visual>
     <origin xyz="-0.000000 0.000000 0.030000" rpy="-0.31545875 1.57079633 -0.31545875"/>
     <geometry>
     <mesh filename="package://robot_assembler/meshes/mesh_SERVO-S3301.dae" scale="1.000000 1.000000 1.000000"/>
     </geometry>
  </visual>
  <collision>
     <origin xyz="-0.000000 0.000000 0.030000" rpy="-0.31545875 1.57079633 -0.31545875"/>
     <geometry>
     <mesh filename="package://robot_assembler/meshes/mesh_SERVO-S3301.dae" scale="1.000000 1.000000 1.000000"/>
     </geometry>
  </collision>
  </link>
  <xacro:gazebo_link_reference link_name="LINK0" />
  <link name="LINK0">
  <inertial>
     <mass value="0.045736"/>
     <origin rpy="0 0 0" xyz="0.03622 -1.776991e-17 -0.0183"/>
     <inertia ixx="0.001004" ixy="1.028654e-20" ixz="-2.000101e-07" iyy="0.001013" iyz="1.356809e-21" izz="0.001011"/>
  </inertial>
  <visual>
     <origin xyz="0.025000 0.000000 -0.004500" rpy="0.00000000 -1.57079633 -0.00000000"/>
     <geometry>
     <mesh filename="package://robot_assembler/meshes/mesh_UPPER-ARM28.dae" scale="1.000000 1.000000 1.000000"/>
     </geometry>
  </visual>
  <collision>
     <origin xyz="0.025000 0.000000 -0.004500" rpy="0.00000000 -1.57079633 -0.00000000"/>
     <geometry>
     <mesh filename="package://robot_assembler/meshes/mesh_UPPER-ARM28.dae" scale="1.000000 1.000000 1.000000"/>
     </geometry>
  </collision>
  <visual>
     <origin xyz="0.025000 0.000000 -0.017500" rpy="0.00000000 -1.57079633 -0.00000000"/>
     <geometry>
     <mesh filename="package://robot_assembler/meshes/mesh_JOINT-BASE.dae" scale="1.000000 1.000000 1.000000"/>
     </geometry>
  </visual>
  <collision>
     <origin xyz="0.025000 0.000000 -0.017500" rpy="0.00000000 -1.57079633 -0.00000000"/>
     <geometry>
     <mesh filename="package://robot_assembler/meshes/mesh_JOINT-BASE.dae" scale="1.000000 1.000000 1.000000"/>
     </geometry>
  </collision>
  <visual>
     <origin xyz="0.034000 -0.000000 -0.038500" rpy="0.00000000 -0.00000000 3.14159265"/>
     <geometry>
     <mesh filename="package://robot_assembler/meshes/mesh_BOTTOM-SPACER.dae" scale="1.000000 1.000000 1.000000"/>
     </geometry>
  </visual>
  <collision>
     <origin xyz="0.034000 -0.000000 -0.038500" rpy="0.00000000 -0.00000000 3.14159265"/>
     <geometry>
     <mesh filename="package://robot_assembler/meshes/mesh_BOTTOM-SPACER.dae" scale="1.000000 1.000000 1.000000"/>
     </geometry>
  </collision>
  <visual>
     <origin xyz="0.047000 -0.000000 -0.017500" rpy="-2.37548056 1.57079633 -2.37548056"/>
     <geometry>
     <mesh filename="package://robot_assembler/meshes/mesh_SERVO-S3301.dae" scale="1.000000 1.000000 1.000000"/>
     </geometry>
  </visual>
  <collision>
     <origin xyz="0.047000 -0.000000 -0.017500" rpy="-2.37548056 1.57079633 -2.37548056"/>
     <geometry>
     <mesh filename="package://robot_assembler/meshes/mesh_SERVO-S3301.dae" scale="1.000000 1.000000 1.000000"/>
     </geometry>
  </collision>
  <visual>
     <origin xyz="0.025000 0.000000 -0.030500" rpy="0.76887886 1.57079633 -2.37271379"/>
     <geometry>
     <mesh filename="package://robot_assembler/meshes/mesh_BOTTOM-ARM28.dae" scale="1.000000 1.000000 1.000000"/>
     </geometry>
  </visual>
  <collision>
     <origin xyz="0.025000 0.000000 -0.030500" rpy="0.76887886 1.57079633 -2.37271379"/>
     <geometry>
     <mesh filename="package://robot_assembler/meshes/mesh_BOTTOM-ARM28.dae" scale="1.000000 1.000000 1.000000"/>
     </geometry>
  </collision>
  </link>
  <xacro:gazebo_link_reference link_name="LINK1" />
  <link name="LINK1">
  <inertial>
     <mass value="0.03987"/>
     <origin rpy="0 0 0" xyz="2.220446e-19 -1.009742e-31 0.002"/>
     <inertia ixx="1.292452e-05" ixy="9.916532e-83" ixz="-2.279075e-36" iyy="1.292452e-05" iyz="8.932018e-67" izz="2.472604e-05"/>
  </inertial>
  <visual>
     <origin xyz="0.000000 -0.000000 0.002000" rpy="0.00000000 -0.00000000 0.00000000"/>
     <geometry>
     <mesh filename="package://robot_assembler/meshes/mesh_WHEEL.dae" scale="1.000000 1.000000 1.000000"/>
     </geometry>
  </visual>
  <collision>
     <origin xyz="0.000000 -0.000000 0.002000" rpy="0.00000000 -0.00000000 0.00000000"/>
     <geometry>
     <mesh filename="package://robot_assembler/meshes/mesh_WHEEL.dae" scale="1.000000 1.000000 1.000000"/>
     </geometry>
  </collision>
  </link>
  <xacro:gazebo_transmission joint_name="JOINT0" />
  <joint name="JOINT0" type="revolute">
     <parent link="BASE"/>
     <child link="LINK0"/>
     <origin xyz="0.018000 0.000000 0.030000" rpy="1.24475092 -1.57079633 1.89684173"/>
     <axis xyz="0 0 1"/>
     <limit effort="200" lower="-3.14159" upper="3.14159" velocity="40"/>
  </joint>
  <xacro:gazebo_transmission joint_name="JOINT1" />
  <joint name="JOINT1" type="revolute">
     <parent link="LINK0"/>
     <child link="LINK1"/>
     <origin xyz="0.065000 -0.000000 -0.017500" rpy="2.08806691 -1.57079633 1.05352574"/>
     <axis xyz="0 0 1"/>
     <limit effort="200" lower="-3.14159" upper="3.14159" velocity="40"/>
  </joint>

  <!-- Gazebo plugin for ROS Control -->
  <gazebo>
    <plugin name="gazebo_ros_control" filename="libgazebo_ros_control.so">
      <!--robotNamespace>/</robotNamespace-->
      <legacyModeNS>false</legacyModeNS>
      <robotSimType>gazebo_ros_control/DefaultRobotHWSim</robotSimType>
    </plugin>
  </gazebo>
</robot>
