<?xml version="1.0" ?>
<!-- This file was generated by robot assembler -->
<robot name="rarm"
       xmlns:xi="http://www.w3.org/2001/XInclude"
       xmlns:gazebo="http://playerstage.sourceforge.net/gazebo/xmlschema/#gz"
       xmlns:model="http://playerstage.sourceforge.net/gazebo/xmlschema/#model"
       xmlns:sensor="http://playerstage.sourceforge.net/gazebo/xmlschema/#sensor"
       xmlns:body="http://playerstage.sourceforge.net/gazebo/xmlschema/#body"
       xmlns:geom="http://playerstage.sourceforge.net/gazebo/xmlschema/#geom"
       xmlns:joint="http://playerstage.sourceforge.net/gazebo/xmlschema/#joint"
       xmlns:interface="http://playerstage.sourceforge.net/gazebo/xmlschema/#interface"
       xmlns:rendering="http://playerstage.sourceforge.net/gazebo/xmlschema/#rendering"
       xmlns:renderable="http://playerstage.sourceforge.net/gazebo/xmlschema/#renderable"
       xmlns:controller="http://playerstage.sourceforge.net/gazebo/xmlschema/#controller"
       xmlns:physics="http://playerstage.sourceforge.net/gazebo/xmlschema/#physics"
       xmlns:xacro="http://www.ros.org/wiki/xacro">
  <xacro:macro name="gazebo_link_reference" params="link_name mu1:=0.9 mu2:=0.9" >
    <gazebo reference="${link_name}">
      <mu1>${mu1}</mu1>
      <mu2>${mu2}</mu2>
    </gazebo>
  </xacro:macro>
  <xacro:macro name="gazebo_transmission" params="joint_name" >
    <transmission name="${joint_name}_trans">
      <type>transmission_interface/SimpleTransmission</type>
      <joint name="${joint_name}">
        <hardwareInterface>hardware_interface/VelocityJointInterface</hardwareInterface>
        <!--hardwareInterface>hardware_interface/EffortJointInterface</hardwareInterface-->
      </joint>
      <actuator name="${joint_name}_motor">
        <hardwareInterface>hardware_interface/VelocityJointInterface</hardwareInterface>
        <!--hardwareInterface>hardware_interface/EffortJointInterface</hardwareInterface-->
        <mechanicalReduction>1</mechanicalReduction>
      </actuator>
    </transmission>
  </xacro:macro>

  <xacro:macro name="no_gazebo_transmission" params="joint_name" >
    <!-- dummy for fixed joint -->
  </xacro:macro>
  <xacro:gazebo_link_reference link_name="BASE" />
  <link name="BASE">
     <inertial>
        <mass value="0.011949"/>
        <origin rpy="0 0 0" xyz="2.973231e-18 4.461323e-18 0.007918"/>
        <inertia ixx="1.701549e-06" ixy="9.249566e-22" ixz="-1.136868e-22" iyy="3.250821e-06" iyz="-6.644882e-22" izz="2.468319e-06"/>
     </inertial>
     <visual>
        <origin xyz="0.000000 0.000000 0.000000" rpy="0.00000000 -0.00000000 0.00000000"/>
        <geometry>
        <mesh filename="package://robot_assembler/meshes/mesh_JOINT-BASE.dae" scale="1.000000 1.000000 1.000000"/>
        </geometry>
     </visual>
     <collision>
        <origin xyz="0.000000 0.000000 0.000000" rpy="0.00000000 -0.00000000 0.00000000"/>
        <geometry>
          <box size="0.026800 0.026800 0.006000" />
        </geometry>
     </collision>
     <visual>
        <origin xyz="-0.013000 0.000000 -0.000000" rpy="0.00000000 -0.00000000 -3.14159265"/>
        <geometry>
        <mesh filename="package://robot_assembler/meshes/mesh_BOTTOM-ARM26.dae" scale="1.000000 1.000000 1.000000"/>
        </geometry>
     </visual>
     <collision>
        <origin xyz="-0.016150 0.000000 0.030600" rpy="0.00000000 -0.00000000 -3.14159265"/>
        <geometry>
          <box size="0.004400 0.001200 0.000800" />
        </geometry>
     </collision>
     <collision>
        <origin xyz="-0.016150 0.000000 0.029200" rpy="0.00000000 -0.00000000 -3.14159265"/>
        <geometry>
          <box size="0.004400 0.007600 0.002000" />
        </geometry>
     </collision>
     <collision>
        <origin xyz="-0.015750 0.000000 0.016200" rpy="0.00000000 -0.00000000 -3.14159265"/>
        <geometry>
          <box size="0.005200 0.011600 0.024000" />
        </geometry>
     </collision>
     <collision>
        <origin xyz="-0.016150 -0.000000 0.000600" rpy="0.00000000 -0.00000000 -3.14159265"/>
        <geometry>
          <box size="0.004400 0.015600 0.007200" />
        </geometry>
     </collision>
     <visual>
        <origin xyz="0.013000 0.000000 0.000000" rpy="0.00000000 -0.00000000 0.00000000"/>
        <geometry>
        <mesh filename="package://robot_assembler/meshes/mesh_UPPER-ARM26.dae" scale="1.000000 1.000000 1.000000"/>
        </geometry>
     </visual>
     <collision>
        <origin xyz="0.016150 0.000000 0.030600" rpy="0.00000000 -0.00000000 0.00000000"/>
        <geometry>
          <box size="0.004400 0.001200 0.000800" />
        </geometry>
     </collision>
     <collision>
        <origin xyz="0.016150 0.000000 0.029000" rpy="0.00000000 -0.00000000 0.00000000"/>
        <geometry>
          <box size="0.004400 0.007600 0.002400" />
        </geometry>
     </collision>
     <collision>
        <origin xyz="0.016150 0.000000 0.014200" rpy="0.00000000 -0.00000000 0.00000000"/>
        <geometry>
          <box size="0.004400 0.012400 0.027200" />
        </geometry>
     </collision>
     <collision>
        <origin xyz="0.015750 0.000000 -0.001200" rpy="0.00000000 -0.00000000 0.00000000"/>
        <geometry>
          <box size="0.005200 0.016400 0.003600" />
        </geometry>
     </collision>
  </link>
  <xacro:gazebo_link_reference link_name="LINK0" />
  <link name="LINK0">
     <inertial>
        <mass value="0.068898"/>
        <origin rpy="0 0 0" xyz="-0.02723 -0.000531 -0.018"/>
        <inertia ixx="0.002003" ixy="-3.115518e-07" ixz="1.051603e-21" iyy="0.002038" iyz="1.168843e-21" izz="0.002038"/>
     </inertial>
     <visual>
        <origin xyz="0.000000 0.000000 -0.018000" rpy="0.00000000 -0.00000000 -3.14159265"/>
        <geometry>
        <mesh filename="package://robot_assembler/meshes/mesh_SERVO-S3301.dae" scale="1.000000 1.000000 1.000000"/>
        </geometry>
     </visual>
     <collision>
        <origin xyz="-0.000050 -0.000000 -0.002250" rpy="0.00000000 -0.00000000 -3.14159265"/>
        <geometry>
          <box size="0.006000 0.006000 0.003200" />
        </geometry>
     </collision>
     <collision>
        <origin xyz="-0.000050 -0.000000 -0.004450" rpy="0.00000000 -0.00000000 -3.14159265"/>
        <geometry>
          <box size="0.011600 0.011600 0.001200" />
        </geometry>
     </collision>
     <collision>
        <origin xyz="-0.007250 -0.000000 -0.018250" rpy="0.00000000 -0.00000000 -3.14159265"/>
        <geometry>
          <box size="0.032400 0.026000 0.026400" />
        </geometry>
     </collision>
     <collision>
        <origin xyz="-0.000050 -0.000000 -0.031850" rpy="0.00000000 -0.00000000 -3.14159265"/>
        <geometry>
          <box size="0.012400 0.012400 0.000800" />
        </geometry>
     </collision>
     <collision>
        <origin xyz="0.000150 0.000000 -0.033050" rpy="0.00000000 -0.00000000 -3.14159265"/>
        <geometry>
          <box size="0.005600 0.006000 0.001600" />
        </geometry>
     </collision>
     <visual>
        <origin xyz="-0.030000 -0.000000 -0.005000" rpy="0.78539816 -1.57079633 -2.35619449"/>
        <geometry>
        <mesh filename="package://robot_assembler/meshes/mesh_JOINT-FRAME-A.dae" scale="1.000000 1.000000 1.000000"/>
        </geometry>
     </visual>
     <collision>
        <origin xyz="-0.026600 0.012600 -0.004250" rpy="0.78539816 -1.57079633 -2.35619449"/>
        <geometry>
          <box size="0.002800 0.013200 0.000800" />
        </geometry>
     </collision>
     <collision>
        <origin xyz="-0.025600 0.008800 -0.004250" rpy="0.78539816 -1.57079633 -2.35619449"/>
        <geometry>
          <box size="0.002800 0.015200 0.006800" />
        </geometry>
     </collision>
     <collision>
        <origin xyz="-0.024800 -0.003600 -0.004250" rpy="0.78539816 -1.57079633 -2.35619449"/>
        <geometry>
          <box size="0.002800 0.016000 0.018000" />
        </geometry>
     </collision>
     <collision>
        <origin xyz="-0.026000 -0.012800 -0.004250" rpy="0.78539816 -1.57079633 -2.35619449"/>
        <geometry>
          <box size="0.002800 0.014400 0.000400" />
        </geometry>
     </collision>
     <visual>
        <origin xyz="-0.030000 -0.000000 -0.018000" rpy="-1.02404522 -1.57079633 -2.11754743"/>
        <geometry>
        <mesh filename="package://robot_assembler/meshes/mesh_JOINT-BASE.dae" scale="1.000000 1.000000 1.000000"/>
        </geometry>
     </visual>
     <collision>
        <origin xyz="-0.030000 -0.000000 -0.018000" rpy="-1.02404522 -1.57079633 -2.11754743"/>
        <geometry>
          <box size="0.026800 0.026800 0.006000" />
        </geometry>
     </collision>
     <visual>
        <origin xyz="-0.039000 -0.021000 -0.018000" rpy="-1.57079633 -0.00000000 0.00000000"/>
        <geometry>
        <mesh filename="package://robot_assembler/meshes/mesh_BOTTOM-SPACER.dae" scale="1.000000 1.000000 1.000000"/>
        </geometry>
     </visual>
     <collision>
        <origin xyz="-0.037550 -0.005250 -0.018000" rpy="-1.57079633 -0.00000000 0.00000000"/>
        <geometry>
          <box size="0.003200 0.026800 0.037200" />
        </geometry>
     </collision>
     <collision>
        <origin xyz="-0.035350 -0.003850 -0.018000" rpy="-1.57079633 -0.00000000 0.00000000"/>
        <geometry>
          <box size="0.001200 0.026800 0.034400" />
        </geometry>
     </collision>
     <collision>
        <origin xyz="-0.034350 -0.002450 -0.018000" rpy="-1.57079633 -0.00000000 0.00000000"/>
        <geometry>
          <box size="0.000800 0.026800 0.031600" />
        </geometry>
     </collision>
     <collision>
        <origin xyz="-0.033350 -0.001450 -0.018000" rpy="-1.57079633 -0.00000000 0.00000000"/>
        <geometry>
          <box size="0.001200 0.026800 0.029600" />
        </geometry>
     </collision>
     <collision>
        <origin xyz="-0.032550 -0.000050 -0.018000" rpy="-1.57079633 -0.00000000 0.00000000"/>
        <geometry>
          <box size="0.000400 0.026800 0.026800" />
        </geometry>
     </collision>
     <visual>
        <origin xyz="-0.052000 -0.000000 -0.018000" rpy="1.57079633 0.00000000 -1.57079633"/>
        <geometry>
        <mesh filename="package://robot_assembler/meshes/mesh_SERVO-S3301.dae" scale="1.000000 1.000000 1.000000"/>
        </geometry>
     </visual>
     <collision>
        <origin xyz="-0.067750 -0.000050 -0.018000" rpy="1.57079633 0.00000000 -1.57079633"/>
        <geometry>
          <box size="0.006000 0.006000 0.003200" />
        </geometry>
     </collision>
     <collision>
        <origin xyz="-0.065550 -0.000050 -0.018000" rpy="1.57079633 0.00000000 -1.57079633"/>
        <geometry>
          <box size="0.011600 0.011600 0.001200" />
        </geometry>
     </collision>
     <collision>
        <origin xyz="-0.051750 -0.007250 -0.018000" rpy="1.57079633 0.00000000 -1.57079633"/>
        <geometry>
          <box size="0.032400 0.026000 0.026400" />
        </geometry>
     </collision>
     <collision>
        <origin xyz="-0.038150 -0.000050 -0.018000" rpy="1.57079633 0.00000000 -1.57079633"/>
        <geometry>
          <box size="0.012400 0.012400 0.000800" />
        </geometry>
     </collision>
     <collision>
        <origin xyz="-0.036950 0.000150 -0.018000" rpy="1.57079633 0.00000000 -1.57079633"/>
        <geometry>
          <box size="0.005600 0.006000 0.001600" />
        </geometry>
     </collision>
     <visual>
        <origin xyz="-0.030000 -0.000000 -0.031000" rpy="2.35619449 1.57079633 0.78539816"/>
        <geometry>
        <mesh filename="package://robot_assembler/meshes/mesh_JOINT-FRAME-A.dae" scale="1.000000 1.000000 1.000000"/>
        </geometry>
     </visual>
     <collision>
        <origin xyz="-0.026600 -0.012600 -0.031750" rpy="2.49809154 1.57079633 0.92729522"/>
        <geometry>
          <box size="0.002800 0.013200 0.000800" />
        </geometry>
     </collision>
     <collision>
        <origin xyz="-0.025600 -0.008800 -0.031750" rpy="2.49809154 1.57079633 0.92729522"/>
        <geometry>
          <box size="0.002800 0.015200 0.006800" />
        </geometry>
     </collision>
     <collision>
        <origin xyz="-0.024800 0.003600 -0.031750" rpy="2.49809154 1.57079633 0.92729522"/>
        <geometry>
          <box size="0.002800 0.016000 0.018000" />
        </geometry>
     </collision>
     <collision>
        <origin xyz="-0.026000 0.012800 -0.031750" rpy="2.49809154 1.57079633 0.92729522"/>
        <geometry>
          <box size="0.002800 0.014400 0.000400" />
        </geometry>
     </collision>
  </link>
  <xacro:gazebo_link_reference link_name="LINK1" />
  <link name="LINK1">
     <inertial>
        <mass value="0.011949"/>
        <origin rpy="0 0 0" xyz="3.567877e-18 5.218926e-18 0.010418"/>
        <inertia ixx="1.701549e-06" ixy="1.453989e-21" ixz="-1.364242e-21" iyy="3.250821e-06" iyz="-7.397629e-22" izz="2.468319e-06"/>
     </inertial>
     <visual>
        <origin xyz="0.000000 -0.000000 0.002500" rpy="0.00000000 -0.00000000 0.00000000"/>
        <geometry>
        <mesh filename="package://robot_assembler/meshes/mesh_JOINT-BASE.dae" scale="1.000000 1.000000 1.000000"/>
        </geometry>
     </visual>
     <collision>
        <origin xyz="0.000000 -0.000000 0.002500" rpy="0.00000000 -0.00000000 0.00000000"/>
        <geometry>
          <box size="0.026800 0.026800 0.006000" />
        </geometry>
     </collision>
     <visual>
        <origin xyz="-0.013000 0.000000 0.002500" rpy="0.00000000 -0.00000000 -3.14159265"/>
        <geometry>
        <mesh filename="package://robot_assembler/meshes/mesh_BOTTOM-ARM26.dae" scale="1.000000 1.000000 1.000000"/>
        </geometry>
     </visual>
     <collision>
        <origin xyz="-0.016150 0.000000 0.033100" rpy="0.00000000 -0.00000000 -3.14159265"/>
        <geometry>
          <box size="0.004400 0.001200 0.000800" />
        </geometry>
     </collision>
     <collision>
        <origin xyz="-0.016150 0.000000 0.031700" rpy="0.00000000 -0.00000000 -3.14159265"/>
        <geometry>
          <box size="0.004400 0.007600 0.002000" />
        </geometry>
     </collision>
     <collision>
        <origin xyz="-0.015750 0.000000 0.018700" rpy="0.00000000 -0.00000000 -3.14159265"/>
        <geometry>
          <box size="0.005200 0.011600 0.024000" />
        </geometry>
     </collision>
     <collision>
        <origin xyz="-0.016150 -0.000000 0.003100" rpy="0.00000000 -0.00000000 -3.14159265"/>
        <geometry>
          <box size="0.004400 0.015600 0.007200" />
        </geometry>
     </collision>
     <visual>
        <origin xyz="0.013000 -0.000000 0.002500" rpy="0.00000000 0.00000000 0.00000000"/>
        <geometry>
        <mesh filename="package://robot_assembler/meshes/mesh_UPPER-ARM26.dae" scale="1.000000 1.000000 1.000000"/>
        </geometry>
     </visual>
     <collision>
        <origin xyz="0.016150 -0.000000 0.033100" rpy="0.00000000 0.00000000 0.00000000"/>
        <geometry>
          <box size="0.004400 0.001200 0.000800" />
        </geometry>
     </collision>
     <collision>
        <origin xyz="0.016150 -0.000000 0.031500" rpy="0.00000000 0.00000000 0.00000000"/>
        <geometry>
          <box size="0.004400 0.007600 0.002400" />
        </geometry>
     </collision>
     <collision>
        <origin xyz="0.016150 -0.000000 0.016700" rpy="0.00000000 0.00000000 0.00000000"/>
        <geometry>
          <box size="0.004400 0.012400 0.027200" />
        </geometry>
     </collision>
     <collision>
        <origin xyz="0.015750 0.000000 0.001300" rpy="0.00000000 0.00000000 0.00000000"/>
        <geometry>
          <box size="0.005200 0.016400 0.003600" />
        </geometry>
     </collision>
  </link>
  <xacro:gazebo_link_reference link_name="LINK2" />
  <link name="LINK2">
     <inertial>
        <mass value="0.071723"/>
        <origin rpy="0 0 0" xyz="-0.029208 9.585489e-07 -0.018337"/>
        <inertia ixx="0.002004" ixy="8.106716e-10" ixz="-2.847049e-07" iyy="0.002044" iyz="3.377936e-10" izz="0.002044"/>
     </inertial>
     <visual>
        <origin xyz="0.000000 0.000000 -0.018000" rpy="0.00000000 -0.00000000 -3.14159265"/>
        <geometry>
        <mesh filename="package://robot_assembler/meshes/mesh_SERVO-S3301.dae" scale="1.000000 1.000000 1.000000"/>
        </geometry>
     </visual>
     <collision>
        <origin xyz="-0.000050 -0.000000 -0.002250" rpy="0.00000000 -0.00000000 -3.14159265"/>
        <geometry>
          <box size="0.006000 0.006000 0.003200" />
        </geometry>
     </collision>
     <collision>
        <origin xyz="-0.000050 -0.000000 -0.004450" rpy="0.00000000 -0.00000000 -3.14159265"/>
        <geometry>
          <box size="0.011600 0.011600 0.001200" />
        </geometry>
     </collision>
     <collision>
        <origin xyz="-0.007250 -0.000000 -0.018250" rpy="0.00000000 -0.00000000 -3.14159265"/>
        <geometry>
          <box size="0.032400 0.026000 0.026400" />
        </geometry>
     </collision>
     <collision>
        <origin xyz="-0.000050 -0.000000 -0.031850" rpy="0.00000000 -0.00000000 -3.14159265"/>
        <geometry>
          <box size="0.012400 0.012400 0.000800" />
        </geometry>
     </collision>
     <collision>
        <origin xyz="0.000150 0.000000 -0.033050" rpy="0.00000000 -0.00000000 -3.14159265"/>
        <geometry>
          <box size="0.005600 0.006000 0.001600" />
        </geometry>
     </collision>
     <visual>
        <origin xyz="-0.030000 -0.000000 -0.031000" rpy="-2.89661399 1.57079633 1.81577499"/>
        <geometry>
        <mesh filename="package://robot_assembler/meshes/mesh_JOINT-FRAME-A.dae" scale="1.000000 1.000000 1.000000"/>
        </geometry>
     </visual>
     <collision>
        <origin xyz="-0.026600 -0.012600 -0.031750" rpy="-2.89661399 1.57079633 1.81577499"/>
        <geometry>
          <box size="0.002800 0.013200 0.000800" />
        </geometry>
     </collision>
     <collision>
        <origin xyz="-0.025600 -0.008800 -0.031750" rpy="-2.89661399 1.57079633 1.81577499"/>
        <geometry>
          <box size="0.002800 0.015200 0.006800" />
        </geometry>
     </collision>
     <collision>
        <origin xyz="-0.024800 0.003600 -0.031750" rpy="-2.89661399 1.57079633 1.81577499"/>
        <geometry>
          <box size="0.002800 0.016000 0.018000" />
        </geometry>
     </collision>
     <collision>
        <origin xyz="-0.026000 0.012800 -0.031750" rpy="-2.89661399 1.57079633 1.81577499"/>
        <geometry>
          <box size="0.002800 0.014400 0.000400" />
        </geometry>
     </collision>
     <visual>
        <origin xyz="-0.030000 -0.000000 -0.018000" rpy="1.57079633 -0.00000000 1.57079633"/>
        <geometry>
        <mesh filename="package://robot_assembler/meshes/mesh_JOINT-BASE.dae" scale="1.000000 1.000000 1.000000"/>
        </geometry>
     </visual>
     <collision>
        <origin xyz="-0.030000 -0.000000 -0.018000" rpy="1.57079633 -0.00000000 1.57079633"/>
        <geometry>
          <box size="0.026800 0.026800 0.006000" />
        </geometry>
     </collision>
     <visual>
        <origin xyz="-0.036000 -0.000000 -0.018000" rpy="-1.57079633 -0.00000000 1.57079633"/>
        <geometry>
        <mesh filename="package://robot_assembler/meshes/mesh_JOINT-BASE.dae" scale="1.000000 1.000000 1.000000"/>
        </geometry>
     </visual>
     <collision>
        <origin xyz="-0.036000 -0.000000 -0.018000" rpy="-1.57079633 -0.00000000 1.57079633"/>
        <geometry>
          <box size="0.026800 0.026800 0.006000" />
        </geometry>
     </collision>
     <visual>
        <origin xyz="-0.036000 -0.013000 -0.018000" rpy="3.14159265 0.00000000 -1.57079633"/>
        <geometry>
        <mesh filename="package://robot_assembler/meshes/mesh_JOINT-FRAME-B-A.dae" scale="1.000000 1.000000 1.000000"/>
        </geometry>
     </visual>
     <collision>
        <origin xyz="-0.044600 -0.013350 -0.040250" rpy="3.14159265 0.00000000 -1.57079633"/>
        <geometry>
          <box size="0.002000 0.003600 0.002400" />
        </geometry>
     </collision>
     <collision>
        <origin xyz="-0.045200 -0.013350 -0.037250" rpy="3.14159265 0.00000000 -1.57079633"/>
        <geometry>
          <box size="0.002000 0.007200 0.003600" />
        </geometry>
     </collision>
     <collision>
        <origin xyz="-0.043800 -0.013750 -0.033250" rpy="3.14159265 0.00000000 -1.57079633"/>
        <geometry>
          <box size="0.002800 0.010000 0.004400" />
        </geometry>
     </collision>
     <collision>
        <origin xyz="-0.040800 -0.013750 -0.020650" rpy="3.14159265 0.00000000 -1.57079633"/>
        <geometry>
          <box size="0.002800 0.016000 0.020800" />
        </geometry>
     </collision>
     <collision>
        <origin xyz="-0.039400 -0.013750 -0.007650" rpy="3.14159265 0.00000000 -1.57079633"/>
        <geometry>
          <box size="0.002800 0.012400 0.005200" />
        </geometry>
     </collision>
     <visual>
        <origin xyz="-0.055500 -0.000000 -0.018000" rpy="-2.65711472 1.57079633 2.05527426"/>
        <geometry>
        <mesh filename="package://robot_assembler/meshes/mesh_SERVO-S3301.dae" scale="1.000000 1.000000 1.000000"/>
        </geometry>
     </visual>
     <collision>
        <origin xyz="-0.055500 -0.015750 -0.018050" rpy="-2.69717344 1.57079633 2.01521554"/>
        <geometry>
          <box size="0.006000 0.006000 0.003200" />
        </geometry>
     </collision>
     <collision>
        <origin xyz="-0.055500 -0.013550 -0.018050" rpy="-2.69717344 1.57079633 2.01521554"/>
        <geometry>
          <box size="0.011600 0.011600 0.001200" />
        </geometry>
     </collision>
     <collision>
        <origin xyz="-0.055500 0.000250 -0.025250" rpy="-2.69717344 1.57079633 2.01521554"/>
        <geometry>
          <box size="0.032400 0.026000 0.026400" />
        </geometry>
     </collision>
     <collision>
        <origin xyz="-0.055500 0.013850 -0.018050" rpy="-2.69717344 1.57079633 2.01521554"/>
        <geometry>
          <box size="0.012400 0.012400 0.000800" />
        </geometry>
     </collision>
     <collision>
        <origin xyz="-0.055500 0.015050 -0.017850" rpy="-2.69717344 1.57079633 2.01521554"/>
        <geometry>
          <box size="0.005600 0.006000 0.001600" />
        </geometry>
     </collision>
     <visual>
        <origin xyz="-0.036000 0.013000 -0.018000" rpy="0.00000000 0.00000000 1.57079633"/>
        <geometry>
        <mesh filename="package://robot_assembler/meshes/mesh_JOINT-FRAME-B-B.dae" scale="1.000000 1.000000 1.000000"/>
        </geometry>
     </visual>
     <collision>
        <origin xyz="-0.037600 0.013750 -0.007850" rpy="0.00000000 0.00000000 1.57079633"/>
        <geometry>
          <box size="0.002800 0.008800 0.005600" />
        </geometry>
     </collision>
     <collision>
        <origin xyz="-0.039400 0.013750 -0.021050" rpy="0.00000000 0.00000000 1.57079633"/>
        <geometry>
          <box size="0.002800 0.013200 0.020800" />
        </geometry>
     </collision>
     <collision>
        <origin xyz="-0.042800 0.013750 -0.034250" rpy="0.00000000 0.00000000 1.57079633"/>
        <geometry>
          <box size="0.002800 0.012800 0.005600" />
        </geometry>
     </collision>
     <collision>
        <origin xyz="-0.044400 0.013550 -0.039050" rpy="0.00000000 0.00000000 1.57079633"/>
        <geometry>
          <box size="0.002400 0.008800 0.004000" />
        </geometry>
     </collision>
     <collision>
        <origin xyz="-0.045000 0.013350 -0.041250" rpy="0.00000000 0.00000000 1.57079633"/>
        <geometry>
          <box size="0.002000 0.004400 0.000400" />
        </geometry>
     </collision>
     <visual>
        <origin xyz="-0.030000 -0.000000 -0.005000" rpy="1.37340077 -1.57079633 -2.94419709"/>
        <geometry>
        <mesh filename="package://robot_assembler/meshes/mesh_JOINT-FRAME-A.dae" scale="1.000000 1.000000 1.000000"/>
        </geometry>
     </visual>
     <collision>
        <origin xyz="-0.026600 0.012600 -0.004250" rpy="1.37340077 -1.57079633 -2.94419709"/>
        <geometry>
          <box size="0.002800 0.013200 0.000800" />
        </geometry>
     </collision>
     <collision>
        <origin xyz="-0.025600 0.008800 -0.004250" rpy="1.37340077 -1.57079633 -2.94419709"/>
        <geometry>
          <box size="0.002800 0.015200 0.006800" />
        </geometry>
     </collision>
     <collision>
        <origin xyz="-0.024800 -0.003600 -0.004250" rpy="1.37340077 -1.57079633 -2.94419709"/>
        <geometry>
          <box size="0.002800 0.016000 0.018000" />
        </geometry>
     </collision>
     <collision>
        <origin xyz="-0.026000 -0.012800 -0.004250" rpy="1.37340077 -1.57079633 -2.94419709"/>
        <geometry>
          <box size="0.002800 0.014400 0.000400" />
        </geometry>
     </collision>
  </link>
  <xacro:gazebo_link_reference link_name="LINK3" />
  <link name="LINK3">
     <inertial>
        <mass value="0.013908"/>
        <origin rpy="0 0 0" xyz="0.008 0.013856 -0.018"/>
        <inertia ixx="4.882867e-06" ixy="-1.349004e-06" ixz="2.970003e-22" iyy="3.325171e-06" iyz="-1.033409e-21" izz="4.682360e-06"/>
     </inertial>
     <visual>
        <origin xyz="0.000000 -0.000000 -0.033500" rpy="0.60940904 1.57079633 0.08581026"/>
        <geometry>
        <mesh filename="package://robot_assembler/meshes/mesh_FINGER.dae" scale="1.000000 1.000000 1.000000"/>
        </geometry>
     </visual>
     <collision>
        <origin xyz="0.023160 0.020115 -0.018000" rpy="0.61225466 1.57079633 0.08865588"/>
        <geometry>
          <box size="0.038800 0.032000 0.006000" />
        </geometry>
     </collision>
     <collision>
        <origin xyz="0.011369 0.007292 -0.018000" rpy="0.61225466 1.57079633 0.08865588"/>
        <geometry>
          <box size="0.038800 0.002000 0.013600" />
        </geometry>
     </collision>
     <collision>
        <origin xyz="0.004398 0.001618 -0.018000" rpy="0.61225466 1.57079633 0.08865588"/>
        <geometry>
          <box size="0.038800 0.014800 0.020000" />
        </geometry>
     </collision>
     <collision>
        <origin xyz="-0.003573 -0.005789 -0.018000" rpy="0.61225466 1.57079633 0.08865588"/>
        <geometry>
          <box size="0.038800 0.006000 0.024000" />
        </geometry>
     </collision>
     <collision>
        <origin xyz="-0.005400 -0.009353 -0.018000" rpy="0.61225466 1.57079633 0.08865588"/>
        <geometry>
          <box size="0.038800 0.002000 0.017200" />
        </geometry>
     </collision>
     <collision>
        <origin xyz="-0.006373 -0.010639 -0.018000" rpy="0.61225466 1.57079633 0.08865588"/>
        <geometry>
          <box size="0.038800 0.001200 0.010400" />
        </geometry>
     </collision>
  </link>
  <xacro:gazebo_link_reference link_name="LINK4" />
  <link name="LINK4">
     <inertial>
        <mass value="0.013908"/>
        <origin rpy="0 0 0" xyz="0.008 0.013856 -0.018"/>
        <inertia ixx="4.882867e-06" ixy="-1.349004e-06" ixz="1.430153e-22" iyy="3.325171e-06" iyz="8.460968e-22" izz="4.682360e-06"/>
     </inertial>
     <visual>
        <origin xyz="-0.000000 0.000000 -0.002500" rpy="-0.63902544 -1.57079633 0.11542666"/>
        <geometry>
        <mesh filename="package://robot_assembler/meshes/mesh_FINGER.dae" scale="1.000000 1.000000 1.000000"/>
        </geometry>
     </visual>
     <collision>
        <origin xyz="0.005840 0.030115 -0.018000" rpy="-0.52359878 -1.57079633 0.00000000"/>
        <geometry>
          <box size="0.038800 0.032000 0.006000" />
        </geometry>
     </collision>
     <collision>
        <origin xyz="0.000631 0.013492 -0.018000" rpy="-0.52359878 -1.57079633 0.00000000"/>
        <geometry>
          <box size="0.038800 0.002000 0.013600" />
        </geometry>
     </collision>
     <collision>
        <origin xyz="-0.000798 0.004618 -0.018000" rpy="-0.52359878 -1.57079633 0.00000000"/>
        <geometry>
          <box size="0.038800 0.014800 0.020000" />
        </geometry>
     </collision>
     <collision>
        <origin xyz="-0.003227 -0.005989 -0.018000" rpy="-0.52359878 -1.57079633 0.00000000"/>
        <geometry>
          <box size="0.038800 0.006000 0.024000" />
        </geometry>
     </collision>
     <collision>
        <origin xyz="-0.005400 -0.009353 -0.018000" rpy="-0.52359878 -1.57079633 0.00000000"/>
        <geometry>
          <box size="0.038800 0.002000 0.017200" />
        </geometry>
     </collision>
     <collision>
        <origin xyz="-0.006027 -0.010839 -0.018000" rpy="-0.52359878 -1.57079633 0.00000000"/>
        <geometry>
          <box size="0.038800 0.001200 0.010400" />
        </geometry>
     </collision>
  </link>
  <xacro:gazebo_transmission joint_name="rarm-shoulder-r" />
  <joint name="rarm-shoulder-r" type="revolute">
     <parent link="BASE"/>
     <child link="LINK0"/>
     <origin xyz="0.017500 0.000000 0.023000" rpy="0.00000000 1.57079633 0.00000000"/>
     <axis xyz=" 0  0  1"/>
     <limit lower="-4.71239000" upper="4.71239000" velocity="40.00" effort="200.00" />
  </joint>
  <xacro:gazebo_transmission joint_name="rarm-shoulder-y" />
  <joint name="rarm-shoulder-y" type="revolute">
     <parent link="LINK0"/>
     <child link="LINK1"/>
     <origin xyz="-0.070000 -0.000000 -0.018000" rpy="-1.57079633 -0.00000000 1.57079633"/>
     <axis xyz=" 0  0  1"/>
     <limit lower="-4.71239000" upper="4.71239000" velocity="40.00" effort="200.00" />
  </joint>
  <xacro:gazebo_transmission joint_name="rarm-elbow-p" />
  <joint name="rarm-elbow-p" type="revolute">
     <parent link="LINK1"/>
     <child link="LINK2"/>
     <origin xyz="0.017500 -0.000000 0.025500" rpy="0.81482692 1.57079633 0.81482692"/>
     <axis xyz=" 0  0  1"/>
     <limit lower="-4.71239000" upper="4.71239000" velocity="40.00" effort="200.00" />
  </joint>
  <xacro:gazebo_transmission joint_name="rarm-gripper-r" />
  <joint name="rarm-gripper-r" type="revolute">
     <parent link="LINK2"/>
     <child link="LINK3"/>
     <origin xyz="-0.055500 -0.018000 -0.018000" rpy="2.12939564 -1.57079633 -0.55859932"/>
     <axis xyz=" 0  0  1"/>
     <limit lower="-4.71239000" upper="4.71239000" velocity="40.00" effort="200.00" />
  </joint>
  <xacro:gazebo_transmission joint_name="rarm-gripper2-r" />
  <joint name="rarm-gripper2-r" type="revolute">
     <parent link="LINK2"/>
     <child link="LINK4"/>
     <origin xyz="-0.066000 -0.018000 -0.039000" rpy="2.12939564 -1.57079633 -0.55859932"/>
     <axis xyz=" 0  0  1"/>
     <limit lower="-4.71239000" upper="4.71239000" velocity="40.00" effort="200.00" />
  </joint>

  <!-- Gazebo plugin for ROS Control -->
  <gazebo>
    <plugin name="gazebo_ros_control" filename="libgazebo_ros_control.so">
      <!--robotNamespace>/</robotNamespace-->
      <legacyModeNS>false</legacyModeNS>
      <robotSimType>gazebo_ros_control/DefaultRobotHWSim</robotSimType>
    </plugin>
  </gazebo>
</robot>
