<?xml version="1.0" ?>
<!-- This file was generated by robot assembler -->
<robot name="rleg"
       xmlns:xi="http://www.w3.org/2001/XInclude"
       xmlns:gazebo="http://playerstage.sourceforge.net/gazebo/xmlschema/#gz"
       xmlns:model="http://playerstage.sourceforge.net/gazebo/xmlschema/#model"
       xmlns:sensor="http://playerstage.sourceforge.net/gazebo/xmlschema/#sensor"
       xmlns:body="http://playerstage.sourceforge.net/gazebo/xmlschema/#body"
       xmlns:geom="http://playerstage.sourceforge.net/gazebo/xmlschema/#geom"
       xmlns:joint="http://playerstage.sourceforge.net/gazebo/xmlschema/#joint"
       xmlns:interface="http://playerstage.sourceforge.net/gazebo/xmlschema/#interface"
       xmlns:rendering="http://playerstage.sourceforge.net/gazebo/xmlschema/#rendering"
       xmlns:renderable="http://playerstage.sourceforge.net/gazebo/xmlschema/#renderable"
       xmlns:controller="http://playerstage.sourceforge.net/gazebo/xmlschema/#controller"
       xmlns:physics="http://playerstage.sourceforge.net/gazebo/xmlschema/#physics"
       xmlns:xacro="http://www.ros.org/wiki/xacro">
  <xacro:macro name="gazebo_link_reference" params="link_name mu1:=0.9 mu2:=0.9" >
    <gazebo reference="${link_name}">
      <mu1>${mu1}</mu1>
      <mu2>${mu2}</mu2>
    </gazebo>
  </xacro:macro>
  <xacro:macro name="gazebo_transmission" params="joint_name" >
    <transmission name="${joint_name}_trans">
      <type>transmission_interface/SimpleTransmission</type>
      <joint name="${joint_name}">
        <hardwareInterface>hardware_interface/VelocityJointInterface</hardwareInterface>
        <!--hardwareInterface>hardware_interface/EffortJointInterface</hardwareInterface-->
      </joint>
      <actuator name="${joint_name}_motor">
        <hardwareInterface>hardware_interface/VelocityJointInterface</hardwareInterface>
        <!--hardwareInterface>hardware_interface/EffortJointInterface</hardwareInterface-->
        <mechanicalReduction>1</mechanicalReduction>
      </actuator>
    </transmission>
  </xacro:macro>

  <xacro:macro name="no_gazebo_transmission" params="joint_name" >
    <!-- dummy for fixed joint -->
  </xacro:macro>
  <xacro:gazebo_link_reference link_name="BASE" />
  <link name="BASE">
     <inertial>
        <mass value="0.012371"/>
        <origin rpy="0 0 0" xyz="2.297446e-18 4.967856e-18 0.008706"/>
        <inertia ixx="1.937420e-06" ixy="1.058633e-21" ixz="-1.705303e-22" iyy="3.583435e-06" iyz="-8.045714e-22" izz="2.583068e-06"/>
     </inertial>
     <visual>
        <origin xyz="0.000000 0.000000 0.000000" rpy="0.00000000 -0.00000000 0.00000000"/>
        <geometry>
        <mesh filename="package://robot_assembler/meshes/mesh_JOINT-BASE.dae" scale="1.000000 1.000000 1.000000"/>
        </geometry>
     </visual>
     <collision>
        <origin xyz="0.000000 0.000000 0.000000" rpy="0.00000000 -0.00000000 0.00000000"/>
        <geometry>
          <box size="0.026800 0.026800 0.006000" />
        </geometry>
     </collision>
     <visual>
        <origin xyz="-0.013000 0.000000 -0.000000" rpy="0.00000000 -0.00000000 -3.14159265"/>
        <geometry>
        <mesh filename="package://robot_assembler/meshes/mesh_UPPER-ARM28.dae" scale="1.000000 1.000000 1.000000"/>
        </geometry>
     </visual>
     <collision>
        <origin xyz="-0.016150 0.000000 0.032400" rpy="0.00000000 -0.00000000 -3.14159265"/>
        <geometry>
          <box size="0.004400 0.002800 0.000800" />
        </geometry>
     </collision>
     <collision>
        <origin xyz="-0.016150 0.000000 0.031000" rpy="0.00000000 -0.00000000 -3.14159265"/>
        <geometry>
          <box size="0.004400 0.008400 0.002000" />
        </geometry>
     </collision>
     <collision>
        <origin xyz="-0.016150 0.000000 0.015600" rpy="0.00000000 -0.00000000 -3.14159265"/>
        <geometry>
          <box size="0.004400 0.012400 0.028800" />
        </geometry>
     </collision>
     <collision>
        <origin xyz="-0.015750 -0.000000 -0.001000" rpy="0.00000000 -0.00000000 -3.14159265"/>
        <geometry>
          <box size="0.005200 0.016400 0.004400" />
        </geometry>
     </collision>
     <visual>
        <origin xyz="0.013000 0.000000 0.000000" rpy="0.00000000 -0.00000000 0.00000000"/>
        <geometry>
        <mesh filename="package://robot_assembler/meshes/mesh_BOTTOM-ARM28.dae" scale="1.000000 1.000000 1.000000"/>
        </geometry>
     </visual>
     <collision>
        <origin xyz="0.016150 0.000000 0.032400" rpy="0.00000000 -0.00000000 0.00000000"/>
        <geometry>
          <box size="0.004400 0.002800 0.000800" />
        </geometry>
     </collision>
     <collision>
        <origin xyz="0.016150 0.000000 0.031000" rpy="0.00000000 -0.00000000 0.00000000"/>
        <geometry>
          <box size="0.004400 0.008400 0.002000" />
        </geometry>
     </collision>
     <collision>
        <origin xyz="0.015750 0.000000 0.015600" rpy="0.00000000 -0.00000000 0.00000000"/>
        <geometry>
          <box size="0.005200 0.012400 0.028800" />
        </geometry>
     </collision>
     <collision>
        <origin xyz="0.015750 0.000000 -0.001000" rpy="0.00000000 -0.00000000 0.00000000"/>
        <geometry>
          <box size="0.005200 0.016400 0.004400" />
        </geometry>
     </collision>
  </link>
  <xacro:gazebo_link_reference link_name="LINK0" />
  <link name="LINK0">
     <inertial>
        <mass value="0.061777"/>
        <origin rpy="0 0 0" xyz="-0.001295 -1.828736e-18 0.001582"/>
        <inertia ixx="0.00202" ixy="-2.557679e-21" ixz="1.039537e-06" iyy="0.002021" iyz="2.403882e-21" izz="0.002002"/>
     </inertial>
     <visual>
        <origin xyz="0.000000 -0.000000 -0.018000" rpy="-0.00000000 -0.00000000 -3.14159265"/>
        <geometry>
        <mesh filename="package://robot_assembler/meshes/mesh_SERVO-S3301.dae" scale="1.000000 1.000000 1.000000"/>
        </geometry>
     </visual>
     <collision>
        <origin xyz="-0.000050 -0.000000 -0.002250" rpy="-0.00000000 -0.00000000 -3.14159265"/>
        <geometry>
          <box size="0.006000 0.006000 0.003200" />
        </geometry>
     </collision>
     <collision>
        <origin xyz="-0.000050 -0.000000 -0.004450" rpy="-0.00000000 -0.00000000 -3.14159265"/>
        <geometry>
          <box size="0.011600 0.011600 0.001200" />
        </geometry>
     </collision>
     <collision>
        <origin xyz="-0.007250 -0.000000 -0.018250" rpy="-0.00000000 -0.00000000 -3.14159265"/>
        <geometry>
          <box size="0.032400 0.026000 0.026400" />
        </geometry>
     </collision>
     <collision>
        <origin xyz="-0.000050 -0.000000 -0.031850" rpy="-0.00000000 -0.00000000 -3.14159265"/>
        <geometry>
          <box size="0.012400 0.012400 0.000800" />
        </geometry>
     </collision>
     <collision>
        <origin xyz="0.000150 0.000000 -0.033050" rpy="-0.00000000 -0.00000000 -3.14159265"/>
        <geometry>
          <box size="0.005600 0.006000 0.001600" />
        </geometry>
     </collision>
     <visual>
        <origin xyz="0.000000 0.000000 0.006500" rpy="1.40690422 1.57079633 1.40690422"/>
        <geometry>
        <mesh filename="package://robot_assembler/meshes/mesh_CROSS-SERVO-FRAME-A.dae" scale="1.000000 1.000000 1.000000"/>
        </geometry>
     </visual>
     <collision>
        <origin xyz="0.007700 0.000000 -0.003900" rpy="1.40690422 1.57079633 1.40690422"/>
        <geometry>
          <box size="0.002800 0.000400 0.000800" />
        </geometry>
     </collision>
     <collision>
        <origin xyz="0.006500 0.000000 -0.003900" rpy="1.40690422 1.57079633 1.40690422"/>
        <geometry>
          <box size="0.002800 0.006000 0.001600" />
        </geometry>
     </collision>
     <collision>
        <origin xyz="0.004900 0.000000 -0.004100" rpy="1.40690422 1.57079633 1.40690422"/>
        <geometry>
          <box size="0.003200 0.010800 0.001600" />
        </geometry>
     </collision>
     <collision>
        <origin xyz="-0.003900 0.000000 0.000500" rpy="1.40690422 1.57079633 1.40690422"/>
        <geometry>
          <box size="0.012400 0.030000 0.016000" />
        </geometry>
     </collision>
     <collision>
        <origin xyz="-0.014100 -0.000000 0.004900" rpy="1.40690422 1.57079633 1.40690422"/>
        <geometry>
          <box size="0.010800 0.030000 0.004400" />
        </geometry>
     </collision>
     <collision>
        <origin xyz="-0.020100 -0.000000 0.002500" rpy="1.40690422 1.57079633 1.40690422"/>
        <geometry>
          <box size="0.015600 0.030000 0.007600" />
        </geometry>
     </collision>
     <collision>
        <origin xyz="-0.024100 -0.000000 0.004900" rpy="1.40690422 1.57079633 1.40690422"/>
        <geometry>
          <box size="0.009200 0.030000 0.000400" />
        </geometry>
     </collision>
     <collision>
        <origin xyz="-0.024700 -0.000000 0.006500" rpy="1.40690422 1.57079633 1.40690422"/>
        <geometry>
          <box size="0.003600 0.030000 0.000800" />
        </geometry>
     </collision>
     <visual>
        <origin xyz="-0.000000 0.000000 0.017000" rpy="-1.57079633 0.00000000 -3.14159265"/>
        <geometry>
        <mesh filename="package://robot_assembler/meshes/mesh_SERVO-S3301.dae" scale="1.000000 1.000000 1.000000"/>
        </geometry>
     </visual>
     <collision>
        <origin xyz="-0.000050 -0.015750 0.017000" rpy="-1.57079633 0.00000000 -3.14159265"/>
        <geometry>
          <box size="0.006000 0.006000 0.003200" />
        </geometry>
     </collision>
     <collision>
        <origin xyz="-0.000050 -0.013550 0.017000" rpy="-1.57079633 0.00000000 -3.14159265"/>
        <geometry>
          <box size="0.011600 0.011600 0.001200" />
        </geometry>
     </collision>
     <collision>
        <origin xyz="-0.007250 0.000250 0.017000" rpy="-1.57079633 0.00000000 -3.14159265"/>
        <geometry>
          <box size="0.032400 0.026000 0.026400" />
        </geometry>
     </collision>
     <collision>
        <origin xyz="-0.000050 0.013850 0.017000" rpy="-1.57079633 0.00000000 -3.14159265"/>
        <geometry>
          <box size="0.012400 0.012400 0.000800" />
        </geometry>
     </collision>
     <collision>
        <origin xyz="0.000150 0.015050 0.017000" rpy="-1.57079633 0.00000000 -3.14159265"/>
        <geometry>
          <box size="0.005600 0.006000 0.001600" />
        </geometry>
     </collision>
     <visual>
        <origin xyz="-0.000000 -0.000000 0.027500" rpy="1.74622570 1.57079633 1.74622570"/>
        <geometry>
        <mesh filename="package://robot_assembler/meshes/mesh_CROSS-SERVO-FRAME-B.dae" scale="1.000000 1.000000 1.000000"/>
        </geometry>
     </visual>
     <collision>
        <origin xyz="0.005300 -0.000000 0.033000" rpy="1.74622570 1.57079633 1.74622570"/>
        <geometry>
          <box size="0.003200 0.002000 0.001200" />
        </geometry>
     </collision>
     <collision>
        <origin xyz="0.004300 -0.000000 0.033000" rpy="1.74622570 1.57079633 1.74622570"/>
        <geometry>
          <box size="0.003200 0.007600 0.000800" />
        </geometry>
     </collision>
     <collision>
        <origin xyz="0.002900 -0.000000 0.030800" rpy="1.74622570 1.57079633 1.74622570"/>
        <geometry>
          <box size="0.007600 0.030000 0.002000" />
        </geometry>
     </collision>
     <collision>
        <origin xyz="-0.010500 -0.000000 0.030400" rpy="1.74622570 1.57079633 1.74622570"/>
        <geometry>
          <box size="0.012400 0.030000 0.024800" />
        </geometry>
     </collision>
     <collision>
        <origin xyz="-0.023700 -0.000000 0.028000" rpy="1.74622570 1.57079633 1.74622570"/>
        <geometry>
          <box size="0.007600 0.030000 0.001600" />
        </geometry>
     </collision>
     <collision>
        <origin xyz="-0.024700 -0.000000 0.027600" rpy="1.74622570 1.57079633 1.74622570"/>
        <geometry>
          <box size="0.002800 0.030000 0.000400" />
        </geometry>
     </collision>
  </link>
  <xacro:gazebo_link_reference link_name="LINK1" />
  <link name="LINK1">
     <inertial>
        <mass value="0.025166"/>
        <origin rpy="0 0 0" xyz="-0.032563 -7.070122e-17 -0.0175"/>
        <inertia ixx="5.281429e-06" ixy="-4.257597e-21" ixz="-5.229595e-21" iyy="1.170518e-05" iyz="-3.532905e-21" izz="8.315946e-06"/>
     </inertial>
     <visual>
        <origin xyz="-0.035000 -0.000000 -0.004500" rpy="-0.69388606 -1.57079633 -2.44770659"/>
        <geometry>
        <mesh filename="package://robot_assembler/meshes/mesh_UPPER-ARM38.dae" scale="1.000000 1.000000 1.000000"/>
        </geometry>
     </visual>
     <collision>
        <origin xyz="0.007600 0.000000 -0.001150" rpy="-1.05599037 -1.57079633 -2.08560228"/>
        <geometry>
          <box size="0.004000 0.001200 0.000800" />
        </geometry>
     </collision>
     <collision>
        <origin xyz="0.006000 0.000000 -0.001350" rpy="-1.05599037 -1.57079633 -2.08560228"/>
        <geometry>
          <box size="0.004400 0.007600 0.002400" />
        </geometry>
     </collision>
     <collision>
        <origin xyz="-0.013800 -0.000000 -0.001350" rpy="-1.05599037 -1.57079633 -2.08560228"/>
        <geometry>
          <box size="0.004400 0.012400 0.037200" />
        </geometry>
     </collision>
     <collision>
        <origin xyz="-0.035200 -0.000000 -0.001750" rpy="-1.05599037 -1.57079633 -2.08560228"/>
        <geometry>
          <box size="0.005200 0.016400 0.005600" />
        </geometry>
     </collision>
     <visual>
        <origin xyz="-0.035000 -0.000000 -0.017500" rpy="-1.57079633 -0.00000000 -1.57079633"/>
        <geometry>
        <mesh filename="package://robot_assembler/meshes/mesh_JOINT-BASE.dae" scale="1.000000 1.000000 1.000000"/>
        </geometry>
     </visual>
     <collision>
        <origin xyz="-0.035000 -0.000000 -0.017500" rpy="-1.57079633 -0.00000000 -1.57079633"/>
        <geometry>
          <box size="0.026800 0.026800 0.006000" />
        </geometry>
     </collision>
     <visual>
        <origin xyz="-0.041000 -0.000000 -0.017500" rpy="1.57079633 -0.00000000 -1.57079633"/>
        <geometry>
        <mesh filename="package://robot_assembler/meshes/mesh_JOINT-BASE.dae" scale="1.000000 1.000000 1.000000"/>
        </geometry>
     </visual>
     <collision>
        <origin xyz="-0.041000 -0.000000 -0.017500" rpy="1.57079633 -0.00000000 -1.57079633"/>
        <geometry>
          <box size="0.026800 0.026800 0.006000" />
        </geometry>
     </collision>
     <visual>
        <origin xyz="-0.041000 -0.000000 -0.030500" rpy="2.88395151 1.57079633 -0.25764115"/>
        <geometry>
        <mesh filename="package://robot_assembler/meshes/mesh_BOTTOM-ARM20.dae" scale="1.000000 1.000000 1.000000"/>
        </geometry>
     </visual>
     <collision>
        <origin xyz="-0.065400 -0.000000 -0.033650" rpy="2.88395151 1.57079633 -0.25764115"/>
        <geometry>
          <box size="0.004400 0.002800 0.000800" />
        </geometry>
     </collision>
     <collision>
        <origin xyz="-0.063800 -0.000000 -0.033650" rpy="2.88395151 1.57079633 -0.25764115"/>
        <geometry>
          <box size="0.004400 0.008400 0.002400" />
        </geometry>
     </collision>
     <collision>
        <origin xyz="-0.053800 -0.000000 -0.033250" rpy="2.88395151 1.57079633 -0.25764115"/>
        <geometry>
          <box size="0.005200 0.012400 0.017600" />
        </geometry>
     </collision>
     <collision>
        <origin xyz="-0.041400 -0.000000 -0.033650" rpy="2.88395151 1.57079633 -0.25764115"/>
        <geometry>
          <box size="0.004400 0.016400 0.007200" />
        </geometry>
     </collision>
     <visual>
        <origin xyz="-0.041000 -0.000000 -0.004500" rpy="-2.72546015 -1.57079633 2.72546015"/>
        <geometry>
        <mesh filename="package://robot_assembler/meshes/mesh_UPPER-ARM20.dae" scale="1.000000 1.000000 1.000000"/>
        </geometry>
     </visual>
     <collision>
        <origin xyz="-0.065400 -0.000000 -0.001350" rpy="-2.72546015 -1.57079633 2.72546015"/>
        <geometry>
          <box size="0.004400 0.002800 0.000800" />
        </geometry>
     </collision>
     <collision>
        <origin xyz="-0.063800 -0.000000 -0.001350" rpy="-2.72546015 -1.57079633 2.72546015"/>
        <geometry>
          <box size="0.004400 0.008400 0.002400" />
        </geometry>
     </collision>
     <collision>
        <origin xyz="-0.053800 -0.000000 -0.001350" rpy="-2.72546015 -1.57079633 2.72546015"/>
        <geometry>
          <box size="0.004400 0.012400 0.017600" />
        </geometry>
     </collision>
     <collision>
        <origin xyz="-0.041400 -0.000000 -0.001350" rpy="-2.72546015 -1.57079633 2.72546015"/>
        <geometry>
          <box size="0.004400 0.016400 0.007200" />
        </geometry>
     </collision>
     <visual>
        <origin xyz="-0.035000 -0.000000 -0.030500" rpy="0.64266942 1.57079633 0.64266942"/>
        <geometry>
        <mesh filename="package://robot_assembler/meshes/mesh_BOTTOM-ARM38.dae" scale="1.000000 1.000000 1.000000"/>
        </geometry>
     </visual>
     <collision>
        <origin xyz="0.007600 -0.000000 -0.033850" rpy="0.79443243 1.57079633 0.79443243"/>
        <geometry>
          <box size="0.004000 0.001200 0.000800" />
        </geometry>
     </collision>
     <collision>
        <origin xyz="0.006200 -0.000000 -0.033650" rpy="0.79443243 1.57079633 0.79443243"/>
        <geometry>
          <box size="0.004400 0.007600 0.002000" />
        </geometry>
     </collision>
     <collision>
        <origin xyz="-0.012600 -0.000000 -0.033250" rpy="0.79443243 1.57079633 0.79443243"/>
        <geometry>
          <box size="0.005200 0.011600 0.035600" />
        </geometry>
     </collision>
     <collision>
        <origin xyz="-0.034200 -0.000000 -0.033650" rpy="0.79443243 1.57079633 0.79443243"/>
        <geometry>
          <box size="0.004400 0.015600 0.007600" />
        </geometry>
     </collision>
  </link>
  <xacro:gazebo_link_reference link_name="LINK2" />
  <link name="LINK2">
     <inertial>
        <mass value="0.055048"/>
        <origin rpy="0 0 0" xyz="-0.01223 -0.007733 -0.018"/>
        <inertia ixx="0.001018" ixy="-4.797495e-06" ixz="-1.296030e-20" iyy="0.001012" iyz="-1.000444e-20" izz="0.001022"/>
     </inertial>
     <visual>
        <origin xyz="0.000000 0.000000 -0.018000" rpy="-0.00000000 -0.00000000 -3.14159265"/>
        <geometry>
        <mesh filename="package://robot_assembler/meshes/mesh_SERVO-S3301.dae" scale="1.000000 1.000000 1.000000"/>
        </geometry>
     </visual>
     <collision>
        <origin xyz="-0.000050 -0.000000 -0.002250" rpy="-0.00000000 -0.00000000 -3.14159265"/>
        <geometry>
          <box size="0.006000 0.006000 0.003200" />
        </geometry>
     </collision>
     <collision>
        <origin xyz="-0.000050 -0.000000 -0.004450" rpy="-0.00000000 -0.00000000 -3.14159265"/>
        <geometry>
          <box size="0.011600 0.011600 0.001200" />
        </geometry>
     </collision>
     <collision>
        <origin xyz="-0.007250 -0.000000 -0.018250" rpy="-0.00000000 -0.00000000 -3.14159265"/>
        <geometry>
          <box size="0.032400 0.026000 0.026400" />
        </geometry>
     </collision>
     <collision>
        <origin xyz="-0.000050 0.000000 -0.031850" rpy="-0.00000000 -0.00000000 -3.14159265"/>
        <geometry>
          <box size="0.012400 0.012400 0.000800" />
        </geometry>
     </collision>
     <collision>
        <origin xyz="0.000150 0.000000 -0.033050" rpy="-0.00000000 -0.00000000 -3.14159265"/>
        <geometry>
          <box size="0.005600 0.006000 0.001600" />
        </geometry>
     </collision>
     <visual>
        <origin xyz="-0.023500 -0.000000 -0.033000" rpy="-1.96759629 1.57079633 1.17399637"/>
        <geometry>
        <mesh filename="package://robot_assembler/meshes/mesh_ANGLE-BRACKET.dae" scale="1.000000 1.000000 1.000000"/>
        </geometry>
     </visual>
     <collision>
        <origin xyz="-0.023500 -0.011350 -0.025500" rpy="-1.96759629 1.57079633 1.17399637"/>
        <geometry>
          <box size="0.014800 0.019600 0.018000" />
        </geometry>
     </collision>
     <collision>
        <origin xyz="-0.022500 0.001650 -0.025500" rpy="-1.96759629 1.57079633 1.17399637"/>
        <geometry>
          <box size="0.014800 0.006400 0.016000" />
        </geometry>
     </collision>
     <collision>
        <origin xyz="-0.021500 0.006850 -0.025500" rpy="-1.96759629 1.57079633 1.17399637"/>
        <geometry>
          <box size="0.014800 0.004000 0.014000" />
        </geometry>
     </collision>
     <collision>
        <origin xyz="-0.020500 0.010450 -0.025500" rpy="-1.96759629 1.57079633 1.17399637"/>
        <geometry>
          <box size="0.014800 0.003200 0.012000" />
        </geometry>
     </collision>
     <collision>
        <origin xyz="-0.019500 0.012850 -0.025500" rpy="-1.96759629 1.57079633 1.17399637"/>
        <geometry>
          <box size="0.014800 0.001600 0.010000" />
        </geometry>
     </collision>
     <visual>
        <origin xyz="-0.023500 -0.018000 -0.031000" rpy="2.31455191 1.57079633 0.74375558"/>
        <geometry>
        <mesh filename="package://robot_assembler/meshes/mesh_UPPER-ARM38.dae" scale="1.000000 1.000000 1.000000"/>
        </geometry>
     </visual>
     <collision>
        <origin xyz="-0.023500 -0.060600 -0.034350" rpy="2.35619449 1.57079633 0.78539816"/>
        <geometry>
          <box size="0.004000 0.001200 0.000800" />
        </geometry>
     </collision>
     <collision>
        <origin xyz="-0.023500 -0.059000 -0.034150" rpy="2.35619449 1.57079633 0.78539816"/>
        <geometry>
          <box size="0.004400 0.007600 0.002400" />
        </geometry>
     </collision>
     <collision>
        <origin xyz="-0.023500 -0.039200 -0.034150" rpy="2.35619449 1.57079633 0.78539816"/>
        <geometry>
          <box size="0.004400 0.012400 0.037200" />
        </geometry>
     </collision>
     <collision>
        <origin xyz="-0.023500 -0.017800 -0.033750" rpy="2.35619449 1.57079633 0.78539816"/>
        <geometry>
          <box size="0.005200 0.016400 0.005600" />
        </geometry>
     </collision>
     <visual>
        <origin xyz="-0.023500 -0.000000 -0.018000" rpy="-1.10784160 1.57079633 2.03375105"/>
        <geometry>
        <mesh filename="package://robot_assembler/meshes/mesh_ANGLE-BRACKET.dae" scale="1.000000 1.000000 1.000000"/>
        </geometry>
     </visual>
     <collision>
        <origin xyz="-0.023500 -0.011350 -0.010500" rpy="-1.24956534 1.57079633 1.89202731"/>
        <geometry>
          <box size="0.014800 0.019600 0.018000" />
        </geometry>
     </collision>
     <collision>
        <origin xyz="-0.022500 0.001650 -0.010500" rpy="-1.24956534 1.57079633 1.89202731"/>
        <geometry>
          <box size="0.014800 0.006400 0.016000" />
        </geometry>
     </collision>
     <collision>
        <origin xyz="-0.021500 0.006850 -0.010500" rpy="-1.24956534 1.57079633 1.89202731"/>
        <geometry>
          <box size="0.014800 0.004000 0.014000" />
        </geometry>
     </collision>
     <collision>
        <origin xyz="-0.020500 0.010450 -0.010500" rpy="-1.24956534 1.57079633 1.89202731"/>
        <geometry>
          <box size="0.014800 0.003200 0.012000" />
        </geometry>
     </collision>
     <collision>
        <origin xyz="-0.019500 0.012850 -0.010500" rpy="-1.24956534 1.57079633 1.89202731"/>
        <geometry>
          <box size="0.014800 0.001600 0.010000" />
        </geometry>
     </collision>
     <visual>
        <origin xyz="-0.023500 -0.018000 -0.005000" rpy="-2.30861139 -1.57079633 -2.40377759"/>
        <geometry>
        <mesh filename="package://robot_assembler/meshes/mesh_BOTTOM-ARM38.dae" scale="1.000000 1.000000 1.000000"/>
        </geometry>
     </visual>
     <collision>
        <origin xyz="-0.023500 -0.060600 -0.001650" rpy="-2.30361143 -1.57079633 -2.40877755"/>
        <geometry>
          <box size="0.004000 0.001200 0.000800" />
        </geometry>
     </collision>
     <collision>
        <origin xyz="-0.023500 -0.059200 -0.001850" rpy="-2.30361143 -1.57079633 -2.40877755"/>
        <geometry>
          <box size="0.004400 0.007600 0.002000" />
        </geometry>
     </collision>
     <collision>
        <origin xyz="-0.023500 -0.040400 -0.002250" rpy="-2.30361143 -1.57079633 -2.40877755"/>
        <geometry>
          <box size="0.005200 0.011600 0.035600" />
        </geometry>
     </collision>
     <collision>
        <origin xyz="-0.023500 -0.018800 -0.001850" rpy="-2.30361143 -1.57079633 -2.40877755"/>
        <geometry>
          <box size="0.004400 0.015600 0.007600" />
        </geometry>
     </collision>
  </link>
  <xacro:gazebo_link_reference link_name="LINK3" />
  <link name="LINK3">
     <inertial>
        <mass value="0.061777"/>
        <origin rpy="0 0 0" xyz="-0.001295 -0.015418 -0.018"/>
        <inertia ixx="0.00202" ixy="1.039537e-06" ixz="-2.282845e-21" iyy="0.002002" iyz="2.911839e-20" izz="0.002021"/>
     </inertial>
     <visual>
        <origin xyz="0.000000 0.000000 -0.018000" rpy="-0.00000000 -0.00000000 -3.14159265"/>
        <geometry>
        <mesh filename="package://robot_assembler/meshes/mesh_SERVO-S3301.dae" scale="1.000000 1.000000 1.000000"/>
        </geometry>
     </visual>
     <collision>
        <origin xyz="-0.000050 -0.000000 -0.002250" rpy="-0.00000000 -0.00000000 -3.14159265"/>
        <geometry>
          <box size="0.006000 0.006000 0.003200" />
        </geometry>
     </collision>
     <collision>
        <origin xyz="-0.000050 -0.000000 -0.004450" rpy="-0.00000000 -0.00000000 -3.14159265"/>
        <geometry>
          <box size="0.011600 0.011600 0.001200" />
        </geometry>
     </collision>
     <collision>
        <origin xyz="-0.007250 -0.000000 -0.018250" rpy="-0.00000000 -0.00000000 -3.14159265"/>
        <geometry>
          <box size="0.032400 0.026000 0.026400" />
        </geometry>
     </collision>
     <collision>
        <origin xyz="-0.000050 -0.000000 -0.031850" rpy="-0.00000000 -0.00000000 -3.14159265"/>
        <geometry>
          <box size="0.012400 0.012400 0.000800" />
        </geometry>
     </collision>
     <collision>
        <origin xyz="0.000150 0.000000 -0.033050" rpy="-0.00000000 -0.00000000 -3.14159265"/>
        <geometry>
          <box size="0.005600 0.006000 0.001600" />
        </geometry>
     </collision>
     <visual>
        <origin xyz="-0.000000 0.010500 -0.018000" rpy="-1.57079633 0.00000000 -1.57079633"/>
        <geometry>
        <mesh filename="package://robot_assembler/meshes/mesh_CROSS-SERVO-FRAME-B.dae" scale="1.000000 1.000000 1.000000"/>
        </geometry>
     </visual>
     <collision>
        <origin xyz="0.005300 0.016000 -0.018000" rpy="-1.57079633 0.00000000 -1.57079633"/>
        <geometry>
          <box size="0.003200 0.002000 0.001200" />
        </geometry>
     </collision>
     <collision>
        <origin xyz="0.004300 0.016000 -0.018000" rpy="-1.57079633 0.00000000 -1.57079633"/>
        <geometry>
          <box size="0.003200 0.007600 0.000800" />
        </geometry>
     </collision>
     <collision>
        <origin xyz="0.002900 0.013800 -0.018000" rpy="-1.57079633 0.00000000 -1.57079633"/>
        <geometry>
          <box size="0.007600 0.030000 0.002000" />
        </geometry>
     </collision>
     <collision>
        <origin xyz="-0.010500 0.013400 -0.018000" rpy="-1.57079633 0.00000000 -1.57079633"/>
        <geometry>
          <box size="0.012400 0.030000 0.024800" />
        </geometry>
     </collision>
     <collision>
        <origin xyz="-0.023700 0.011000 -0.018000" rpy="-1.57079633 0.00000000 -1.57079633"/>
        <geometry>
          <box size="0.007600 0.030000 0.001600" />
        </geometry>
     </collision>
     <collision>
        <origin xyz="-0.024700 0.010600 -0.018000" rpy="-1.57079633 0.00000000 -1.57079633"/>
        <geometry>
          <box size="0.002800 0.030000 0.000400" />
        </geometry>
     </collision>
     <visual>
        <origin xyz="0.000000 -0.010500 -0.018000" rpy="-1.57079633 -0.00000000 -1.57079633"/>
        <geometry>
        <mesh filename="package://robot_assembler/meshes/mesh_CROSS-SERVO-FRAME-A.dae" scale="1.000000 1.000000 1.000000"/>
        </geometry>
     </visual>
     <collision>
        <origin xyz="0.007700 -0.020900 -0.018000" rpy="-1.57079633 -0.00000000 -1.57079633"/>
        <geometry>
          <box size="0.002800 0.000400 0.000800" />
        </geometry>
     </collision>
     <collision>
        <origin xyz="0.006500 -0.020900 -0.018000" rpy="-1.57079633 -0.00000000 -1.57079633"/>
        <geometry>
          <box size="0.002800 0.006000 0.001600" />
        </geometry>
     </collision>
     <collision>
        <origin xyz="0.004900 -0.021100 -0.018000" rpy="-1.57079633 -0.00000000 -1.57079633"/>
        <geometry>
          <box size="0.003200 0.010800 0.001600" />
        </geometry>
     </collision>
     <collision>
        <origin xyz="-0.003900 -0.016500 -0.018000" rpy="-1.57079633 -0.00000000 -1.57079633"/>
        <geometry>
          <box size="0.012400 0.030000 0.016000" />
        </geometry>
     </collision>
     <collision>
        <origin xyz="-0.014100 -0.012100 -0.018000" rpy="-1.57079633 -0.00000000 -1.57079633"/>
        <geometry>
          <box size="0.010800 0.030000 0.004400" />
        </geometry>
     </collision>
     <collision>
        <origin xyz="-0.020100 -0.014500 -0.018000" rpy="-1.57079633 -0.00000000 -1.57079633"/>
        <geometry>
          <box size="0.015600 0.030000 0.007600" />
        </geometry>
     </collision>
     <collision>
        <origin xyz="-0.024100 -0.012100 -0.018000" rpy="-1.57079633 -0.00000000 -1.57079633"/>
        <geometry>
          <box size="0.009200 0.030000 0.000400" />
        </geometry>
     </collision>
     <collision>
        <origin xyz="-0.024700 -0.010500 -0.018000" rpy="-1.57079633 -0.00000000 -1.57079633"/>
        <geometry>
          <box size="0.003600 0.030000 0.000800" />
        </geometry>
     </collision>
     <visual>
        <origin xyz="0.000000 -0.035000 -0.018000" rpy="1.57079633 0.00000000 -3.14159265"/>
        <geometry>
        <mesh filename="package://robot_assembler/meshes/mesh_SERVO-S3301.dae" scale="1.000000 1.000000 1.000000"/>
        </geometry>
     </visual>
     <collision>
        <origin xyz="-0.000050 -0.019250 -0.018000" rpy="1.57079633 0.00000000 -3.14159265"/>
        <geometry>
          <box size="0.006000 0.006000 0.003200" />
        </geometry>
     </collision>
     <collision>
        <origin xyz="-0.000050 -0.021450 -0.018000" rpy="1.57079633 0.00000000 -3.14159265"/>
        <geometry>
          <box size="0.011600 0.011600 0.001200" />
        </geometry>
     </collision>
     <collision>
        <origin xyz="-0.007250 -0.035250 -0.018000" rpy="1.57079633 0.00000000 -3.14159265"/>
        <geometry>
          <box size="0.032400 0.026000 0.026400" />
        </geometry>
     </collision>
     <collision>
        <origin xyz="-0.000050 -0.048850 -0.018000" rpy="1.57079633 0.00000000 -3.14159265"/>
        <geometry>
          <box size="0.012400 0.012400 0.000800" />
        </geometry>
     </collision>
     <collision>
        <origin xyz="0.000150 -0.050050 -0.018000" rpy="1.57079633 0.00000000 -3.14159265"/>
        <geometry>
          <box size="0.005600 0.006000 0.001600" />
        </geometry>
     </collision>
  </link>
  <xacro:gazebo_link_reference link_name="LINK4" />
  <link name="LINK4">
     <inertial>
        <mass value="0.034087"/>
        <origin rpy="0 0 0" xyz="0.02407 -0.007645 0.017"/>
        <inertia ixx="2.922703e-05" ixy="1.154370e-06" ixz="7.844392e-21" iyy="2.289952e-05" iyz="5.439915e-20" izz="1.170413e-05"/>
     </inertial>
     <visual>
        <origin xyz="0.025000 -0.000000 0.004000" rpy="-1.25137173 1.57079633 1.89022092"/>
        <geometry>
        <mesh filename="package://robot_assembler/meshes/mesh_UPPER-ARM28.dae" scale="1.000000 1.000000 1.000000"/>
        </geometry>
     </visual>
     <collision>
        <origin xyz="-0.007400 0.000000 0.000850" rpy="-1.25137173 1.57079633 1.89022092"/>
        <geometry>
          <box size="0.004400 0.002800 0.000800" />
        </geometry>
     </collision>
     <collision>
        <origin xyz="-0.006000 0.000000 0.000850" rpy="-1.25137173 1.57079633 1.89022092"/>
        <geometry>
          <box size="0.004400 0.008400 0.002000" />
        </geometry>
     </collision>
     <collision>
        <origin xyz="0.009400 -0.000000 0.000850" rpy="-1.25137173 1.57079633 1.89022092"/>
        <geometry>
          <box size="0.004400 0.012400 0.028800" />
        </geometry>
     </collision>
     <collision>
        <origin xyz="0.026000 -0.000000 0.001250" rpy="-1.25137173 1.57079633 1.89022092"/>
        <geometry>
          <box size="0.005200 0.016400 0.004400" />
        </geometry>
     </collision>
     <visual>
        <origin xyz="0.025000 -0.000000 0.017000" rpy="1.65329638 -1.57079633 -1.65329638"/>
        <geometry>
        <mesh filename="package://robot_assembler/meshes/mesh_JOINT-BASE.dae" scale="1.000000 1.000000 1.000000"/>
        </geometry>
     </visual>
     <collision>
        <origin xyz="0.025000 -0.000000 0.017000" rpy="1.65329638 -1.57079633 -1.65329638"/>
        <geometry>
          <box size="0.026800 0.026800 0.006000" />
        </geometry>
     </collision>
     <visual>
        <origin xyz="0.031000 -0.000000 0.017000" rpy="-1.57079633 0.00000000 3.14159265"/>
        <geometry>
        <mesh filename="package://robot_assembler/meshes/mesh_SOLE.dae" scale="1.000000 1.000000 1.000000"/>
        </geometry>
     </visual>
     <collision>
        <origin xyz="0.028500 -0.011800 0.017000" rpy="-1.57079633 0.00000000 3.14159265"/>
        <geometry>
          <box size="0.005200 0.100400 0.064000" />
        </geometry>
     </collision>
     <visual>
        <origin xyz="0.025000 -0.000000 0.030000" rpy="1.65329638 -1.57079633 -1.65329638"/>
        <geometry>
        <mesh filename="package://robot_assembler/meshes/mesh_BOTTOM-ARM28.dae" scale="1.000000 1.000000 1.000000"/>
        </geometry>
     </visual>
     <collision>
        <origin xyz="-0.007400 -0.000000 0.033150" rpy="1.65329638 -1.57079633 -1.65329638"/>
        <geometry>
          <box size="0.004400 0.002800 0.000800" />
        </geometry>
     </collision>
     <collision>
        <origin xyz="-0.006000 -0.000000 0.033150" rpy="1.65329638 -1.57079633 -1.65329638"/>
        <geometry>
          <box size="0.004400 0.008400 0.002000" />
        </geometry>
     </collision>
     <collision>
        <origin xyz="0.009400 -0.000000 0.032750" rpy="1.65329638 -1.57079633 -1.65329638"/>
        <geometry>
          <box size="0.005200 0.012400 0.028800" />
        </geometry>
     </collision>
     <collision>
        <origin xyz="0.026000 -0.000000 0.032750" rpy="1.65329638 -1.57079633 -1.65329638"/>
        <geometry>
          <box size="0.005200 0.016400 0.004400" />
        </geometry>
     </collision>
  </link>
  <xacro:gazebo_transmission joint_name="rleg-crotch-r" />
  <joint name="rleg-crotch-r" type="revolute">
     <parent link="BASE"/>
     <child link="LINK0"/>
     <origin xyz="-0.017000 0.000000 0.025000" rpy="3.14159265 1.57079633 3.14159265"/>
     <axis xyz=" 0  0  1"/>
     <limit lower="-4.71239000" upper="4.71239000" velocity="40.00" effort="200.00" />
  </joint>
  <xacro:gazebo_transmission joint_name="rleg-crotch-p" />
  <joint name="rleg-crotch-p" type="revolute">
     <parent link="LINK0"/>
     <child link="LINK1"/>
     <origin xyz="0.000000 -0.018000 0.017000" rpy="1.57079633 0.00000000 0.00000000"/>
     <axis xyz=" 0  0  1"/>
     <limit lower="-4.71239000" upper="4.71239000" velocity="40.00" effort="200.00" />
  </joint>
  <xacro:gazebo_transmission joint_name="rleg-knee-p" />
  <joint name="rleg-knee-p" type="revolute">
     <parent link="LINK1"/>
     <child link="LINK2"/>
     <origin xyz="-0.058000 -0.000000 -0.000000" rpy="-0.00000000 -0.00000000 0.00000000"/>
     <axis xyz=" 0  0  1"/>
     <limit lower="-4.71239000" upper="4.71239000" velocity="40.00" effort="200.00" />
  </joint>
  <xacro:gazebo_transmission joint_name="rleg-ankle-p" />
  <joint name="rleg-ankle-p" type="revolute">
     <parent link="LINK2"/>
     <child link="LINK3"/>
     <origin xyz="-0.023500 -0.053000 -0.035500" rpy="-3.14159265 0.00000000 -1.57079633"/>
     <axis xyz=" 0  0  1"/>
     <limit lower="-4.71239000" upper="4.71239000" velocity="40.00" effort="200.00" />
  </joint>
  <xacro:gazebo_transmission joint_name="rleg-ankle-r" />
  <joint name="rleg-ankle-r" type="revolute">
     <parent link="LINK3"/>
     <child link="LINK4"/>
     <origin xyz="0.000000 -0.017000 -0.018000" rpy="-1.57079633 -0.00000000 0.00000000"/>
     <axis xyz=" 0  0  1"/>
     <limit lower="-4.71239000" upper="4.71239000" velocity="40.00" effort="200.00" />
  </joint>

  <!-- Gazebo plugin for ROS Control -->
  <gazebo>
    <plugin name="gazebo_ros_control" filename="libgazebo_ros_control.so">
      <!--robotNamespace>/</robotNamespace-->
      <legacyModeNS>false</legacyModeNS>
      <robotSimType>gazebo_ros_control/DefaultRobotHWSim</robotSimType>
    </plugin>
  </gazebo>
</robot>
