<?xml version="1.0" ?>
<!-- This file was generated by robot assembler -->
<robot name="torso"
       xmlns:xi="http://www.w3.org/2001/XInclude"
       xmlns:gazebo="http://playerstage.sourceforge.net/gazebo/xmlschema/#gz"
       xmlns:model="http://playerstage.sourceforge.net/gazebo/xmlschema/#model"
       xmlns:sensor="http://playerstage.sourceforge.net/gazebo/xmlschema/#sensor"
       xmlns:body="http://playerstage.sourceforge.net/gazebo/xmlschema/#body"
       xmlns:geom="http://playerstage.sourceforge.net/gazebo/xmlschema/#geom"
       xmlns:joint="http://playerstage.sourceforge.net/gazebo/xmlschema/#joint"
       xmlns:interface="http://playerstage.sourceforge.net/gazebo/xmlschema/#interface"
       xmlns:rendering="http://playerstage.sourceforge.net/gazebo/xmlschema/#rendering"
       xmlns:renderable="http://playerstage.sourceforge.net/gazebo/xmlschema/#renderable"
       xmlns:controller="http://playerstage.sourceforge.net/gazebo/xmlschema/#controller"
       xmlns:physics="http://playerstage.sourceforge.net/gazebo/xmlschema/#physics"
       xmlns:xacro="http://www.ros.org/wiki/xacro">
  <xacro:macro name="gazebo_link_reference" params="link_name mu1:=0.9 mu2:=0.9" >
    <gazebo reference="${link_name}">
      <mu1>${mu1}</mu1>
      <mu2>${mu2}</mu2>
    </gazebo>
  </xacro:macro>
  <xacro:macro name="gazebo_transmission" params="joint_name" >
    <transmission name="${joint_name}_trans">
      <type>transmission_interface/SimpleTransmission</type>
      <joint name="${joint_name}">
        <hardwareInterface>hardware_interface/VelocityJointInterface</hardwareInterface>
        <!--hardwareInterface>hardware_interface/EffortJointInterface</hardwareInterface-->
      </joint>
      <actuator name="${joint_name}_motor">
        <hardwareInterface>hardware_interface/VelocityJointInterface</hardwareInterface>
        <!--hardwareInterface>hardware_interface/EffortJointInterface</hardwareInterface-->
        <mechanicalReduction>1</mechanicalReduction>
      </actuator>
    </transmission>
  </xacro:macro>

  <xacro:macro name="no_gazebo_transmission" params="joint_name" >
    <!-- dummy for fixed joint -->
  </xacro:macro>
  <xacro:gazebo_link_reference link_name="BASE" />
  <link name="BASE">
     <inertial>
        <mass value="0.964506"/>
        <origin rpy="0 0 0" xyz="1.408758e-16 -0.048903 0.037378"/>
        <inertia ixx="0.005057" ixy="6.075900e-05" ixz="1.978200e-05" iyy="0.003772" iyz="1.009086e-05" izz="0.005278"/>
     </inertial>
     <visual>
        <origin xyz="0.000000 0.000000 0.000000" rpy="0.00000000 -0.00000000 0.00000000"/>
        <geometry>
        <mesh filename="package://robot_assembler/meshes/mesh_BATTERY-LEG-PLATE.dae" scale="1.000000 1.000000 1.000000"/>
        </geometry>
     </visual>
     <collision>
        <origin xyz="0.000000 0.000000 -0.001800" rpy="0.00000000 -0.00000000 0.00000000"/>
        <geometry>
          <box size="0.078000 0.045200 0.004000" />
        </geometry>
     </collision>
     <collision>
        <origin xyz="0.000000 0.000000 -0.004400" rpy="0.00000000 -0.00000000 0.00000000"/>
        <geometry>
          <box size="0.078000 0.042800 0.001200" />
        </geometry>
     </collision>
     <collision>
        <origin xyz="0.000000 0.000000 -0.005600" rpy="0.00000000 -0.00000000 0.00000000"/>
        <geometry>
          <box size="0.078000 0.040400 0.001200" />
        </geometry>
     </collision>
     <collision>
        <origin xyz="0.000000 0.000000 -0.006800" rpy="0.00000000 -0.00000000 0.00000000"/>
        <geometry>
          <box size="0.078000 0.038000 0.001200" />
        </geometry>
     </collision>
     <collision>
        <origin xyz="0.000000 0.000000 -0.007800" rpy="0.00000000 -0.00000000 0.00000000"/>
        <geometry>
          <box size="0.078000 0.035600 0.000800" />
        </geometry>
     </collision>
     <visual>
        <origin xyz="0.000000 -0.000000 0.016000" rpy="3.14159265 0.00000000 0.00000000"/>
        <geometry>
        <mesh filename="package://robot_assembler/meshes/mesh_BATTERY-BOX.dae" scale="1.000000 1.000000 1.000000"/>
        </geometry>
     </visual>
     <collision>
        <origin xyz="0.000000 -0.000000 0.016000" rpy="3.14159265 0.00000000 0.00000000"/>
        <geometry>
          <box size="0.078000 0.045200 0.032400" />
        </geometry>
     </collision>
     <visual>
        <origin xyz="-0.000000 0.025500 0.016000" rpy="-0.78539816 1.57079633 -2.35619449"/>
        <geometry>
        <mesh filename="package://robot_assembler/meshes/mesh_BODY-PLATE.dae" scale="1.000000 1.000000 1.000000"/>
        </geometry>
     </visual>
     <collision>
        <origin xyz="0.000000 0.024000 0.045000" rpy="-0.78539816 1.57079633 -2.35619449"/>
        <geometry>
          <box size="0.058000 0.094800 0.002800" />
        </geometry>
     </collision>
     <visual>
        <origin xyz="-0.047500 -0.024500 0.063500" rpy="-3.14159265 0.00000000 0.00000000"/>
        <geometry>
        <mesh filename="package://robot_assembler/meshes/kxr_auv/auv_backpack_mount.STL" scale="0.001000 0.001000 0.001000"/>
        </geometry>
     </visual>
     <collision>
        <origin xyz="-0.047500 -0.024500 0.063500" rpy="-3.14159265 0.00000000 0.00000000"/>
        <geometry>
        <mesh filename="package://robot_assembler/meshes/kxr_auv/auv_backpack_mount.STL" scale="0.001000 0.001000 0.001000"/>
        </geometry>
     </collision>
     <visual>
        <origin xyz="-0.056500 -0.032500 0.098500" rpy="-3.14159265 0.00000000 0.00000000"/>
        <geometry>
        <mesh filename="package://robot_assembler/meshes/kxr_auv/auv_backpack.STL" scale="0.001000 0.001000 0.001000"/>
        </geometry>
     </visual>
     <collision>
        <origin xyz="-0.056500 -0.032500 0.098500" rpy="-3.14159265 0.00000000 0.00000000"/>
        <geometry>
        <mesh filename="package://robot_assembler/meshes/kxr_auv/auv_backpack.STL" scale="0.001000 0.001000 0.001000"/>
        </geometry>
     </collision>
     <visual>
        <origin xyz="0.056500 -0.075500 -0.019500" rpy="0.00000000 -0.00000000 -3.14159265"/>
        <geometry>
        <mesh filename="package://robot_assembler/meshes/kxr_auv/buoyancybody-t35.STL" scale="0.001000 0.001000 0.001000"/>
        </geometry>
     </visual>
     <collision>
        <origin xyz="0.056500 -0.075500 -0.019500" rpy="0.00000000 -0.00000000 -3.14159265"/>
        <geometry>
        <mesh filename="package://robot_assembler/meshes/kxr_auv/buoyancybody-t35.STL" scale="0.001000 0.001000 0.001000"/>
        </geometry>
     </collision>
     <visual>
        <origin xyz="0.000000 -0.025500 0.016000" rpy="1.38080804 1.57079633 2.95160437"/>
        <geometry>
        <mesh filename="package://robot_assembler/meshes/mesh_BODY-PLATE.dae" scale="1.000000 1.000000 1.000000"/>
        </geometry>
     </visual>
     <collision>
        <origin xyz="0.000000 -0.024000 0.045000" rpy="1.48013644 1.57079633 3.05093277"/>
        <geometry>
          <box size="0.058000 0.094800 0.002800" />
        </geometry>
     </collision>
     <visual>
        <origin xyz="-0.033000 -0.019500 0.059500" rpy="1.57079633 -0.00000000 -3.14159265"/>
        <geometry>
        <mesh filename="package://robot_assembler/meshes/mesh_JOINT-BASE.dae" scale="1.000000 1.000000 1.000000"/>
        </geometry>
     </visual>
     <collision>
        <origin xyz="-0.033000 -0.019500 0.059500" rpy="1.57079633 -0.00000000 -3.14159265"/>
        <geometry>
          <box size="0.026800 0.026800 0.006000" />
        </geometry>
     </collision>
     <visual>
        <origin xyz="-0.046500 -0.007250 0.059500" rpy="-1.57079633 0.00000000 -3.14159265"/>
        <geometry>
        <mesh filename="package://robot_assembler/meshes/mesh_ARM-SUPPORTER-A.dae" scale="1.000000 1.000000 1.000000"/>
        </geometry>
     </visual>
     <collision>
        <origin xyz="-0.047650 -0.021200 0.059500" rpy="-1.57079633 0.00000000 -3.14159265"/>
        <geometry>
          <box size="0.002400 0.026000 0.002800" />
        </geometry>
     </collision>
     <collision>
        <origin xyz="-0.048650 -0.006800 0.059500" rpy="-1.57079633 0.00000000 -3.14159265"/>
        <geometry>
          <box size="0.004400 0.026000 0.026000" />
        </geometry>
     </collision>
     <collision>
        <origin xyz="-0.047650 0.014400 0.059500" rpy="-1.57079633 0.00000000 -3.14159265"/>
        <geometry>
          <box size="0.002400 0.026000 0.016400" />
        </geometry>
     </collision>
     <visual>
        <origin xyz="-0.033000 -0.007250 0.059500" rpy="-1.57079633 0.00000000 1.57079633"/>
        <geometry>
        <mesh filename="package://robot_assembler/meshes/mesh_SERVO-S3301.dae" scale="1.000000 1.000000 1.000000"/>
        </geometry>
     </visual>
     <collision>
        <origin xyz="-0.048750 -0.007200 0.059500" rpy="-1.57079633 0.00000000 1.57079633"/>
        <geometry>
          <box size="0.006000 0.006000 0.003200" />
        </geometry>
     </collision>
     <collision>
        <origin xyz="-0.046550 -0.007200 0.059500" rpy="-1.57079633 0.00000000 1.57079633"/>
        <geometry>
          <box size="0.011600 0.011600 0.001200" />
        </geometry>
     </collision>
     <collision>
        <origin xyz="-0.032750 -0.000000 0.059500" rpy="-1.57079633 0.00000000 1.57079633"/>
        <geometry>
          <box size="0.032400 0.026000 0.026400" />
        </geometry>
     </collision>
     <collision>
        <origin xyz="-0.019150 -0.007200 0.059500" rpy="-1.57079633 0.00000000 1.57079633"/>
        <geometry>
          <box size="0.012400 0.012400 0.000800" />
        </geometry>
     </collision>
     <collision>
        <origin xyz="-0.017950 -0.007400 0.059500" rpy="-1.57079633 0.00000000 1.57079633"/>
        <geometry>
          <box size="0.005600 0.006000 0.001600" />
        </geometry>
     </collision>
     <visual>
        <origin xyz="-0.033000 0.019500 0.059500" rpy="-2.65469342 1.57079633 -1.08389709"/>
        <geometry>
        <mesh filename="package://robot_assembler/meshes/mesh_JOINT-BASE.dae" scale="1.000000 1.000000 1.000000"/>
        </geometry>
     </visual>
     <collision>
        <origin xyz="-0.033000 0.019500 0.059500" rpy="-2.61918922 1.57079633 -1.04839290"/>
        <geometry>
          <box size="0.026800 0.026800 0.006000" />
        </geometry>
     </collision>
     <visual>
        <origin xyz="0.033000 -0.019500 0.059500" rpy="1.57079633 -0.00000000 -3.14159265"/>
        <geometry>
        <mesh filename="package://robot_assembler/meshes/mesh_JOINT-BASE.dae" scale="1.000000 1.000000 1.000000"/>
        </geometry>
     </visual>
     <collision>
        <origin xyz="0.033000 -0.019500 0.059500" rpy="1.57079633 -0.00000000 -3.14159265"/>
        <geometry>
          <box size="0.026800 0.026800 0.006000" />
        </geometry>
     </collision>
     <visual>
        <origin xyz="0.046500 -0.007250 0.059500" rpy="1.57079633 0.00000000 0.00000000"/>
        <geometry>
        <mesh filename="package://robot_assembler/meshes/mesh_ARM-SUPPORTER-A.dae" scale="1.000000 1.000000 1.000000"/>
        </geometry>
     </visual>
     <collision>
        <origin xyz="0.047650 -0.021200 0.059500" rpy="1.57079633 0.00000000 0.00000000"/>
        <geometry>
          <box size="0.002400 0.026000 0.002800" />
        </geometry>
     </collision>
     <collision>
        <origin xyz="0.048650 -0.006800 0.059500" rpy="1.57079633 0.00000000 0.00000000"/>
        <geometry>
          <box size="0.004400 0.026000 0.026000" />
        </geometry>
     </collision>
     <collision>
        <origin xyz="0.047650 0.014400 0.059500" rpy="1.57079633 0.00000000 0.00000000"/>
        <geometry>
          <box size="0.002400 0.026000 0.016400" />
        </geometry>
     </collision>
     <visual>
        <origin xyz="0.033000 -0.007250 0.059500" rpy="1.57079633 -0.00000000 1.57079633"/>
        <geometry>
        <mesh filename="package://robot_assembler/meshes/mesh_SERVO-S3301.dae" scale="1.000000 1.000000 1.000000"/>
        </geometry>
     </visual>
     <collision>
        <origin xyz="0.048750 -0.007200 0.059500" rpy="1.57079633 -0.00000000 1.57079633"/>
        <geometry>
          <box size="0.006000 0.006000 0.003200" />
        </geometry>
     </collision>
     <collision>
        <origin xyz="0.046550 -0.007200 0.059500" rpy="1.57079633 -0.00000000 1.57079633"/>
        <geometry>
          <box size="0.011600 0.011600 0.001200" />
        </geometry>
     </collision>
     <collision>
        <origin xyz="0.032750 0.000000 0.059500" rpy="1.57079633 -0.00000000 1.57079633"/>
        <geometry>
          <box size="0.032400 0.026000 0.026400" />
        </geometry>
     </collision>
     <collision>
        <origin xyz="0.019150 -0.007200 0.059500" rpy="1.57079633 -0.00000000 1.57079633"/>
        <geometry>
          <box size="0.012400 0.012400 0.000800" />
        </geometry>
     </collision>
     <collision>
        <origin xyz="0.017950 -0.007400 0.059500" rpy="1.57079633 -0.00000000 1.57079633"/>
        <geometry>
          <box size="0.005600 0.006000 0.001600" />
        </geometry>
     </collision>
     <visual>
        <origin xyz="0.033000 0.019500 0.059500" rpy="1.57079633 -0.00000000 0.00000000"/>
        <geometry>
        <mesh filename="package://robot_assembler/meshes/mesh_JOINT-BASE.dae" scale="1.000000 1.000000 1.000000"/>
        </geometry>
     </visual>
     <collision>
        <origin xyz="0.033000 0.019500 0.059500" rpy="1.57079633 -0.00000000 0.00000000"/>
        <geometry>
          <box size="0.026800 0.026800 0.006000" />
        </geometry>
     </collision>
     <visual>
        <origin xyz="0.000000 -0.019500 0.059500" rpy="1.57079633 -0.00000000 -3.14159265"/>
        <geometry>
        <mesh filename="package://robot_assembler/meshes/mesh_JOINT-BASE.dae" scale="1.000000 1.000000 1.000000"/>
        </geometry>
     </visual>
     <collision>
        <origin xyz="0.000000 -0.019500 0.059500" rpy="1.57079633 -0.00000000 -3.14159265"/>
        <geometry>
          <box size="0.026800 0.026800 0.006000" />
        </geometry>
     </collision>
     <visual>
        <origin xyz="0.000000 -0.007250 0.073000" rpy="0.98279372 -1.57079633 0.58800260"/>
        <geometry>
        <mesh filename="package://robot_assembler/meshes/mesh_ARM-SUPPORTER-A.dae" scale="1.000000 1.000000 1.000000"/>
        </geometry>
     </visual>
     <collision>
        <origin xyz="0.000000 -0.021200 0.074150" rpy="0.98279372 -1.57079633 0.58800260"/>
        <geometry>
          <box size="0.002400 0.026000 0.002800" />
        </geometry>
     </collision>
     <collision>
        <origin xyz="0.000000 -0.006800 0.075150" rpy="0.98279372 -1.57079633 0.58800260"/>
        <geometry>
          <box size="0.004400 0.026000 0.026000" />
        </geometry>
     </collision>
     <collision>
        <origin xyz="-0.000000 0.014400 0.074150" rpy="0.98279372 -1.57079633 0.58800260"/>
        <geometry>
          <box size="0.002400 0.026000 0.016400" />
        </geometry>
     </collision>
     <visual>
        <origin xyz="0.000000 -0.007250 0.059500" rpy="0.00000000 -0.00000000 1.57079633"/>
        <geometry>
        <mesh filename="package://robot_assembler/meshes/mesh_SERVO-S3301.dae" scale="1.000000 1.000000 1.000000"/>
        </geometry>
     </visual>
     <collision>
        <origin xyz="0.000000 -0.007200 0.075250" rpy="0.00000000 -0.00000000 1.57079633"/>
        <geometry>
          <box size="0.006000 0.006000 0.003200" />
        </geometry>
     </collision>
     <collision>
        <origin xyz="0.000000 -0.007200 0.073050" rpy="0.00000000 -0.00000000 1.57079633"/>
        <geometry>
          <box size="0.011600 0.011600 0.001200" />
        </geometry>
     </collision>
     <collision>
        <origin xyz="-0.000000 -0.000000 0.059250" rpy="0.00000000 -0.00000000 1.57079633"/>
        <geometry>
          <box size="0.032400 0.026000 0.026400" />
        </geometry>
     </collision>
     <collision>
        <origin xyz="0.000000 -0.007200 0.045650" rpy="0.00000000 -0.00000000 1.57079633"/>
        <geometry>
          <box size="0.012400 0.012400 0.000800" />
        </geometry>
     </collision>
     <collision>
        <origin xyz="0.000000 -0.007400 0.044450" rpy="0.00000000 -0.00000000 1.57079633"/>
        <geometry>
          <box size="0.005600 0.006000 0.001600" />
        </geometry>
     </collision>
     <visual>
        <origin xyz="-0.000000 0.019500 0.059500" rpy="1.57079633 -0.00000000 -3.14159265"/>
        <geometry>
        <mesh filename="package://robot_assembler/meshes/mesh_JOINT-BASE.dae" scale="1.000000 1.000000 1.000000"/>
        </geometry>
     </visual>
     <collision>
        <origin xyz="-0.000000 0.019500 0.059500" rpy="1.57079633 -0.00000000 -3.14159265"/>
        <geometry>
          <box size="0.026800 0.026800 0.006000" />
        </geometry>
     </collision>
  </link>
  <xacro:gazebo_link_reference link_name="LINK0" />
  <link name="LINK0">
     <inertial>
        <mass value="0.00857"/>
        <origin rpy="0 0 0" xyz="-2.776153e-18 -0.00621 0.00802"/>
        <inertia ixx="1.573826e-06" ixy="-4.180784e-22" ixz="5.178423e-22" iyy="1.129679e-06" iyz="4.513017e-07" izz="1.219024e-06"/>
     </inertial>
     <visual>
        <origin xyz="0.000000 0.000000 0.002500" rpy="0.00000000 -0.00000000 0.00000000"/>
        <geometry>
        <mesh filename="package://robot_assembler/meshes/mesh_JOINT-BASE.dae" scale="1.000000 1.000000 1.000000"/>
        </geometry>
     </visual>
     <collision>
        <origin xyz="0.000000 0.000000 0.002500" rpy="0.00000000 -0.00000000 0.00000000"/>
        <geometry>
          <box size="0.026800 0.026800 0.006000" />
        </geometry>
     </collision>
     <visual>
        <origin xyz="-0.000000 -0.013000 0.002500" rpy="0.00000000 -0.00000000 -1.57079633"/>
        <geometry>
        <mesh filename="package://robot_assembler/meshes/mesh_BOTTOM-ARM26.dae" scale="1.000000 1.000000 1.000000"/>
        </geometry>
     </visual>
     <collision>
        <origin xyz="-0.000000 -0.016150 0.033100" rpy="0.00000000 -0.00000000 -1.57079633"/>
        <geometry>
          <box size="0.004400 0.001200 0.000800" />
        </geometry>
     </collision>
     <collision>
        <origin xyz="-0.000000 -0.016150 0.031700" rpy="0.00000000 -0.00000000 -1.57079633"/>
        <geometry>
          <box size="0.004400 0.007600 0.002000" />
        </geometry>
     </collision>
     <collision>
        <origin xyz="-0.000000 -0.015750 0.018700" rpy="0.00000000 -0.00000000 -1.57079633"/>
        <geometry>
          <box size="0.005200 0.011600 0.024000" />
        </geometry>
     </collision>
     <collision>
        <origin xyz="0.000000 -0.016150 0.003100" rpy="0.00000000 -0.00000000 -1.57079633"/>
        <geometry>
          <box size="0.004400 0.015600 0.007200" />
        </geometry>
     </collision>
  </link>
  <xacro:gazebo_link_reference link_name="LINK1" />
  <link name="LINK1">
     <inertial>
        <mass value="0.00857"/>
        <origin rpy="0 0 0" xyz="-2.425960e-18 -0.00621 0.00802"/>
        <inertia ixx="1.573826e-06" ixy="-4.141482e-22" ixz="4.685941e-22" iyy="1.129679e-06" iyz="4.513017e-07" izz="1.219024e-06"/>
     </inertial>
     <visual>
        <origin xyz="0.000000 0.000000 0.002500" rpy="0.00000000 -0.00000000 0.00000000"/>
        <geometry>
        <mesh filename="package://robot_assembler/meshes/mesh_JOINT-BASE.dae" scale="1.000000 1.000000 1.000000"/>
        </geometry>
     </visual>
     <collision>
        <origin xyz="0.000000 0.000000 0.002500" rpy="0.00000000 -0.00000000 0.00000000"/>
        <geometry>
          <box size="0.026800 0.026800 0.006000" />
        </geometry>
     </collision>
     <visual>
        <origin xyz="0.000000 -0.013000 0.002500" rpy="0.00000000 -0.00000000 -1.57079633"/>
        <geometry>
        <mesh filename="package://robot_assembler/meshes/mesh_BOTTOM-ARM26.dae" scale="1.000000 1.000000 1.000000"/>
        </geometry>
     </visual>
     <collision>
        <origin xyz="-0.000000 -0.016150 0.033100" rpy="0.00000000 -0.00000000 -1.57079633"/>
        <geometry>
          <box size="0.004400 0.001200 0.000800" />
        </geometry>
     </collision>
     <collision>
        <origin xyz="-0.000000 -0.016150 0.031700" rpy="0.00000000 -0.00000000 -1.57079633"/>
        <geometry>
          <box size="0.004400 0.007600 0.002000" />
        </geometry>
     </collision>
     <collision>
        <origin xyz="-0.000000 -0.015750 0.018700" rpy="0.00000000 -0.00000000 -1.57079633"/>
        <geometry>
          <box size="0.005200 0.011600 0.024000" />
        </geometry>
     </collision>
     <collision>
        <origin xyz="0.000000 -0.016150 0.003100" rpy="0.00000000 -0.00000000 -1.57079633"/>
        <geometry>
          <box size="0.004400 0.015600 0.007200" />
        </geometry>
     </collision>
  </link>
  <xacro:gazebo_link_reference link_name="LINK2" />
  <link name="LINK2">
     <inertial>
        <mass value="0.03619"/>
        <origin rpy="0 0 0" xyz="-0.008327 1.899696e-06 0.02502"/>
        <inertia ixx="0.001007" ixy="-2.115259e-10" ixz="1.650472e-06" iyy="0.001007" iyz="1.204493e-09" izz="0.001003"/>
     </inertial>
     <visual>
        <origin xyz="0.000000 0.000000 0.002500" rpy="0.00000000 -0.00000000 0.00000000"/>
        <geometry>
        <mesh filename="package://robot_assembler/meshes/mesh_JOINT-BASE.dae" scale="1.000000 1.000000 1.000000"/>
        </geometry>
     </visual>
     <collision>
        <origin xyz="0.000000 0.000000 0.002500" rpy="0.00000000 -0.00000000 0.00000000"/>
        <geometry>
          <box size="0.026800 0.026800 0.006000" />
        </geometry>
     </collision>
     <visual>
        <origin xyz="-0.000000 -0.013000 0.002500" rpy="1.57079633 -0.00000000 -1.57079633"/>
        <geometry>
        <mesh filename="package://robot_assembler/meshes/mesh_JOINT-FRAME-B-A.dae" scale="1.000000 1.000000 1.000000"/>
        </geometry>
     </visual>
     <collision>
        <origin xyz="-0.022250 -0.013350 0.011100" rpy="1.57079633 -0.00000000 -1.57079633"/>
        <geometry>
          <box size="0.002000 0.003600 0.002400" />
        </geometry>
     </collision>
     <collision>
        <origin xyz="-0.019250 -0.013350 0.011700" rpy="1.57079633 -0.00000000 -1.57079633"/>
        <geometry>
          <box size="0.002000 0.007200 0.003600" />
        </geometry>
     </collision>
     <collision>
        <origin xyz="-0.015250 -0.013750 0.010300" rpy="1.57079633 -0.00000000 -1.57079633"/>
        <geometry>
          <box size="0.002800 0.010000 0.004400" />
        </geometry>
     </collision>
     <collision>
        <origin xyz="-0.002650 -0.013750 0.007300" rpy="1.57079633 -0.00000000 -1.57079633"/>
        <geometry>
          <box size="0.002800 0.016000 0.020800" />
        </geometry>
     </collision>
     <collision>
        <origin xyz="0.010350 -0.013750 0.005900" rpy="1.57079633 -0.00000000 -1.57079633"/>
        <geometry>
          <box size="0.002800 0.012400 0.005200" />
        </geometry>
     </collision>
     <visual>
        <origin xyz="-0.010500 0.000000 0.032500" rpy="1.10714872 1.57079633 -0.46364761"/>
        <geometry>
        <mesh filename="package://robot_assembler/meshes/mesh_SERVO-S3301.dae" scale="1.000000 1.000000 1.000000"/>
        </geometry>
     </visual>
     <collision>
        <origin xyz="-0.010500 -0.015750 0.032450" rpy="0.46364761 1.57079633 -1.10714872"/>
        <geometry>
          <box size="0.006000 0.006000 0.003200" />
        </geometry>
     </collision>
     <collision>
        <origin xyz="-0.010500 -0.013550 0.032450" rpy="0.46364761 1.57079633 -1.10714872"/>
        <geometry>
          <box size="0.011600 0.011600 0.001200" />
        </geometry>
     </collision>
     <collision>
        <origin xyz="-0.010500 0.000250 0.025250" rpy="0.46364761 1.57079633 -1.10714872"/>
        <geometry>
          <box size="0.032400 0.026000 0.026400" />
        </geometry>
     </collision>
     <collision>
        <origin xyz="-0.010500 0.013850 0.032450" rpy="0.46364761 1.57079633 -1.10714872"/>
        <geometry>
          <box size="0.012400 0.012400 0.000800" />
        </geometry>
     </collision>
     <collision>
        <origin xyz="-0.010500 0.015050 0.032650" rpy="0.46364761 1.57079633 -1.10714872"/>
        <geometry>
          <box size="0.005600 0.006000 0.001600" />
        </geometry>
     </collision>
     <visual>
        <origin xyz="0.000000 0.013000 0.002500" rpy="1.57079633 -0.00000000 1.57079633"/>
        <geometry>
        <mesh filename="package://robot_assembler/meshes/mesh_JOINT-FRAME-B-B.dae" scale="1.000000 1.000000 1.000000"/>
        </geometry>
     </visual>
     <collision>
        <origin xyz="0.010150 0.013750 0.004100" rpy="1.57079633 -0.00000000 1.57079633"/>
        <geometry>
          <box size="0.002800 0.008800 0.005600" />
        </geometry>
     </collision>
     <collision>
        <origin xyz="-0.003050 0.013750 0.005900" rpy="1.57079633 -0.00000000 1.57079633"/>
        <geometry>
          <box size="0.002800 0.013200 0.020800" />
        </geometry>
     </collision>
     <collision>
        <origin xyz="-0.016250 0.013750 0.009300" rpy="1.57079633 -0.00000000 1.57079633"/>
        <geometry>
          <box size="0.002800 0.012800 0.005600" />
        </geometry>
     </collision>
     <collision>
        <origin xyz="-0.021050 0.013550 0.010900" rpy="1.57079633 -0.00000000 1.57079633"/>
        <geometry>
          <box size="0.002400 0.008800 0.004000" />
        </geometry>
     </collision>
     <collision>
        <origin xyz="-0.023250 0.013350 0.011500" rpy="1.57079633 -0.00000000 1.57079633"/>
        <geometry>
          <box size="0.002000 0.004400 0.000400" />
        </geometry>
     </collision>
  </link>
  <xacro:gazebo_link_reference link_name="LINK3" />
  <link name="LINK3">
     <inertial>
        <mass value="0.325949"/>
        <origin rpy="0 0 0" xyz="0.01404 0.026492 -0.049483"/>
        <inertia ixx="0.000197" ixy="3.425134e-07" ixz="-4.135071e-07" iyy="0.000306" iyz="1.050951e-05" izz="0.000162"/>
     </inertial>
     <visual>
        <origin xyz="0.023000 0.000000 -0.004500" rpy="0.00000000 -1.57079633 -0.00000000"/>
        <geometry>
        <mesh filename="package://robot_assembler/meshes/mesh_UPPER-ARM26.dae" scale="1.000000 1.000000 1.000000"/>
        </geometry>
     </visual>
     <collision>
        <origin xyz="-0.007600 -0.000000 -0.001350" rpy="0.00000000 -1.57079633 -0.00000000"/>
        <geometry>
          <box size="0.004400 0.001200 0.000800" />
        </geometry>
     </collision>
     <collision>
        <origin xyz="-0.006000 -0.000000 -0.001350" rpy="0.00000000 -1.57079633 -0.00000000"/>
        <geometry>
          <box size="0.004400 0.007600 0.002400" />
        </geometry>
     </collision>
     <collision>
        <origin xyz="0.008800 -0.000000 -0.001350" rpy="0.00000000 -1.57079633 -0.00000000"/>
        <geometry>
          <box size="0.004400 0.012400 0.027200" />
        </geometry>
     </collision>
     <collision>
        <origin xyz="0.024200 -0.000000 -0.001750" rpy="0.00000000 -1.57079633 -0.00000000"/>
        <geometry>
          <box size="0.005200 0.016400 0.003600" />
        </geometry>
     </collision>
     <visual>
        <origin xyz="0.023000 0.000000 -0.017500" rpy="-0.76887886 1.57079633 2.37271379"/>
        <geometry>
        <mesh filename="package://robot_assembler/meshes/mesh_JOINT-BASE.dae" scale="1.000000 1.000000 1.000000"/>
        </geometry>
     </visual>
     <collision>
        <origin xyz="0.023000 0.000000 -0.017500" rpy="-0.76887886 1.57079633 2.37271379"/>
        <geometry>
          <box size="0.026800 0.026800 0.006000" />
        </geometry>
     </collision>
     <visual>
        <origin xyz="0.066000 -0.024500 -0.070200" rpy="1.57079633 -0.00000000 -3.14159265"/>
        <geometry>
        <mesh filename="package://robot_assembler/meshes/kxr_auv/M5_camera_head.STL" scale="0.001000 0.001000 0.001000"/>
        </geometry>
     </visual>
     <collision>
        <origin xyz="0.066000 -0.024500 -0.070200" rpy="1.57079633 -0.00000000 -3.14159265"/>
        <geometry>
        <mesh filename="package://robot_assembler/meshes/kxr_auv/M5_camera_head.STL" scale="0.001000 0.001000 0.001000"/>
        </geometry>
     </collision>
     <visual>
        <origin xyz="0.023000 0.000000 -0.030500" rpy="-0.76887886 1.57079633 2.37271379"/>
        <geometry>
        <mesh filename="package://robot_assembler/meshes/mesh_BOTTOM-ARM26.dae" scale="1.000000 1.000000 1.000000"/>
        </geometry>
     </visual>
     <collision>
        <origin xyz="-0.007600 0.000000 -0.033650" rpy="-0.76887886 1.57079633 2.37271379"/>
        <geometry>
          <box size="0.004400 0.001200 0.000800" />
        </geometry>
     </collision>
     <collision>
        <origin xyz="-0.006200 0.000000 -0.033650" rpy="-0.76887886 1.57079633 2.37271379"/>
        <geometry>
          <box size="0.004400 0.007600 0.002000" />
        </geometry>
     </collision>
     <collision>
        <origin xyz="0.006800 0.000000 -0.033250" rpy="-0.76887886 1.57079633 2.37271379"/>
        <geometry>
          <box size="0.005200 0.011600 0.024000" />
        </geometry>
     </collision>
     <collision>
        <origin xyz="0.022400 0.000000 -0.033650" rpy="-0.76887886 1.57079633 2.37271379"/>
        <geometry>
          <box size="0.004400 0.015600 0.007200" />
        </geometry>
     </collision>
  </link>
  <xacro:gazebo_transmission joint_name="larm-shoulder-p" />
  <joint name="larm-shoulder-p" type="revolute">
     <parent link="BASE"/>
     <child link="LINK0"/>
     <origin xyz="-0.051000 -0.007250 0.059500" rpy="1.57079633 -0.00000000 -1.57079633"/>
     <axis xyz=" 0  0  1"/>
     <limit lower="-4.71239000" upper="4.71239000" velocity="40.00" effort="200.00" />
  </joint>
  <xacro:gazebo_transmission joint_name="rarm-shoulder-p" />
  <joint name="rarm-shoulder-p" type="revolute">
     <parent link="BASE"/>
     <child link="LINK1"/>
     <origin xyz="0.051000 -0.007250 0.059500" rpy="-1.57079633 0.00000000 -1.57079633"/>
     <axis xyz=" 0  0  1"/>
     <limit lower="-4.71239000" upper="4.71239000" velocity="40.00" effort="200.00" />
  </joint>
  <xacro:gazebo_transmission joint_name="head-neck-y" />
  <joint name="head-neck-y" type="revolute">
     <parent link="BASE"/>
     <child link="LINK2"/>
     <origin xyz="0.000000 -0.007250 0.077500" rpy="-0.00000000 0.00000000 -1.57079633"/>
     <axis xyz=" 0  0  1"/>
     <limit lower="-4.71239000" upper="4.71239000" velocity="40.00" effort="200.00" />
  </joint>
  <xacro:gazebo_transmission joint_name="head-neck-p" />
  <joint name="head-neck-p" type="revolute">
     <parent link="LINK2"/>
     <child link="LINK3"/>
     <origin xyz="-0.010500 -0.018000 0.032500" rpy="1.42371797 -1.57079633 0.14707836"/>
     <axis xyz=" 0  0  1"/>
     <limit lower="-4.71239000" upper="4.71239000" velocity="40.00" effort="200.00" />
  </joint>

  <!-- Gazebo plugin for ROS Control -->
  <gazebo>
    <plugin name="gazebo_ros_control" filename="libgazebo_ros_control.so">
      <!--robotNamespace>/</robotNamespace-->
      <legacyModeNS>false</legacyModeNS>
      <robotSimType>gazebo_ros_control/DefaultRobotHWSim</robotSimType>
    </plugin>
  </gazebo>
</robot>
