<?xml version="1.0" ?>
<!-- This file was generated by robot assembler -->
<robot name="SAMPLE_HUMANOID"
       xmlns:xi="http://www.w3.org/2001/XInclude"
       xmlns:gazebo="http://playerstage.sourceforge.net/gazebo/xmlschema/#gz"
       xmlns:model="http://playerstage.sourceforge.net/gazebo/xmlschema/#model"
       xmlns:sensor="http://playerstage.sourceforge.net/gazebo/xmlschema/#sensor"
       xmlns:body="http://playerstage.sourceforge.net/gazebo/xmlschema/#body"
       xmlns:geom="http://playerstage.sourceforge.net/gazebo/xmlschema/#geom"
       xmlns:joint="http://playerstage.sourceforge.net/gazebo/xmlschema/#joint"
       xmlns:interface="http://playerstage.sourceforge.net/gazebo/xmlschema/#interface"
       xmlns:rendering="http://playerstage.sourceforge.net/gazebo/xmlschema/#rendering"
       xmlns:renderable="http://playerstage.sourceforge.net/gazebo/xmlschema/#renderable"
       xmlns:controller="http://playerstage.sourceforge.net/gazebo/xmlschema/#controller"
       xmlns:physics="http://playerstage.sourceforge.net/gazebo/xmlschema/#physics"
       xmlns:xacro="http://www.ros.org/wiki/xacro">
  <xacro:macro name="gazebo_link_reference" params="link_name mu1:=0.9 mu2:=0.9" >
    <gazebo reference="${link_name}">
      <mu1>${mu1}</mu1>
      <mu2>${mu2}</mu2>
      <kp>100000.0</kp>
      <kd>40.0</kd>
    </gazebo>
  </xacro:macro>
  <xacro:macro name="gazebo_transmission" params="joint_name" >
    <transmission name="${joint_name}_trans">
      <type>transmission_interface/SimpleTransmission</type>
      <joint name="${joint_name}">
        <hardwareInterface>hardware_interface/VelocityJointInterface</hardwareInterface>
      </joint>
      <actuator name="${joint_name}_motor">
        <hardwareInterface>hardware_interface/VelocityJointInterface</hardwareInterface>
        <mechanicalReduction>1</mechanicalReduction>
      </actuator>
    </transmission>
  </xacro:macro>

  <xacro:gazebo_link_reference link_name="BASE" />
  <link name="BASE">
  <inertial>
     <mass value="0.62"/>
     <origin rpy="0 0 0" xyz="0.000605 3.667317e-18 0.005565"/>
     <inertia ixx="0.001099" ixy="-4.774847e-20" ixz="-8.975806e-06" iyy="0.000621" iyz="2.182787e-19" izz="0.000712"/>
  </inertial>
  <visual>
     <origin xyz="0.000000 0.000000 0.000000" rpy="0.00000000 -0.00000000 0.00000000"/>
     <geometry>
     <mesh filename="package://robot_assembler/meshes/body-parts-a-new.dae" scale="1.000000 1.000000 1.000000"/>
     </geometry>
  </visual>
  <collision>
     <origin xyz="0.000000 0.000000 0.000000" rpy="0.00000000 -0.00000000 0.00000000"/>
     <geometry>
     <mesh filename="package://robot_assembler/meshes/body-parts-a-new.dae" scale="1.000000 1.000000 1.000000"/>
     </geometry>
  </collision>
  <visual>
     <origin xyz="0.015750 -0.000000 0.028000" rpy="0.00000000 0.00000000 -1.57079633"/>
     <geometry>
     <mesh filename="package://robot_assembler/meshes/xm430_dynamixel.dae" scale="1.000000 1.000000 1.000000"/>
     </geometry>
  </visual>
  <collision>
     <origin xyz="0.015750 -0.000000 0.028000" rpy="0.00000000 0.00000000 -1.57079633"/>
     <geometry>
     <mesh filename="package://robot_assembler/meshes/xm430_dynamixel.dae" scale="1.000000 1.000000 1.000000"/>
     </geometry>
  </collision>
  <visual>
     <origin xyz="0.012000 -0.034000 0.030000" rpy="0.78539816 1.57079633 -0.78539816"/>
     <geometry>
     <mesh filename="package://robot_assembler/meshes/xm430_dynamixel.dae" scale="1.000000 1.000000 1.000000"/>
     </geometry>
  </visual>
  <collision>
     <origin xyz="0.012000 -0.034000 0.030000" rpy="0.78539816 1.57079633 -0.78539816"/>
     <geometry>
     <mesh filename="package://robot_assembler/meshes/xm430_dynamixel.dae" scale="1.000000 1.000000 1.000000"/>
     </geometry>
  </collision>
  <visual>
     <origin xyz="0.012000 0.034000 0.030000" rpy="-0.78539816 -1.57079633 -0.78539816"/>
     <geometry>
     <mesh filename="package://robot_assembler/meshes/xm430_dynamixel.dae" scale="1.000000 1.000000 1.000000"/>
     </geometry>
  </visual>
  <collision>
     <origin xyz="0.012000 0.034000 0.030000" rpy="-0.78539816 -1.57079633 -0.78539816"/>
     <geometry>
     <mesh filename="package://robot_assembler/meshes/xm430_dynamixel.dae" scale="1.000000 1.000000 1.000000"/>
     </geometry>
  </collision>
  <visual>
     <origin xyz="0.012000 -0.033000 -0.026000" rpy="3.14159265 0.00000000 1.57079633"/>
     <geometry>
     <mesh filename="package://robot_assembler/meshes/xm430_dynamixel.dae" scale="1.000000 1.000000 1.000000"/>
     </geometry>
  </visual>
  <collision>
     <origin xyz="0.012000 -0.033000 -0.026000" rpy="3.14159265 0.00000000 1.57079633"/>
     <geometry>
     <mesh filename="package://robot_assembler/meshes/xm430_dynamixel.dae" scale="1.000000 1.000000 1.000000"/>
     </geometry>
  </collision>
  <visual>
     <origin xyz="0.012000 0.033000 -0.026000" rpy="3.14159265 0.00000000 1.57079633"/>
     <geometry>
     <mesh filename="package://robot_assembler/meshes/xm430_dynamixel.dae" scale="1.000000 1.000000 1.000000"/>
     </geometry>
  </visual>
  <collision>
     <origin xyz="0.012000 0.033000 -0.026000" rpy="3.14159265 0.00000000 1.57079633"/>
     <geometry>
     <mesh filename="package://robot_assembler/meshes/xm430_dynamixel.dae" scale="1.000000 1.000000 1.000000"/>
     </geometry>
  </collision>
  </link>
  <xacro:gazebo_link_reference link_name="LINK0" />
  <link name="LINK0">
  <inertial>
     <mass value="0.015"/>
     <origin rpy="0 0 0" xyz="-6.895566e-18 1.065814e-17 0.00655"/>
     <inertia ixx="3.159763e-06" ixy="-2.312039e-21" ixz="-5.722317e-23" iyy="1.969763e-06" iyz="1.562855e-21" izz="3.012500e-06"/>
  </inertial>
  <visual>
     <origin xyz="-0.000000 0.000000 0.020000" rpy="-1.57079633 -0.00000000 3.14159265"/>
     <geometry>
     <mesh filename="package://robot_assembler/meshes/fr12_h101s.dae" scale="1.000000 1.000000 1.000000"/>
     </geometry>
  </visual>
  <collision>
     <origin xyz="-0.000000 0.000000 0.020000" rpy="-1.57079633 -0.00000000 3.14159265"/>
     <geometry>
     <mesh filename="package://robot_assembler/meshes/fr12_h101s.dae" scale="1.000000 1.000000 1.000000"/>
     </geometry>
  </collision>
  </link>
  <xacro:gazebo_link_reference link_name="LINK1" />
  <link name="LINK1">
  <inertial>
     <mass value="0.1"/>
     <origin rpy="0 0 0" xyz="1.421085e-17 -0.012 -0.0175"/>
     <inertia ixx="3.202708e-05" ixy="1.249001e-21" ixz="-1.607510e-21" iyy="2.077708e-05" iyz="-4.014434e-36" izz="2.478750e-05"/>
  </inertial>
  <visual>
     <origin xyz="0.000000 -0.000000 -0.019000" rpy="0.00000000 0.00000000 0.00000000"/>
     <geometry>
     <mesh filename="package://robot_assembler/meshes/xm430_dynamixel.dae" scale="1.000000 1.000000 1.000000"/>
     </geometry>
  </visual>
  <collision>
     <origin xyz="0.000000 -0.000000 -0.019000" rpy="0.00000000 0.00000000 0.00000000"/>
     <geometry>
     <mesh filename="package://robot_assembler/meshes/xm430_dynamixel.dae" scale="1.000000 1.000000 1.000000"/>
     </geometry>
  </collision>
  </link>
  <xacro:gazebo_link_reference link_name="LINK2" />
  <link name="LINK2">
  <inertial>
     <mass value="0.016"/>
     <origin rpy="0 0 0" xyz="0.01 -0.004807 0.0148"/>
     <inertia ixx="3.031831e-06" ixy="1.651328e-22" ixz="1.480093e-21" iyy="3.409547e-06" iyz="3.860268e-22" izz="4.104951e-06"/>
  </inertial>
  <visual>
     <origin xyz="0.010000 -0.000000 0.028500" rpy="-1.57079633 0.00000000 1.57079633"/>
     <geometry>
     <mesh filename="package://robot_assembler/meshes/fr12_h102.dae" scale="1.000000 1.000000 1.000000"/>
     </geometry>
  </visual>
  <collision>
     <origin xyz="0.010000 -0.000000 0.028500" rpy="-1.57079633 0.00000000 1.57079633"/>
     <geometry>
     <mesh filename="package://robot_assembler/meshes/fr12_h102.dae" scale="1.000000 1.000000 1.000000"/>
     </geometry>
  </collision>
  </link>
  <xacro:gazebo_link_reference link_name="LINK3" />
  <link name="LINK3">
  <inertial>
     <mass value="0.214"/>
     <origin rpy="0 0 0" xyz="0.000701 -0.037671 -0.018299"/>
     <inertia ixx="0.000193" ixy="3.911916e-06" ixz="1.051402e-07" iyy="4.430571e-05" iyz="-3.850584e-06" izz="0.000192"/>
  </inertial>
  <visual>
     <origin xyz="0.000000 -0.000000 -0.019000" rpy="-0.00000000 0.00000000 -0.00000000"/>
     <geometry>
     <mesh filename="package://robot_assembler/meshes/xm430_dynamixel.dae" scale="1.000000 1.000000 1.000000"/>
     </geometry>
  </visual>
  <collision>
     <origin xyz="0.000000 -0.000000 -0.019000" rpy="-0.00000000 0.00000000 -0.00000000"/>
     <geometry>
     <mesh filename="package://robot_assembler/meshes/xm430_dynamixel.dae" scale="1.000000 1.000000 1.000000"/>
     </geometry>
  </collision>
  <visual>
     <origin xyz="-0.000000 -0.021000 -0.019000" rpy="1.76819189 1.57079633 0.19739556"/>
     <geometry>
     <mesh filename="package://robot_assembler/meshes/fr12_s102.dae" scale="1.000000 1.000000 1.000000"/>
     </geometry>
  </visual>
  <collision>
     <origin xyz="-0.000000 -0.021000 -0.019000" rpy="1.76819189 1.57079633 0.19739556"/>
     <geometry>
     <mesh filename="package://robot_assembler/meshes/fr12_s102.dae" scale="1.000000 1.000000 1.000000"/>
     </geometry>
  </collision>
  <visual>
     <origin xyz="0.000000 -0.075750 -0.019000" rpy="0.66258529 -1.57079633 2.47900737"/>
     <geometry>
     <mesh filename="package://robot_assembler/meshes/xm430_dynamixel.dae" scale="1.000000 1.000000 1.000000"/>
     </geometry>
  </visual>
  <collision>
     <origin xyz="0.000000 -0.075750 -0.019000" rpy="0.66258529 -1.57079633 2.47900737"/>
     <geometry>
     <mesh filename="package://robot_assembler/meshes/xm430_dynamixel.dae" scale="1.000000 1.000000 1.000000"/>
     </geometry>
  </collision>
  </link>
  <xacro:gazebo_link_reference link_name="LINK4" />
  <link name="LINK4">
  <inertial>
     <mass value="0.129"/>
     <origin rpy="0 0 0" xyz="-6.152529e-17 0.049025 -0.017837"/>
     <inertia ixx="6.363671e-05" ixy="9.013241e-20" ixz="1.578896e-20" iyy="2.635199e-05" iyz="-1.121221e-06" izz="5.685405e-05"/>
  </inertial>
  <visual>
     <origin xyz="0.000000 0.000000 -0.019000" rpy="0.16486786 1.57079633 0.16486786"/>
     <geometry>
     <mesh filename="package://robot_assembler/meshes/fr12_h101.dae" scale="1.000000 1.000000 1.000000"/>
     </geometry>
  </visual>
  <collision>
     <origin xyz="0.000000 0.000000 -0.019000" rpy="0.16486786 1.57079633 0.16486786"/>
     <geometry>
     <mesh filename="package://robot_assembler/meshes/fr12_h101.dae" scale="1.000000 1.000000 1.000000"/>
     </geometry>
  </collision>
  <visual>
     <origin xyz="-0.000000 0.047500 -0.019000" rpy="-0.38588267 -1.57079633 1.95667900"/>
     <geometry>
     <mesh filename="package://robot_assembler/meshes/fr12_s102.dae" scale="1.000000 1.000000 1.000000"/>
     </geometry>
  </visual>
  <collision>
     <origin xyz="-0.000000 0.047500 -0.019000" rpy="-0.38588267 -1.57079633 1.95667900"/>
     <geometry>
     <mesh filename="package://robot_assembler/meshes/fr12_s102.dae" scale="1.000000 1.000000 1.000000"/>
     </geometry>
  </collision>
  <visual>
     <origin xyz="-0.000000 0.068500 -0.019000" rpy="-0.00000000 -0.00000000 0.00000000"/>
     <geometry>
     <mesh filename="package://robot_assembler/meshes/xm430_dynamixel.dae" scale="1.000000 1.000000 1.000000"/>
     </geometry>
  </visual>
  <collision>
     <origin xyz="-0.000000 0.068500 -0.019000" rpy="-0.00000000 -0.00000000 0.00000000"/>
     <geometry>
     <mesh filename="package://robot_assembler/meshes/xm430_dynamixel.dae" scale="1.000000 1.000000 1.000000"/>
     </geometry>
  </collision>
  </link>
  <xacro:gazebo_link_reference link_name="LINK5" />
  <link name="LINK5">
  <inertial>
     <mass value="0.145"/>
     <origin rpy="0 0 0" xyz="-0.001034 0.04584 -0.020028"/>
     <inertia ixx="0.0001" ixy="-5.384483e-07" ixz="7.541379e-07" iyy="5.040990e-05" iyz="1.689589e-05" izz="8.917485e-05"/>
  </inertial>
  <visual>
     <origin xyz="0.000000 -0.000000 -0.019000" rpy="-0.10835955 1.57079633 -0.10835955"/>
     <geometry>
     <mesh filename="package://robot_assembler/meshes/fr12_h101.dae" scale="1.000000 1.000000 1.000000"/>
     </geometry>
  </visual>
  <collision>
     <origin xyz="0.000000 -0.000000 -0.019000" rpy="-0.10835955 1.57079633 -0.10835955"/>
     <geometry>
     <mesh filename="package://robot_assembler/meshes/fr12_h101.dae" scale="1.000000 1.000000 1.000000"/>
     </geometry>
  </collision>
  <visual>
     <origin xyz="-0.000000 0.042250 -0.003000" rpy="1.57079633 -0.00000000 -1.57079633"/>
     <geometry>
     <mesh filename="package://robot_assembler/meshes/xm430_dynamixel.dae" scale="1.000000 1.000000 1.000000"/>
     </geometry>
  </visual>
  <collision>
     <origin xyz="-0.000000 0.042250 -0.003000" rpy="1.57079633 -0.00000000 -1.57079633"/>
     <geometry>
     <mesh filename="package://robot_assembler/meshes/xm430_dynamixel.dae" scale="1.000000 1.000000 1.000000"/>
     </geometry>
  </collision>
  <visual>
     <origin xyz="-0.000000 0.042250 -0.024000" rpy="3.14159265 0.00000000 -3.14159265"/>
     <geometry>
     <mesh filename="package://robot_assembler/meshes/fr12_e170.dae" scale="1.000000 1.000000 1.000000"/>
     </geometry>
  </visual>
  <collision>
     <origin xyz="-0.000000 0.042250 -0.024000" rpy="3.14159265 0.00000000 -3.14159265"/>
     <geometry>
     <mesh filename="package://robot_assembler/meshes/fr12_e170.dae" scale="1.000000 1.000000 1.000000"/>
     </geometry>
  </collision>
  </link>
  <xacro:gazebo_link_reference link_name="LINK6" />
  <link name="LINK6">
  <inertial>
     <mass value="0.035"/>
     <origin rpy="0 0 0" xyz="-0.023397 0.018542 -0.019"/>
     <inertia ixx="1.643493e-05" ixy="8.139500e-06" ixz="9.678720e-21" iyy="2.583362e-05" iyz="-2.962638e-21" izz="2.525856e-05"/>
  </inertial>
  <visual>
     <origin xyz="0.000000 0.000000 -0.019000" rpy="0.01512868 -1.57079633 -0.53872745"/>
     <geometry>
     <mesh filename="package://robot_assembler/meshes/fr12_e171.dae" scale="1.000000 1.000000 1.000000"/>
     </geometry>
  </visual>
  <collision>
     <origin xyz="0.000000 0.000000 -0.019000" rpy="0.01512868 -1.57079633 -0.53872745"/>
     <geometry>
     <mesh filename="package://robot_assembler/meshes/fr12_e171.dae" scale="1.000000 1.000000 1.000000"/>
     </geometry>
  </collision>
  </link>
  <xacro:gazebo_link_reference link_name="LINK7" />
  <link name="LINK7">
  <inertial>
     <mass value="0.016"/>
     <origin rpy="0 0 0" xyz="-0.01 0.004807 0.0148"/>
     <inertia ixx="3.031831e-06" ixy="1.037836e-22" ixz="-1.474285e-21" iyy="3.409547e-06" iyz="-1.544107e-22" izz="4.104951e-06"/>
  </inertial>
  <visual>
     <origin xyz="-0.010000 -0.000000 0.028500" rpy="-1.57079633 0.00000000 -1.57079633"/>
     <geometry>
     <mesh filename="package://robot_assembler/meshes/fr12_h102.dae" scale="1.000000 1.000000 1.000000"/>
     </geometry>
  </visual>
  <collision>
     <origin xyz="-0.010000 -0.000000 0.028500" rpy="-1.57079633 0.00000000 -1.57079633"/>
     <geometry>
     <mesh filename="package://robot_assembler/meshes/fr12_h102.dae" scale="1.000000 1.000000 1.000000"/>
     </geometry>
  </collision>
  </link>
  <xacro:gazebo_link_reference link_name="LINK8" />
  <link name="LINK8">
  <inertial>
     <mass value="0.214"/>
     <origin rpy="0 0 0" xyz="0.000701 -0.037671 -0.018299"/>
     <inertia ixx="0.000193" ixy="3.911916e-06" ixz="1.051402e-07" iyy="4.430571e-05" iyz="-3.850584e-06" izz="0.000192"/>
  </inertial>
  <visual>
     <origin xyz="-0.000000 0.000000 -0.019000" rpy="0.00000000 -0.00000000 -0.00000000"/>
     <geometry>
     <mesh filename="package://robot_assembler/meshes/xm430_dynamixel.dae" scale="1.000000 1.000000 1.000000"/>
     </geometry>
  </visual>
  <collision>
     <origin xyz="-0.000000 0.000000 -0.019000" rpy="0.00000000 -0.00000000 -0.00000000"/>
     <geometry>
     <mesh filename="package://robot_assembler/meshes/xm430_dynamixel.dae" scale="1.000000 1.000000 1.000000"/>
     </geometry>
  </collision>
  <visual>
     <origin xyz="-0.000000 -0.021000 -0.019000" rpy="2.26553460 1.57079633 0.69473828"/>
     <geometry>
     <mesh filename="package://robot_assembler/meshes/fr12_s102.dae" scale="1.000000 1.000000 1.000000"/>
     </geometry>
  </visual>
  <collision>
     <origin xyz="-0.000000 -0.021000 -0.019000" rpy="2.26553460 1.57079633 0.69473828"/>
     <geometry>
     <mesh filename="package://robot_assembler/meshes/fr12_s102.dae" scale="1.000000 1.000000 1.000000"/>
     </geometry>
  </collision>
  <visual>
     <origin xyz="0.000000 -0.075750 -0.019000" rpy="0.09722447 -1.57079633 3.04436819"/>
     <geometry>
     <mesh filename="package://robot_assembler/meshes/xm430_dynamixel.dae" scale="1.000000 1.000000 1.000000"/>
     </geometry>
  </visual>
  <collision>
     <origin xyz="0.000000 -0.075750 -0.019000" rpy="0.09722447 -1.57079633 3.04436819"/>
     <geometry>
     <mesh filename="package://robot_assembler/meshes/xm430_dynamixel.dae" scale="1.000000 1.000000 1.000000"/>
     </geometry>
  </collision>
  </link>
  <xacro:gazebo_link_reference link_name="LINK9" />
  <link name="LINK9">
  <inertial>
     <mass value="0.129"/>
     <origin rpy="0 0 0" xyz="-6.487145e-17 0.049025 -0.017837"/>
     <inertia ixx="6.363671e-05" ixy="9.098310e-20" ixz="1.453394e-20" iyy="2.635199e-05" iyz="-1.121221e-06" izz="5.685405e-05"/>
  </inertial>
  <visual>
     <origin xyz="0.000000 -0.000000 -0.019000" rpy="0.00000000 1.57079633 0.00000000"/>
     <geometry>
     <mesh filename="package://robot_assembler/meshes/fr12_h101.dae" scale="1.000000 1.000000 1.000000"/>
     </geometry>
  </visual>
  <collision>
     <origin xyz="0.000000 -0.000000 -0.019000" rpy="0.00000000 1.57079633 0.00000000"/>
     <geometry>
     <mesh filename="package://robot_assembler/meshes/fr12_h101.dae" scale="1.000000 1.000000 1.000000"/>
     </geometry>
  </collision>
  <visual>
     <origin xyz="-0.000000 0.047500 -0.019000" rpy="-0.32658143 -1.57079633 1.89737776"/>
     <geometry>
     <mesh filename="package://robot_assembler/meshes/fr12_s102.dae" scale="1.000000 1.000000 1.000000"/>
     </geometry>
  </visual>
  <collision>
     <origin xyz="-0.000000 0.047500 -0.019000" rpy="-0.32658143 -1.57079633 1.89737776"/>
     <geometry>
     <mesh filename="package://robot_assembler/meshes/fr12_s102.dae" scale="1.000000 1.000000 1.000000"/>
     </geometry>
  </collision>
  <visual>
     <origin xyz="-0.000000 0.068500 -0.019000" rpy="-0.00000000 -0.00000000 0.00000000"/>
     <geometry>
     <mesh filename="package://robot_assembler/meshes/xm430_dynamixel.dae" scale="1.000000 1.000000 1.000000"/>
     </geometry>
  </visual>
  <collision>
     <origin xyz="-0.000000 0.068500 -0.019000" rpy="-0.00000000 -0.00000000 0.00000000"/>
     <geometry>
     <mesh filename="package://robot_assembler/meshes/xm430_dynamixel.dae" scale="1.000000 1.000000 1.000000"/>
     </geometry>
  </collision>
  </link>
  <xacro:gazebo_link_reference link_name="LINK10" />
  <link name="LINK10">
  <inertial>
     <mass value="0.145"/>
     <origin rpy="0 0 0" xyz="-0.001034 0.04584 -0.020028"/>
     <inertia ixx="0.0001" ixy="-5.384483e-07" ixz="7.541379e-07" iyy="5.040990e-05" iyz="1.689589e-05" izz="8.917485e-05"/>
  </inertial>
  <visual>
     <origin xyz="0.000000 0.000000 -0.019000" rpy="0.14048970 1.57079633 0.14048970"/>
     <geometry>
     <mesh filename="package://robot_assembler/meshes/fr12_h101.dae" scale="1.000000 1.000000 1.000000"/>
     </geometry>
  </visual>
  <collision>
     <origin xyz="0.000000 0.000000 -0.019000" rpy="0.14048970 1.57079633 0.14048970"/>
     <geometry>
     <mesh filename="package://robot_assembler/meshes/fr12_h101.dae" scale="1.000000 1.000000 1.000000"/>
     </geometry>
  </collision>
  <visual>
     <origin xyz="-0.000000 0.042250 -0.003000" rpy="1.57079633 -0.00000000 -1.57079633"/>
     <geometry>
     <mesh filename="package://robot_assembler/meshes/xm430_dynamixel.dae" scale="1.000000 1.000000 1.000000"/>
     </geometry>
  </visual>
  <collision>
     <origin xyz="-0.000000 0.042250 -0.003000" rpy="1.57079633 -0.00000000 -1.57079633"/>
     <geometry>
     <mesh filename="package://robot_assembler/meshes/xm430_dynamixel.dae" scale="1.000000 1.000000 1.000000"/>
     </geometry>
  </collision>
  <visual>
     <origin xyz="-0.000000 0.042250 -0.024000" rpy="3.14159265 0.00000000 -3.14159265"/>
     <geometry>
     <mesh filename="package://robot_assembler/meshes/fr12_e170.dae" scale="1.000000 1.000000 1.000000"/>
     </geometry>
  </visual>
  <collision>
     <origin xyz="-0.000000 0.042250 -0.024000" rpy="3.14159265 0.00000000 -3.14159265"/>
     <geometry>
     <mesh filename="package://robot_assembler/meshes/fr12_e170.dae" scale="1.000000 1.000000 1.000000"/>
     </geometry>
  </collision>
  </link>
  <xacro:gazebo_link_reference link_name="LINK11" />
  <link name="LINK11">
  <inertial>
     <mass value="0.035"/>
     <origin rpy="0 0 0" xyz="-0.023397 0.018542 -0.019"/>
     <inertia ixx="1.643493e-05" ixy="8.139500e-06" ixz="2.985349e-21" iyy="2.583362e-05" iyz="-6.399788e-21" izz="2.525856e-05"/>
  </inertial>
  <visual>
     <origin xyz="0.000000 0.000000 -0.019000" rpy="-0.93810565 -1.57079633 0.41450687"/>
     <geometry>
     <mesh filename="package://robot_assembler/meshes/fr12_e171.dae" scale="1.000000 1.000000 1.000000"/>
     </geometry>
  </visual>
  <collision>
     <origin xyz="0.000000 0.000000 -0.019000" rpy="-0.93810565 -1.57079633 0.41450687"/>
     <geometry>
     <mesh filename="package://robot_assembler/meshes/fr12_e171.dae" scale="1.000000 1.000000 1.000000"/>
     </geometry>
  </collision>
  </link>
  <xacro:gazebo_link_reference link_name="LINK12" />
  <link name="LINK12">
  <inertial>
     <mass value="0.015"/>
     <origin rpy="0 0 0" xyz="-2.842171e-17 -1.776357e-18 0.01455"/>
     <inertia ixx="1.969763e-06" ixy="-7.473640e-22" ixz="-1.473474e-21" iyy="3.159763e-06" iyz="4.904843e-23" izz="3.012500e-06"/>
  </inertial>
  <visual>
     <origin xyz="-0.000000 -0.000000 0.028000" rpy="-1.57079633 0.00000000 -1.57079633"/>
     <geometry>
     <mesh filename="package://robot_assembler/meshes/fr12_h101.dae" scale="1.000000 1.000000 1.000000"/>
     </geometry>
  </visual>
  <collision>
     <origin xyz="-0.000000 -0.000000 0.028000" rpy="-1.57079633 0.00000000 -1.57079633"/>
     <geometry>
     <mesh filename="package://robot_assembler/meshes/fr12_h101.dae" scale="1.000000 1.000000 1.000000"/>
     </geometry>
  </collision>
  </link>
  <xacro:gazebo_link_reference link_name="LINK13" />
  <link name="LINK13">
  <inertial>
     <mass value="0.228"/>
     <origin rpy="0 0 0" xyz="-0.000658 -0.012202 0.003807"/>
     <inertia ixx="0.000153" ixy="3.026316e-08" ixz="2.519013e-06" iyy="0.000136" iyz="-8.800526e-07" izz="6.231353e-05"/>
  </inertial>
  <visual>
     <origin xyz="0.000000 0.000000 -0.019000" rpy="0.00000000 -0.00000000 0.00000000"/>
     <geometry>
     <mesh filename="package://robot_assembler/meshes/xm430_dynamixel.dae" scale="1.000000 1.000000 1.000000"/>
     </geometry>
  </visual>
  <collision>
     <origin xyz="0.000000 0.000000 -0.019000" rpy="0.00000000 -0.00000000 0.00000000"/>
     <geometry>
     <mesh filename="package://robot_assembler/meshes/xm430_dynamixel.dae" scale="1.000000 1.000000 1.000000"/>
     </geometry>
  </collision>
  <visual>
     <origin xyz="-0.000000 -0.000000 -0.016000" rpy="1.57079633 -0.00000000 0.00000000"/>
     <geometry>
     <mesh filename="package://robot_assembler/meshes/fr12_x102.dae" scale="1.000000 1.000000 1.000000"/>
     </geometry>
  </visual>
  <collision>
     <origin xyz="-0.000000 -0.000000 -0.016000" rpy="1.57079633 -0.00000000 0.00000000"/>
     <geometry>
     <mesh filename="package://robot_assembler/meshes/fr12_x102.dae" scale="1.000000 1.000000 1.000000"/>
     </geometry>
  </collision>
  <visual>
     <origin xyz="-0.000000 0.000000 0.020600" rpy="-1.11791708 -1.57079633 1.11791708"/>
     <geometry>
     <mesh filename="package://robot_assembler/meshes/xm430_dynamixel.dae" scale="1.000000 1.000000 1.000000"/>
     </geometry>
  </visual>
  <collision>
     <origin xyz="-0.000000 0.000000 0.020600" rpy="-1.11791708 -1.57079633 1.11791708"/>
     <geometry>
     <mesh filename="package://robot_assembler/meshes/xm430_dynamixel.dae" scale="1.000000 1.000000 1.000000"/>
     </geometry>
  </collision>
  <visual>
     <origin xyz="-0.000000 0.000000 0.034850" rpy="1.57079633 0.00000000 0.00000000"/>
     <geometry>
     <mesh filename="package://robot_assembler/meshes/hr12_f101.dae" scale="1.000000 1.000000 1.000000"/>
     </geometry>
  </visual>
  <collision>
     <origin xyz="-0.000000 0.000000 0.034850" rpy="1.57079633 0.00000000 0.00000000"/>
     <geometry>
     <mesh filename="package://robot_assembler/meshes/hr12_f101.dae" scale="1.000000 1.000000 1.000000"/>
     </geometry>
  </collision>
  </link>
  <xacro:gazebo_link_reference link_name="LINK14" />
  <link name="LINK14">
  <inertial>
     <mass value="0.134"/>
     <origin rpy="0 0 0" xyz="1.970961e-16 -0.072683 -0.017881"/>
     <inertia ixx="9.582042e-05" ixy="2.464070e-19" ixz="-1.684729e-20" iyy="2.736267e-05" iyz="1.622575e-06" izz="8.942792e-05"/>
  </inertial>
  <visual>
     <origin xyz="0.000000 0.000000 -0.019000" rpy="-0.32123098 1.57079633 2.82036167"/>
     <geometry>
     <mesh filename="package://robot_assembler/meshes/fr12_h103.dae" scale="1.000000 1.000000 1.000000"/>
     </geometry>
  </visual>
  <collision>
     <origin xyz="0.000000 0.000000 -0.019000" rpy="-0.32123098 1.57079633 2.82036167"/>
     <geometry>
     <mesh filename="package://robot_assembler/meshes/fr12_h103.dae" scale="1.000000 1.000000 1.000000"/>
     </geometry>
  </collision>
  <visual>
     <origin xyz="0.000000 -0.074500 -0.019000" rpy="-0.30805278 -1.57079633 -1.26274355"/>
     <geometry>
     <mesh filename="package://robot_assembler/meshes/fr12_s102.dae" scale="1.000000 1.000000 1.000000"/>
     </geometry>
  </visual>
  <collision>
     <origin xyz="0.000000 -0.074500 -0.019000" rpy="-0.30805278 -1.57079633 -1.26274355"/>
     <geometry>
     <mesh filename="package://robot_assembler/meshes/fr12_s102.dae" scale="1.000000 1.000000 1.000000"/>
     </geometry>
  </collision>
  <visual>
     <origin xyz="0.000000 -0.095500 -0.019000" rpy="-0.00000000 -0.00000000 -3.14159265"/>
     <geometry>
     <mesh filename="package://robot_assembler/meshes/xm430_dynamixel.dae" scale="1.000000 1.000000 1.000000"/>
     </geometry>
  </visual>
  <collision>
     <origin xyz="0.000000 -0.095500 -0.019000" rpy="-0.00000000 -0.00000000 -3.14159265"/>
     <geometry>
     <mesh filename="package://robot_assembler/meshes/xm430_dynamixel.dae" scale="1.000000 1.000000 1.000000"/>
     </geometry>
  </collision>
  </link>
  <xacro:gazebo_link_reference link_name="LINK15" />
  <link name="LINK15">
  <inertial>
     <mass value="0.035"/>
     <origin rpy="0 0 0" xyz="2.943677e-17 0.037793 -0.019"/>
     <inertia ixx="2.398520e-05" ixy="-2.345021e-20" ixz="-4.260739e-21" iyy="7.029167e-06" iyz="1.789835e-21" izz="2.676187e-05"/>
  </inertial>
  <visual>
     <origin xyz="0.000000 0.000000 -0.019000" rpy="0.40124714 1.57079633 0.40124714"/>
     <geometry>
     <mesh filename="package://robot_assembler/meshes/fr12_h101.dae" scale="1.000000 1.000000 1.000000"/>
     </geometry>
  </visual>
  <collision>
     <origin xyz="0.000000 0.000000 -0.019000" rpy="0.40124714 1.57079633 0.40124714"/>
     <geometry>
     <mesh filename="package://robot_assembler/meshes/fr12_h101.dae" scale="1.000000 1.000000 1.000000"/>
     </geometry>
  </collision>
  <visual>
     <origin xyz="0.000000 0.083000 -0.019000" rpy="2.89702147 1.57079633 -0.24457119"/>
     <geometry>
     <mesh filename="package://robot_assembler/meshes/fr12_h103.dae" scale="1.000000 1.000000 1.000000"/>
     </geometry>
  </visual>
  <collision>
     <origin xyz="0.000000 0.083000 -0.019000" rpy="2.89702147 1.57079633 -0.24457119"/>
     <geometry>
     <mesh filename="package://robot_assembler/meshes/fr12_h103.dae" scale="1.000000 1.000000 1.000000"/>
     </geometry>
  </collision>
  </link>
  <xacro:gazebo_link_reference link_name="LINK16" />
  <link name="LINK16">
  <inertial>
     <mass value="0.228"/>
     <origin rpy="0 0 0" xyz="0.016793 -0.012202 -0.018342"/>
     <inertia ixx="6.231353e-05" ixy="8.800526e-07" ixz="2.519013e-06" iyy="0.000136" iyz="-3.026316e-08" izz="0.000153"/>
  </inertial>
  <visual>
     <origin xyz="0.000000 0.000000 -0.019000" rpy="-0.00000000 -0.00000000 0.00000000"/>
     <geometry>
     <mesh filename="package://robot_assembler/meshes/xm430_dynamixel.dae" scale="1.000000 1.000000 1.000000"/>
     </geometry>
  </visual>
  <collision>
     <origin xyz="0.000000 0.000000 -0.019000" rpy="-0.00000000 -0.00000000 0.00000000"/>
     <geometry>
     <mesh filename="package://robot_assembler/meshes/xm430_dynamixel.dae" scale="1.000000 1.000000 1.000000"/>
     </geometry>
  </collision>
  <visual>
     <origin xyz="-0.014250 -0.000000 -0.019000" rpy="1.57079633 -1.57079633 0.00000000"/>
     <geometry>
     <mesh filename="package://robot_assembler/meshes/hr12_f101.dae" scale="1.000000 1.000000 1.000000"/>
     </geometry>
  </visual>
  <collision>
     <origin xyz="-0.014250 -0.000000 -0.019000" rpy="1.57079633 -1.57079633 0.00000000"/>
     <geometry>
     <mesh filename="package://robot_assembler/meshes/hr12_f101.dae" scale="1.000000 1.000000 1.000000"/>
     </geometry>
  </collision>
  <visual>
     <origin xyz="0.036600 0.000000 -0.019000" rpy="-2.20911613 -1.57079633 -2.50327285"/>
     <geometry>
     <mesh filename="package://robot_assembler/meshes/fr12_x102.dae" scale="1.000000 1.000000 1.000000"/>
     </geometry>
  </visual>
  <collision>
     <origin xyz="0.036600 0.000000 -0.019000" rpy="-2.20911613 -1.57079633 -2.50327285"/>
     <geometry>
     <mesh filename="package://robot_assembler/meshes/fr12_x102.dae" scale="1.000000 1.000000 1.000000"/>
     </geometry>
  </collision>
  <visual>
     <origin xyz="0.039600 0.000000 -0.019000" rpy="2.51004372 -1.57079633 -2.51004372"/>
     <geometry>
     <mesh filename="package://robot_assembler/meshes/xm430_dynamixel.dae" scale="1.000000 1.000000 1.000000"/>
     </geometry>
  </visual>
  <collision>
     <origin xyz="0.039600 0.000000 -0.019000" rpy="2.51004372 -1.57079633 -2.51004372"/>
     <geometry>
     <mesh filename="package://robot_assembler/meshes/xm430_dynamixel.dae" scale="1.000000 1.000000 1.000000"/>
     </geometry>
  </collision>
  </link>
  <xacro:gazebo_link_reference link_name="LINK17" />
  <link name="LINK17">
  <inertial>
     <mass value="0.04"/>
     <origin rpy="0 0 0" xyz="0.00375 0.023794 0.0205"/>
     <inertia ixx="1.790427e-05" ixy="-9.309375e-07" ixz="7.695701e-21" iyy="2.418333e-05" iyz="-1.955991e-20" izz="1.359843e-05"/>
  </inertial>
  <visual>
     <origin xyz="0.000000 0.000000 0.020500" rpy="0.00000000 1.57079633 0.00000000"/>
     <geometry>
     <mesh filename="package://robot_assembler/meshes/fr12_h101.dae" scale="1.000000 1.000000 1.000000"/>
     </geometry>
  </visual>
  <collision>
     <origin xyz="0.000000 0.000000 0.020500" rpy="0.00000000 1.57079633 0.00000000"/>
     <geometry>
     <mesh filename="package://robot_assembler/meshes/fr12_h101.dae" scale="1.000000 1.000000 1.000000"/>
     </geometry>
  </collision>
  <visual>
     <origin xyz="0.006000 0.032000 0.020500" rpy="0.78539816 1.57079633 -0.78539816"/>
     <geometry>
     <mesh filename="package://robot_assembler/meshes/foot-plate.dae" scale="1.000000 1.000000 1.000000"/>
     </geometry>
  </visual>
  <collision>
     <origin xyz="0.006000 0.032000 0.020500" rpy="0.78539816 1.57079633 -0.78539816"/>
     <geometry>
     <mesh filename="package://robot_assembler/meshes/foot-plate.dae" scale="1.000000 1.000000 1.000000"/>
     </geometry>
  </collision>
  </link>
  <xacro:gazebo_link_reference link_name="LINK18" />
  <link name="LINK18">
  <inertial>
     <mass value="0.015"/>
     <origin rpy="0 0 0" xyz="-2.842171e-17 -1.776357e-18 0.01455"/>
     <inertia ixx="1.969763e-06" ixy="-7.473640e-22" ixz="-1.473474e-21" iyy="3.159763e-06" iyz="4.904843e-23" izz="3.012500e-06"/>
  </inertial>
  <visual>
     <origin xyz="-0.000000 -0.000000 0.028000" rpy="-1.57079633 0.00000000 -1.57079633"/>
     <geometry>
     <mesh filename="package://robot_assembler/meshes/fr12_h101.dae" scale="1.000000 1.000000 1.000000"/>
     </geometry>
  </visual>
  <collision>
     <origin xyz="-0.000000 -0.000000 0.028000" rpy="-1.57079633 0.00000000 -1.57079633"/>
     <geometry>
     <mesh filename="package://robot_assembler/meshes/fr12_h101.dae" scale="1.000000 1.000000 1.000000"/>
     </geometry>
  </collision>
  </link>
  <xacro:gazebo_link_reference link_name="LINK19" />
  <link name="LINK19">
  <inertial>
     <mass value="0.228"/>
     <origin rpy="0 0 0" xyz="-0.000658 -0.012202 0.003807"/>
     <inertia ixx="0.000153" ixy="3.026316e-08" ixz="2.519013e-06" iyy="0.000136" iyz="-8.800526e-07" izz="6.231353e-05"/>
  </inertial>
  <visual>
     <origin xyz="0.000000 0.000000 -0.019000" rpy="0.00000000 -0.00000000 0.00000000"/>
     <geometry>
     <mesh filename="package://robot_assembler/meshes/xm430_dynamixel.dae" scale="1.000000 1.000000 1.000000"/>
     </geometry>
  </visual>
  <collision>
     <origin xyz="0.000000 0.000000 -0.019000" rpy="0.00000000 -0.00000000 0.00000000"/>
     <geometry>
     <mesh filename="package://robot_assembler/meshes/xm430_dynamixel.dae" scale="1.000000 1.000000 1.000000"/>
     </geometry>
  </collision>
  <visual>
     <origin xyz="-0.000000 0.000000 -0.016000" rpy="1.57079633 -0.00000000 0.00000000"/>
     <geometry>
     <mesh filename="package://robot_assembler/meshes/fr12_x102.dae" scale="1.000000 1.000000 1.000000"/>
     </geometry>
  </visual>
  <collision>
     <origin xyz="-0.000000 0.000000 -0.016000" rpy="1.57079633 -0.00000000 0.00000000"/>
     <geometry>
     <mesh filename="package://robot_assembler/meshes/fr12_x102.dae" scale="1.000000 1.000000 1.000000"/>
     </geometry>
  </collision>
  <visual>
     <origin xyz="-0.000000 0.000000 0.020600" rpy="-1.11791708 -1.57079633 1.11791708"/>
     <geometry>
     <mesh filename="package://robot_assembler/meshes/xm430_dynamixel.dae" scale="1.000000 1.000000 1.000000"/>
     </geometry>
  </visual>
  <collision>
     <origin xyz="-0.000000 0.000000 0.020600" rpy="-1.11791708 -1.57079633 1.11791708"/>
     <geometry>
     <mesh filename="package://robot_assembler/meshes/xm430_dynamixel.dae" scale="1.000000 1.000000 1.000000"/>
     </geometry>
  </collision>
  <visual>
     <origin xyz="-0.000000 0.000000 0.034850" rpy="1.57079633 0.00000000 0.00000000"/>
     <geometry>
     <mesh filename="package://robot_assembler/meshes/hr12_f101.dae" scale="1.000000 1.000000 1.000000"/>
     </geometry>
  </visual>
  <collision>
     <origin xyz="-0.000000 0.000000 0.034850" rpy="1.57079633 0.00000000 0.00000000"/>
     <geometry>
     <mesh filename="package://robot_assembler/meshes/hr12_f101.dae" scale="1.000000 1.000000 1.000000"/>
     </geometry>
  </collision>
  </link>
  <xacro:gazebo_link_reference link_name="LINK20" />
  <link name="LINK20">
  <inertial>
     <mass value="0.134"/>
     <origin rpy="0 0 0" xyz="1.984217e-16 -0.072683 -0.017881"/>
     <inertia ixx="9.582042e-05" ixy="2.483285e-19" ixz="-1.691489e-20" iyy="2.736267e-05" iyz="1.622575e-06" izz="8.942792e-05"/>
  </inertial>
  <visual>
     <origin xyz="0.000000 0.000000 -0.019000" rpy="-0.32123098 1.57079633 2.82036167"/>
     <geometry>
     <mesh filename="package://robot_assembler/meshes/fr12_h103.dae" scale="1.000000 1.000000 1.000000"/>
     </geometry>
  </visual>
  <collision>
     <origin xyz="0.000000 0.000000 -0.019000" rpy="-0.32123098 1.57079633 2.82036167"/>
     <geometry>
     <mesh filename="package://robot_assembler/meshes/fr12_h103.dae" scale="1.000000 1.000000 1.000000"/>
     </geometry>
  </collision>
  <visual>
     <origin xyz="0.000000 -0.074500 -0.019000" rpy="-0.30805278 -1.57079633 -1.26274355"/>
     <geometry>
     <mesh filename="package://robot_assembler/meshes/fr12_s102.dae" scale="1.000000 1.000000 1.000000"/>
     </geometry>
  </visual>
  <collision>
     <origin xyz="0.000000 -0.074500 -0.019000" rpy="-0.30805278 -1.57079633 -1.26274355"/>
     <geometry>
     <mesh filename="package://robot_assembler/meshes/fr12_s102.dae" scale="1.000000 1.000000 1.000000"/>
     </geometry>
  </collision>
  <visual>
     <origin xyz="0.000000 -0.095500 -0.019000" rpy="-0.00000000 -0.00000000 -3.14159265"/>
     <geometry>
     <mesh filename="package://robot_assembler/meshes/xm430_dynamixel.dae" scale="1.000000 1.000000 1.000000"/>
     </geometry>
  </visual>
  <collision>
     <origin xyz="0.000000 -0.095500 -0.019000" rpy="-0.00000000 -0.00000000 -3.14159265"/>
     <geometry>
     <mesh filename="package://robot_assembler/meshes/xm430_dynamixel.dae" scale="1.000000 1.000000 1.000000"/>
     </geometry>
  </collision>
  </link>
  <xacro:gazebo_link_reference link_name="LINK21" />
  <link name="LINK21">
  <inertial>
     <mass value="0.035"/>
     <origin rpy="0 0 0" xyz="2.943677e-17 0.037793 -0.019"/>
     <inertia ixx="2.398520e-05" ixy="-2.345021e-20" ixz="-4.260739e-21" iyy="7.029167e-06" iyz="1.789835e-21" izz="2.676187e-05"/>
  </inertial>
  <visual>
     <origin xyz="0.000000 0.000000 -0.019000" rpy="0.40124714 1.57079633 0.40124714"/>
     <geometry>
     <mesh filename="package://robot_assembler/meshes/fr12_h101.dae" scale="1.000000 1.000000 1.000000"/>
     </geometry>
  </visual>
  <collision>
     <origin xyz="0.000000 0.000000 -0.019000" rpy="0.40124714 1.57079633 0.40124714"/>
     <geometry>
     <mesh filename="package://robot_assembler/meshes/fr12_h101.dae" scale="1.000000 1.000000 1.000000"/>
     </geometry>
  </collision>
  <visual>
     <origin xyz="0.000000 0.083000 -0.019000" rpy="2.89702147 1.57079633 -0.24457119"/>
     <geometry>
     <mesh filename="package://robot_assembler/meshes/fr12_h103.dae" scale="1.000000 1.000000 1.000000"/>
     </geometry>
  </visual>
  <collision>
     <origin xyz="0.000000 0.083000 -0.019000" rpy="2.89702147 1.57079633 -0.24457119"/>
     <geometry>
     <mesh filename="package://robot_assembler/meshes/fr12_h103.dae" scale="1.000000 1.000000 1.000000"/>
     </geometry>
  </collision>
  </link>
  <xacro:gazebo_link_reference link_name="LINK22" />
  <link name="LINK22">
  <inertial>
     <mass value="0.228"/>
     <origin rpy="0 0 0" xyz="0.016793 -0.012202 -0.018342"/>
     <inertia ixx="6.231353e-05" ixy="8.800526e-07" ixz="2.519013e-06" iyy="0.000136" iyz="-3.026316e-08" izz="0.000153"/>
  </inertial>
  <visual>
     <origin xyz="0.000000 0.000000 -0.019000" rpy="-0.00000000 -0.00000000 0.00000000"/>
     <geometry>
     <mesh filename="package://robot_assembler/meshes/xm430_dynamixel.dae" scale="1.000000 1.000000 1.000000"/>
     </geometry>
  </visual>
  <collision>
     <origin xyz="0.000000 0.000000 -0.019000" rpy="-0.00000000 -0.00000000 0.00000000"/>
     <geometry>
     <mesh filename="package://robot_assembler/meshes/xm430_dynamixel.dae" scale="1.000000 1.000000 1.000000"/>
     </geometry>
  </collision>
  <visual>
     <origin xyz="-0.014250 0.000000 -0.019000" rpy="1.57079633 -1.57079633 0.00000000"/>
     <geometry>
     <mesh filename="package://robot_assembler/meshes/hr12_f101.dae" scale="1.000000 1.000000 1.000000"/>
     </geometry>
  </visual>
  <collision>
     <origin xyz="-0.014250 0.000000 -0.019000" rpy="1.57079633 -1.57079633 0.00000000"/>
     <geometry>
     <mesh filename="package://robot_assembler/meshes/hr12_f101.dae" scale="1.000000 1.000000 1.000000"/>
     </geometry>
  </collision>
  <visual>
     <origin xyz="0.036600 0.000000 -0.019000" rpy="-2.20911613 -1.57079633 -2.50327285"/>
     <geometry>
     <mesh filename="package://robot_assembler/meshes/fr12_x102.dae" scale="1.000000 1.000000 1.000000"/>
     </geometry>
  </visual>
  <collision>
     <origin xyz="0.036600 0.000000 -0.019000" rpy="-2.20911613 -1.57079633 -2.50327285"/>
     <geometry>
     <mesh filename="package://robot_assembler/meshes/fr12_x102.dae" scale="1.000000 1.000000 1.000000"/>
     </geometry>
  </collision>
  <visual>
     <origin xyz="0.039600 0.000000 -0.019000" rpy="2.51004372 -1.57079633 -2.51004372"/>
     <geometry>
     <mesh filename="package://robot_assembler/meshes/xm430_dynamixel.dae" scale="1.000000 1.000000 1.000000"/>
     </geometry>
  </visual>
  <collision>
     <origin xyz="0.039600 0.000000 -0.019000" rpy="2.51004372 -1.57079633 -2.51004372"/>
     <geometry>
     <mesh filename="package://robot_assembler/meshes/xm430_dynamixel.dae" scale="1.000000 1.000000 1.000000"/>
     </geometry>
  </collision>
  </link>
  <xacro:gazebo_link_reference link_name="LINK23" />
  <link name="LINK23">
  <inertial>
     <mass value="0.04"/>
     <origin rpy="0 0 0" xyz="-0.00375 0.023794 0.0205"/>
     <inertia ixx="1.790427e-05" ixy="9.309375e-07" ixz="7.495861e-21" iyy="2.418333e-05" iyz="-1.680378e-20" izz="1.359843e-05"/>
  </inertial>
  <visual>
     <origin xyz="0.000000 0.000000 0.020500" rpy="0.00000000 1.57079633 0.00000000"/>
     <geometry>
     <mesh filename="package://robot_assembler/meshes/fr12_h101.dae" scale="1.000000 1.000000 1.000000"/>
     </geometry>
  </visual>
  <collision>
     <origin xyz="0.000000 0.000000 0.020500" rpy="0.00000000 1.57079633 0.00000000"/>
     <geometry>
     <mesh filename="package://robot_assembler/meshes/fr12_h101.dae" scale="1.000000 1.000000 1.000000"/>
     </geometry>
  </collision>
  <visual>
     <origin xyz="-0.006000 0.032000 0.020500" rpy="0.78539816 1.57079633 -0.78539816"/>
     <geometry>
     <mesh filename="package://robot_assembler/meshes/foot-plate.dae" scale="1.000000 1.000000 1.000000"/>
     </geometry>
  </visual>
  <collision>
     <origin xyz="-0.006000 0.032000 0.020500" rpy="0.78539816 1.57079633 -0.78539816"/>
     <geometry>
     <mesh filename="package://robot_assembler/meshes/foot-plate.dae" scale="1.000000 1.000000 1.000000"/>
     </geometry>
  </collision>
  </link>
  <xacro:gazebo_transmission joint_name="JOINT0" />
  <joint name="JOINT0" type="revolute">
     <parent link="BASE"/>
     <child link="LINK0"/>
     <origin xyz="0.015750 -0.000000 0.047000" rpy="0.00000000 0.00000000 -1.57079633"/>
     <axis xyz="0 0 1"/>
     <limit effort="200" lower="-3.14159" upper="3.14159" velocity="40"/>
  </joint>
  <xacro:gazebo_transmission joint_name="JOINT1" />
  <joint name="JOINT1" type="revolute">
     <parent link="LINK0"/>
     <child link="LINK1"/>
     <origin xyz="0.019000 -0.000000 0.020000" rpy="-1.57079633 1.57079633 -1.57079633"/>
     <axis xyz="0 0 1"/>
     <limit effort="200" lower="-3.14159" upper="3.14159" velocity="40"/>
  </joint>
  <xacro:gazebo_transmission joint_name="JOINT2" />
  <joint name="JOINT2" type="revolute">
     <parent link="BASE"/>
     <child link="LINK2"/>
     <origin xyz="0.012000 -0.053000 0.030000" rpy="0.78539816 1.57079633 -0.78539816"/>
     <axis xyz="0 0 1"/>
     <limit effort="200" lower="-3.14159" upper="3.14159" velocity="40"/>
  </joint>
  <xacro:gazebo_transmission joint_name="JOINT3" />
  <joint name="JOINT3" type="revolute">
     <parent link="LINK2"/>
     <child link="LINK3"/>
     <origin xyz="0.010000 -0.019000 0.028500" rpy="0.89027510 -1.57079633 0.68052122"/>
     <axis xyz="0 0 1"/>
     <limit effort="200" lower="-3.14159" upper="3.14159" velocity="40"/>
  </joint>
  <xacro:gazebo_transmission joint_name="JOINT4" />
  <joint name="JOINT4" type="revolute">
     <parent link="LINK3"/>
     <child link="LINK4"/>
     <origin xyz="0.019000 -0.075750 -0.019000" rpy="0.66258529 -1.57079633 2.47900737"/>
     <axis xyz="0 0 1"/>
     <limit effort="200" lower="-3.14159" upper="3.14159" velocity="40"/>
  </joint>
  <xacro:gazebo_transmission joint_name="JOINT5" />
  <joint name="JOINT5" type="revolute">
     <parent link="LINK4"/>
     <child link="LINK5"/>
     <origin xyz="-0.000000 0.068500 -0.000000" rpy="-0.00000000 -0.00000000 0.00000000"/>
     <axis xyz="0 0 1"/>
     <limit effort="200" lower="-3.14159" upper="3.14159" velocity="40"/>
  </joint>
  <xacro:gazebo_transmission joint_name="JOINT6" />
  <joint name="JOINT6" type="revolute">
     <parent link="LINK5"/>
     <child link="LINK6"/>
     <origin xyz="-0.019000 0.042250 -0.003000" rpy="1.57079633 -0.00000000 -1.57079633"/>
     <axis xyz="0 0 1"/>
     <limit effort="200" lower="-3.14159" upper="3.14159" velocity="40"/>
  </joint>
  <xacro:gazebo_transmission joint_name="JOINT7" />
  <joint name="JOINT7" type="revolute">
     <parent link="BASE"/>
     <child link="LINK7"/>
     <origin xyz="0.012000 0.053000 0.030000" rpy="-0.78539816 -1.57079633 -0.78539816"/>
     <axis xyz="0 0 1"/>
     <limit effort="200" lower="-3.14159" upper="3.14159" velocity="40"/>
  </joint>
  <xacro:gazebo_transmission joint_name="JOINT8" />
  <joint name="JOINT8" type="revolute">
     <parent link="LINK7"/>
     <child link="LINK8"/>
     <origin xyz="-0.010000 0.019000 0.028500" rpy="1.71269338 -1.57079633 2.99969560"/>
     <axis xyz="0 0 1"/>
     <limit effort="200" lower="-3.14159" upper="3.14159" velocity="40"/>
  </joint>
  <xacro:gazebo_transmission joint_name="JOINT9" />
  <joint name="JOINT9" type="revolute">
     <parent link="LINK8"/>
     <child link="LINK9"/>
     <origin xyz="0.019000 -0.075750 -0.019000" rpy="0.09722447 -1.57079633 3.04436819"/>
     <axis xyz="0 0 1"/>
     <limit effort="200" lower="-3.14159" upper="3.14159" velocity="40"/>
  </joint>
  <xacro:gazebo_transmission joint_name="JOINT10" />
  <joint name="JOINT10" type="revolute">
     <parent link="LINK9"/>
     <child link="LINK10"/>
     <origin xyz="-0.000000 0.068500 -0.000000" rpy="-0.00000000 -0.00000000 0.00000000"/>
     <axis xyz="0 0 1"/>
     <limit effort="200" lower="-3.14159" upper="3.14159" velocity="40"/>
  </joint>
  <xacro:gazebo_transmission joint_name="JOINT11" />
  <joint name="JOINT11" type="revolute">
     <parent link="LINK10"/>
     <child link="LINK11"/>
     <origin xyz="-0.019000 0.042250 -0.003000" rpy="1.57079633 -0.00000000 -1.57079633"/>
     <axis xyz="0 0 1"/>
     <limit effort="200" lower="-3.14159" upper="3.14159" velocity="40"/>
  </joint>
  <xacro:gazebo_transmission joint_name="JOINT12" />
  <joint name="JOINT12" type="revolute">
     <parent link="BASE"/>
     <child link="LINK12"/>
     <origin xyz="0.012000 -0.033000 -0.045000" rpy="3.14159265 0.00000000 1.57079633"/>
     <axis xyz="0 0 1"/>
     <limit effort="200" lower="-3.14159" upper="3.14159" velocity="40"/>
  </joint>
  <xacro:gazebo_transmission joint_name="JOINT13" />
  <joint name="JOINT13" type="revolute">
     <parent link="LINK12"/>
     <child link="LINK13"/>
     <origin xyz="-0.000000 -0.020500 0.028000" rpy="-1.57079633 -0.00000000 0.00000000"/>
     <axis xyz="0 0 1"/>
     <limit effort="200" lower="-3.14159" upper="3.14159" velocity="40"/>
  </joint>
  <xacro:gazebo_transmission joint_name="JOINT14" />
  <joint name="JOINT14" type="revolute">
     <parent link="LINK13"/>
     <child link="LINK14"/>
     <origin xyz="-0.019000 -0.000000 0.020600" rpy="-1.11791708 -1.57079633 1.11791708"/>
     <axis xyz="0 0 1"/>
     <limit effort="200" lower="-3.14159" upper="3.14159" velocity="40"/>
  </joint>
  <xacro:gazebo_transmission joint_name="JOINT15" />
  <joint name="JOINT15" type="revolute">
     <parent link="LINK14"/>
     <child link="LINK15"/>
     <origin xyz="0.000000 -0.095500 -0.000000" rpy="-0.00000000 -0.00000000 -3.14159265"/>
     <axis xyz="0 0 1"/>
     <limit effort="200" lower="-3.14159" upper="3.14159" velocity="40"/>
  </joint>
  <xacro:gazebo_transmission joint_name="JOINT16" />
  <joint name="JOINT16" type="revolute">
     <parent link="LINK15"/>
     <child link="LINK16"/>
     <origin xyz="0.000000 0.083000 -0.000000" rpy="-0.00000000 -0.00000000 -0.00000000"/>
     <axis xyz="0 0 1"/>
     <limit effort="200" lower="-3.14159" upper="3.14159" velocity="40"/>
  </joint>
  <xacro:gazebo_transmission joint_name="JOINT17" />
  <joint name="JOINT17" type="revolute">
     <parent link="LINK16"/>
     <child link="LINK17"/>
     <origin xyz="0.020600 0.000000 -0.019000" rpy="2.51004372 -1.57079633 -2.51004372"/>
     <axis xyz="0 0 1"/>
     <limit effort="200" lower="-3.14159" upper="3.14159" velocity="40"/>
  </joint>
  <xacro:gazebo_transmission joint_name="JOINT18" />
  <joint name="JOINT18" type="revolute">
     <parent link="BASE"/>
     <child link="LINK18"/>
     <origin xyz="0.012000 0.033000 -0.045000" rpy="3.14159265 0.00000000 1.57079633"/>
     <axis xyz="0 0 1"/>
     <limit effort="200" lower="-3.14159" upper="3.14159" velocity="40"/>
  </joint>
  <xacro:gazebo_transmission joint_name="JOINT19" />
  <joint name="JOINT19" type="revolute">
     <parent link="LINK18"/>
     <child link="LINK19"/>
     <origin xyz="-0.000000 -0.020500 0.028000" rpy="-1.57079633 -0.00000000 0.00000000"/>
     <axis xyz="0 0 1"/>
     <limit effort="200" lower="-3.14159" upper="3.14159" velocity="40"/>
  </joint>
  <xacro:gazebo_transmission joint_name="JOINT20" />
  <joint name="JOINT20" type="revolute">
     <parent link="LINK19"/>
     <child link="LINK20"/>
     <origin xyz="-0.019000 0.000000 0.020600" rpy="-1.11791708 -1.57079633 1.11791708"/>
     <axis xyz="0 0 1"/>
     <limit effort="200" lower="-3.14159" upper="3.14159" velocity="40"/>
  </joint>
  <xacro:gazebo_transmission joint_name="JOINT21" />
  <joint name="JOINT21" type="revolute">
     <parent link="LINK20"/>
     <child link="LINK21"/>
     <origin xyz="0.000000 -0.095500 -0.000000" rpy="-0.00000000 -0.00000000 -3.14159265"/>
     <axis xyz="0 0 1"/>
     <limit effort="200" lower="-3.14159" upper="3.14159" velocity="40"/>
  </joint>
  <xacro:gazebo_transmission joint_name="JOINT22" />
  <joint name="JOINT22" type="revolute">
     <parent link="LINK21"/>
     <child link="LINK22"/>
     <origin xyz="0.000000 0.083000 -0.000000" rpy="-0.00000000 -0.00000000 -0.00000000"/>
     <axis xyz="0 0 1"/>
     <limit effort="200" lower="-3.14159" upper="3.14159" velocity="40"/>
  </joint>
  <xacro:gazebo_transmission joint_name="JOINT23" />
  <joint name="JOINT23" type="revolute">
     <parent link="LINK22"/>
     <child link="LINK23"/>
     <origin xyz="0.020600 0.000000 -0.019000" rpy="2.51004372 -1.57079633 -2.51004372"/>
     <axis xyz="0 0 1"/>
     <limit effort="200" lower="-3.14159" upper="3.14159" velocity="40"/>
  </joint>

  <!-- Gazebo plugin for ROS Control -->
  <gazebo>
    <plugin name="gazebo_ros_control" filename="libgazebo_ros_control.so">
      <!--robotNamespace>/</robotNamespace-->
      <legacyModeNS>false</legacyModeNS>
      <robotSimType>gazebo_ros_control/DefaultRobotHWSim</robotSimType>
    </plugin>
  </gazebo>
</robot>
